2024-10-08 16:48:06,492 - services.shipment.shipment_service - ERROR - Shivam
2024-10-08 16:48:06,492 - services.shipment.shipment_service - WARNING - This is a warning log message.
2024-10-08 16:48:06,492 - services.shipment.shipment_service - ERROR - This is an error log message.
2024-10-08 16:48:08,258 - django.request - WARNING - Not Found: /api/check-serviceability/
2024-10-08 17:25:33,228 - django.request - ERROR - Internal Server Error: /api/check-serviceability/
Traceback (most recent call last):
  File "/usr/local/lib/python3.10/dist-packages/django/core/handlers/exception.py", line 55, in inner
    response = get_response(request)
  File "/usr/local/lib/python3.10/dist-packages/django/core/handlers/base.py", line 197, in _get_response
    response = wrapped_callback(request, *callback_args, **callback_kwargs)
  File "/usr/local/lib/python3.10/dist-packages/django/views/decorators/csrf.py", line 65, in _view_wrapper
    return view_func(request, *args, **kwargs)
  File "/usr/local/lib/python3.10/dist-packages/django/views/generic/base.py", line 104, in view
    return self.dispatch(request, *args, **kwargs)
  File "/usr/local/lib/python3.10/dist-packages/rest_framework/views.py", line 509, in dispatch
    response = self.handle_exception(exc)
  File "/usr/local/lib/python3.10/dist-packages/rest_framework/views.py", line 469, in handle_exception
    self.raise_uncaught_exception(exc)
  File "/usr/local/lib/python3.10/dist-packages/rest_framework/views.py", line 480, in raise_uncaught_exception
    raise exc
  File "/usr/local/lib/python3.10/dist-packages/rest_framework/views.py", line 506, in dispatch
    response = handler(request, *args, **kwargs)
  File "/home/shivamkumarsain/Projects/Creworder-Django/shipment/views.py", line 90, in get
    data = checkServiceability(request.user.profile.branch_id,request.user.profile.company_id, request.data['pincode'])
  File "/home/shivamkumarsain/Projects/Creworder-Django/services/shipment/shipment_service.py", line 123, in checkServiceability
    if response.json()['status']==200:
KeyError: 'status'
2024-10-08 17:26:34,047 - django.request - ERROR - Internal Server Error: /api/check-serviceability/
Traceback (most recent call last):
  File "/usr/local/lib/python3.10/dist-packages/django/core/handlers/exception.py", line 55, in inner
    response = get_response(request)
  File "/usr/local/lib/python3.10/dist-packages/django/core/handlers/base.py", line 197, in _get_response
    response = wrapped_callback(request, *callback_args, **callback_kwargs)
  File "/usr/local/lib/python3.10/dist-packages/django/views/decorators/csrf.py", line 65, in _view_wrapper
    return view_func(request, *args, **kwargs)
  File "/usr/local/lib/python3.10/dist-packages/django/views/generic/base.py", line 104, in view
    return self.dispatch(request, *args, **kwargs)
  File "/usr/local/lib/python3.10/dist-packages/rest_framework/views.py", line 509, in dispatch
    response = self.handle_exception(exc)
  File "/usr/local/lib/python3.10/dist-packages/rest_framework/views.py", line 469, in handle_exception
    self.raise_uncaught_exception(exc)
  File "/usr/local/lib/python3.10/dist-packages/rest_framework/views.py", line 480, in raise_uncaught_exception
    raise exc
  File "/usr/local/lib/python3.10/dist-packages/rest_framework/views.py", line 506, in dispatch
    response = handler(request, *args, **kwargs)
  File "/home/shivamkumarsain/Projects/Creworder-Django/shipment/views.py", line 90, in get
    data = checkServiceability(request.user.profile.branch_id,request.user.profile.company_id, request.data['pincode'])
  File "/home/shivamkumarsain/Projects/Creworder-Django/services/shipment/shipment_service.py", line 124, in checkServiceability
    if response.json()['status']==200:
KeyError: 'status'
2024-10-08 17:28:03,612 - django.request - WARNING - Not Found: /api/check-serviceability/
2024-10-08 17:28:57,846 - django.request - ERROR - Internal Server Error: /api/check-serviceability/
Traceback (most recent call last):
  File "/usr/local/lib/python3.10/dist-packages/django/core/handlers/exception.py", line 55, in inner
    response = get_response(request)
  File "/usr/local/lib/python3.10/dist-packages/django/core/handlers/base.py", line 197, in _get_response
    response = wrapped_callback(request, *callback_args, **callback_kwargs)
  File "/usr/local/lib/python3.10/dist-packages/django/views/decorators/csrf.py", line 65, in _view_wrapper
    return view_func(request, *args, **kwargs)
  File "/usr/local/lib/python3.10/dist-packages/django/views/generic/base.py", line 104, in view
    return self.dispatch(request, *args, **kwargs)
  File "/usr/local/lib/python3.10/dist-packages/rest_framework/views.py", line 509, in dispatch
    response = self.handle_exception(exc)
  File "/usr/local/lib/python3.10/dist-packages/rest_framework/views.py", line 469, in handle_exception
    self.raise_uncaught_exception(exc)
  File "/usr/local/lib/python3.10/dist-packages/rest_framework/views.py", line 480, in raise_uncaught_exception
    raise exc
  File "/usr/local/lib/python3.10/dist-packages/rest_framework/views.py", line 506, in dispatch
    response = handler(request, *args, **kwargs)
  File "/home/shivamkumarsain/Projects/Creworder-Django/shipment/views.py", line 90, in get
    data = checkServiceability(request.user.profile.branch_id,request.user.profile.company_id, request.data['pincode'])
  File "/home/shivamkumarsain/Projects/Creworder-Django/services/shipment/shipment_service.py", line 107, in checkServiceability
    token=getShipRocketToken(data['credential_username'],data['credential_password'])
  File "/home/shivamkumarsain/Projects/Creworder-Django/services/shipment/shipment_service.py", line 27, in getShipRocketToken
    print(response.json()['token'])
KeyError: 'token'
2024-10-08 17:29:29,672 - django.request - ERROR - Internal Server Error: /api/check-serviceability/
Traceback (most recent call last):
  File "/usr/local/lib/python3.10/dist-packages/django/core/handlers/exception.py", line 55, in inner
    response = get_response(request)
  File "/usr/local/lib/python3.10/dist-packages/django/core/handlers/base.py", line 197, in _get_response
    response = wrapped_callback(request, *callback_args, **callback_kwargs)
  File "/usr/local/lib/python3.10/dist-packages/django/views/decorators/csrf.py", line 65, in _view_wrapper
    return view_func(request, *args, **kwargs)
  File "/usr/local/lib/python3.10/dist-packages/django/views/generic/base.py", line 104, in view
    return self.dispatch(request, *args, **kwargs)
  File "/usr/local/lib/python3.10/dist-packages/rest_framework/views.py", line 509, in dispatch
    response = self.handle_exception(exc)
  File "/usr/local/lib/python3.10/dist-packages/rest_framework/views.py", line 469, in handle_exception
    self.raise_uncaught_exception(exc)
  File "/usr/local/lib/python3.10/dist-packages/rest_framework/views.py", line 480, in raise_uncaught_exception
    raise exc
  File "/usr/local/lib/python3.10/dist-packages/rest_framework/views.py", line 506, in dispatch
    response = handler(request, *args, **kwargs)
  File "/home/shivamkumarsain/Projects/Creworder-Django/shipment/views.py", line 90, in get
    data = checkServiceability(request.user.profile.branch_id,request.user.profile.company_id, request.data['pincode'])
  File "/home/shivamkumarsain/Projects/Creworder-Django/services/shipment/shipment_service.py", line 107, in checkServiceability
    token=getShipRocketToken(data['credential_username'],data['credential_password'])
  File "/home/shivamkumarsain/Projects/Creworder-Django/services/shipment/shipment_service.py", line 27, in getShipRocketToken
    print(response['status'])
TypeError: 'Response' object is not subscriptable
2024-10-08 17:29:58,548 - django.request - ERROR - Internal Server Error: /api/check-serviceability/
Traceback (most recent call last):
  File "/usr/local/lib/python3.10/dist-packages/django/core/handlers/exception.py", line 55, in inner
    response = get_response(request)
  File "/usr/local/lib/python3.10/dist-packages/django/core/handlers/base.py", line 197, in _get_response
    response = wrapped_callback(request, *callback_args, **callback_kwargs)
  File "/usr/local/lib/python3.10/dist-packages/django/views/decorators/csrf.py", line 65, in _view_wrapper
    return view_func(request, *args, **kwargs)
  File "/usr/local/lib/python3.10/dist-packages/django/views/generic/base.py", line 104, in view
    return self.dispatch(request, *args, **kwargs)
  File "/usr/local/lib/python3.10/dist-packages/rest_framework/views.py", line 509, in dispatch
    response = self.handle_exception(exc)
  File "/usr/local/lib/python3.10/dist-packages/rest_framework/views.py", line 469, in handle_exception
    self.raise_uncaught_exception(exc)
  File "/usr/local/lib/python3.10/dist-packages/rest_framework/views.py", line 480, in raise_uncaught_exception
    raise exc
  File "/usr/local/lib/python3.10/dist-packages/rest_framework/views.py", line 506, in dispatch
    response = handler(request, *args, **kwargs)
  File "/home/shivamkumarsain/Projects/Creworder-Django/shipment/views.py", line 90, in get
    data = checkServiceability(request.user.profile.branch_id,request.user.profile.company_id, request.data['pincode'])
  File "/home/shivamkumarsain/Projects/Creworder-Django/services/shipment/shipment_service.py", line 107, in checkServiceability
    token=getShipRocketToken(data['credential_username'],data['credential_password'])
  File "/home/shivamkumarsain/Projects/Creworder-Django/services/shipment/shipment_service.py", line 28, in getShipRocketToken
    return response.json()['token']
KeyError: 'token'
2024-10-08 17:31:55,786 - django.request - ERROR - Internal Server Error: /api/check-serviceability/
Traceback (most recent call last):
  File "/usr/local/lib/python3.10/dist-packages/django/core/handlers/exception.py", line 55, in inner
    response = get_response(request)
  File "/usr/local/lib/python3.10/dist-packages/django/core/handlers/base.py", line 197, in _get_response
    response = wrapped_callback(request, *callback_args, **callback_kwargs)
  File "/usr/local/lib/python3.10/dist-packages/django/views/decorators/csrf.py", line 65, in _view_wrapper
    return view_func(request, *args, **kwargs)
  File "/usr/local/lib/python3.10/dist-packages/django/views/generic/base.py", line 104, in view
    return self.dispatch(request, *args, **kwargs)
  File "/usr/local/lib/python3.10/dist-packages/rest_framework/views.py", line 509, in dispatch
    response = self.handle_exception(exc)
  File "/usr/local/lib/python3.10/dist-packages/rest_framework/views.py", line 469, in handle_exception
    self.raise_uncaught_exception(exc)
  File "/usr/local/lib/python3.10/dist-packages/rest_framework/views.py", line 480, in raise_uncaught_exception
    raise exc
  File "/usr/local/lib/python3.10/dist-packages/rest_framework/views.py", line 506, in dispatch
    response = handler(request, *args, **kwargs)
  File "/home/shivamkumarsain/Projects/Creworder-Django/shipment/views.py", line 90, in get
    data = checkServiceability(request.user.profile.branch_id,request.user.profile.company_id, request.data['pincode'])
  File "/home/shivamkumarsain/Projects/Creworder-Django/services/shipment/shipment_service.py", line 107, in checkServiceability
    token=getShipRocketToken(data['credential_username'],data['credential_password'])
  File "/home/shivamkumarsain/Projects/Creworder-Django/services/shipment/shipment_service.py", line 28, in getShipRocketToken
    return response.json()['token']
KeyError: 'token'
2024-10-08 17:33:42,180 - django.request - ERROR - Internal Server Error: /api/check-serviceability/
Traceback (most recent call last):
  File "/usr/local/lib/python3.10/dist-packages/django/core/handlers/exception.py", line 55, in inner
    response = get_response(request)
  File "/usr/local/lib/python3.10/dist-packages/django/core/handlers/base.py", line 197, in _get_response
    response = wrapped_callback(request, *callback_args, **callback_kwargs)
  File "/usr/local/lib/python3.10/dist-packages/django/views/decorators/csrf.py", line 65, in _view_wrapper
    return view_func(request, *args, **kwargs)
  File "/usr/local/lib/python3.10/dist-packages/django/views/generic/base.py", line 104, in view
    return self.dispatch(request, *args, **kwargs)
  File "/usr/local/lib/python3.10/dist-packages/rest_framework/views.py", line 509, in dispatch
    response = self.handle_exception(exc)
  File "/usr/local/lib/python3.10/dist-packages/rest_framework/views.py", line 469, in handle_exception
    self.raise_uncaught_exception(exc)
  File "/usr/local/lib/python3.10/dist-packages/rest_framework/views.py", line 480, in raise_uncaught_exception
    raise exc
  File "/usr/local/lib/python3.10/dist-packages/rest_framework/views.py", line 506, in dispatch
    response = handler(request, *args, **kwargs)
  File "/home/shivamkumarsain/Projects/Creworder-Django/shipment/views.py", line 90, in get
    data = checkServiceability(request.user.profile.branch_id,request.user.profile.company_id, request.data['pincode'])
  File "/home/shivamkumarsain/Projects/Creworder-Django/services/shipment/shipment_service.py", line 125, in checkServiceability
    if response.json()['status']==200:
KeyError: 'status'
2024-10-08 17:33:57,011 - django.request - ERROR - Internal Server Error: /api/check-serviceability/
Traceback (most recent call last):
  File "/usr/local/lib/python3.10/dist-packages/django/core/handlers/exception.py", line 55, in inner
    response = get_response(request)
  File "/usr/local/lib/python3.10/dist-packages/django/core/handlers/base.py", line 197, in _get_response
    response = wrapped_callback(request, *callback_args, **callback_kwargs)
  File "/usr/local/lib/python3.10/dist-packages/django/views/decorators/csrf.py", line 65, in _view_wrapper
    return view_func(request, *args, **kwargs)
  File "/usr/local/lib/python3.10/dist-packages/django/views/generic/base.py", line 104, in view
    return self.dispatch(request, *args, **kwargs)
  File "/usr/local/lib/python3.10/dist-packages/rest_framework/views.py", line 509, in dispatch
    response = self.handle_exception(exc)
  File "/usr/local/lib/python3.10/dist-packages/rest_framework/views.py", line 469, in handle_exception
    self.raise_uncaught_exception(exc)
  File "/usr/local/lib/python3.10/dist-packages/rest_framework/views.py", line 480, in raise_uncaught_exception
    raise exc
  File "/usr/local/lib/python3.10/dist-packages/rest_framework/views.py", line 506, in dispatch
    response = handler(request, *args, **kwargs)
  File "/home/shivamkumarsain/Projects/Creworder-Django/shipment/views.py", line 90, in get
    data = checkServiceability(request.user.profile.branch_id,request.user.profile.company_id, request.data['pincode'])
  File "/home/shivamkumarsain/Projects/Creworder-Django/services/shipment/shipment_service.py", line 125, in checkServiceability
    if response.json()['status']==200:
KeyError: 'status'
2024-10-08 17:35:01,679 - django.request - ERROR - Internal Server Error: /api/check-serviceability/
Traceback (most recent call last):
  File "/usr/local/lib/python3.10/dist-packages/django/core/handlers/exception.py", line 55, in inner
    response = get_response(request)
  File "/usr/local/lib/python3.10/dist-packages/django/core/handlers/base.py", line 197, in _get_response
    response = wrapped_callback(request, *callback_args, **callback_kwargs)
  File "/usr/local/lib/python3.10/dist-packages/django/views/decorators/csrf.py", line 65, in _view_wrapper
    return view_func(request, *args, **kwargs)
  File "/usr/local/lib/python3.10/dist-packages/django/views/generic/base.py", line 104, in view
    return self.dispatch(request, *args, **kwargs)
  File "/usr/local/lib/python3.10/dist-packages/rest_framework/views.py", line 509, in dispatch
    response = self.handle_exception(exc)
  File "/usr/local/lib/python3.10/dist-packages/rest_framework/views.py", line 469, in handle_exception
    self.raise_uncaught_exception(exc)
  File "/usr/local/lib/python3.10/dist-packages/rest_framework/views.py", line 480, in raise_uncaught_exception
    raise exc
  File "/usr/local/lib/python3.10/dist-packages/rest_framework/views.py", line 506, in dispatch
    response = handler(request, *args, **kwargs)
  File "/home/shivamkumarsain/Projects/Creworder-Django/shipment/views.py", line 90, in get
    data = checkServiceability(request.user.profile.branch_id,request.user.profile.company_id, request.data['pincode'])
  File "/home/shivamkumarsain/Projects/Creworder-Django/services/shipment/shipment_service.py", line 109, in checkServiceability
    token=getShipRocketToken(data['credential_username'],data['credential_password'])
  File "/home/shivamkumarsain/Projects/Creworder-Django/services/shipment/shipment_service.py", line 28, in getShipRocketToken
    if response.json()['status_code']==200:
KeyError: 'status_code'
2024-10-08 17:36:37,846 - django.request - ERROR - Internal Server Error: /api/check-serviceability/
Traceback (most recent call last):
  File "/usr/local/lib/python3.10/dist-packages/django/core/handlers/exception.py", line 55, in inner
    response = get_response(request)
  File "/usr/local/lib/python3.10/dist-packages/django/core/handlers/base.py", line 197, in _get_response
    response = wrapped_callback(request, *callback_args, **callback_kwargs)
  File "/usr/local/lib/python3.10/dist-packages/django/views/decorators/csrf.py", line 65, in _view_wrapper
    return view_func(request, *args, **kwargs)
  File "/usr/local/lib/python3.10/dist-packages/django/views/generic/base.py", line 104, in view
    return self.dispatch(request, *args, **kwargs)
  File "/usr/local/lib/python3.10/dist-packages/rest_framework/views.py", line 509, in dispatch
    response = self.handle_exception(exc)
  File "/usr/local/lib/python3.10/dist-packages/rest_framework/views.py", line 469, in handle_exception
    self.raise_uncaught_exception(exc)
  File "/usr/local/lib/python3.10/dist-packages/rest_framework/views.py", line 480, in raise_uncaught_exception
    raise exc
  File "/usr/local/lib/python3.10/dist-packages/rest_framework/views.py", line 506, in dispatch
    response = handler(request, *args, **kwargs)
  File "/home/shivamkumarsain/Projects/Creworder-Django/shipment/views.py", line 90, in get
    data = checkServiceability(request.user.profile.branch_id,request.user.profile.company_id, request.data['pincode'])
  File "/home/shivamkumarsain/Projects/Creworder-Django/services/shipment/shipment_service.py", line 127, in checkServiceability
    if response.json()['status']==200:
KeyError: 'status'
2024-10-08 17:38:22,798 - django.request - ERROR - Internal Server Error: /api/check-serviceability/
Traceback (most recent call last):
  File "/usr/local/lib/python3.10/dist-packages/django/core/handlers/exception.py", line 55, in inner
    response = get_response(request)
  File "/usr/local/lib/python3.10/dist-packages/django/core/handlers/base.py", line 197, in _get_response
    response = wrapped_callback(request, *callback_args, **callback_kwargs)
  File "/usr/local/lib/python3.10/dist-packages/django/views/decorators/csrf.py", line 65, in _view_wrapper
    return view_func(request, *args, **kwargs)
  File "/usr/local/lib/python3.10/dist-packages/django/views/generic/base.py", line 104, in view
    return self.dispatch(request, *args, **kwargs)
  File "/usr/local/lib/python3.10/dist-packages/rest_framework/views.py", line 509, in dispatch
    response = self.handle_exception(exc)
  File "/usr/local/lib/python3.10/dist-packages/rest_framework/views.py", line 469, in handle_exception
    self.raise_uncaught_exception(exc)
  File "/usr/local/lib/python3.10/dist-packages/rest_framework/views.py", line 480, in raise_uncaught_exception
    raise exc
  File "/usr/local/lib/python3.10/dist-packages/rest_framework/views.py", line 506, in dispatch
    response = handler(request, *args, **kwargs)
  File "/home/shivamkumarsain/Projects/Creworder-Django/shipment/views.py", line 90, in get
    data = checkServiceability(request.user.profile.branch_id,request.user.profile.company_id, request.data['pincode'])
  File "/home/shivamkumarsain/Projects/Creworder-Django/services/shipment/shipment_service.py", line 126, in checkServiceability
    if response.json()['status']==200:
KeyError: 'status'
2024-10-08 17:39:55,993 - django.request - ERROR - Internal Server Error: /api/check-serviceability/
Traceback (most recent call last):
  File "/usr/local/lib/python3.10/dist-packages/django/core/handlers/exception.py", line 55, in inner
    response = get_response(request)
  File "/usr/local/lib/python3.10/dist-packages/django/core/handlers/base.py", line 197, in _get_response
    response = wrapped_callback(request, *callback_args, **callback_kwargs)
  File "/usr/local/lib/python3.10/dist-packages/django/views/decorators/csrf.py", line 65, in _view_wrapper
    return view_func(request, *args, **kwargs)
  File "/usr/local/lib/python3.10/dist-packages/django/views/generic/base.py", line 104, in view
    return self.dispatch(request, *args, **kwargs)
  File "/usr/local/lib/python3.10/dist-packages/rest_framework/views.py", line 509, in dispatch
    response = self.handle_exception(exc)
  File "/usr/local/lib/python3.10/dist-packages/rest_framework/views.py", line 469, in handle_exception
    self.raise_uncaught_exception(exc)
  File "/usr/local/lib/python3.10/dist-packages/rest_framework/views.py", line 480, in raise_uncaught_exception
    raise exc
  File "/usr/local/lib/python3.10/dist-packages/rest_framework/views.py", line 506, in dispatch
    response = handler(request, *args, **kwargs)
  File "/home/shivamkumarsain/Projects/Creworder-Django/shipment/views.py", line 90, in get
    data = checkServiceability(request.user.profile.branch_id,request.user.profile.company_id, request.data['pincode'])
  File "/home/shivamkumarsain/Projects/Creworder-Django/services/shipment/shipment_service.py", line 125, in checkServiceability
    if response.json()['status']==200:
KeyError: 'status'
2024-10-08 17:42:37,142 - django.request - ERROR - Internal Server Error: /api/check-serviceability/
Traceback (most recent call last):
  File "/usr/local/lib/python3.10/dist-packages/django/core/handlers/exception.py", line 55, in inner
    response = get_response(request)
  File "/usr/local/lib/python3.10/dist-packages/django/core/handlers/base.py", line 197, in _get_response
    response = wrapped_callback(request, *callback_args, **callback_kwargs)
  File "/usr/local/lib/python3.10/dist-packages/django/views/decorators/csrf.py", line 65, in _view_wrapper
    return view_func(request, *args, **kwargs)
  File "/usr/local/lib/python3.10/dist-packages/django/views/generic/base.py", line 104, in view
    return self.dispatch(request, *args, **kwargs)
  File "/usr/local/lib/python3.10/dist-packages/rest_framework/views.py", line 509, in dispatch
    response = self.handle_exception(exc)
  File "/usr/local/lib/python3.10/dist-packages/rest_framework/views.py", line 469, in handle_exception
    self.raise_uncaught_exception(exc)
  File "/usr/local/lib/python3.10/dist-packages/rest_framework/views.py", line 480, in raise_uncaught_exception
    raise exc
  File "/usr/local/lib/python3.10/dist-packages/rest_framework/views.py", line 506, in dispatch
    response = handler(request, *args, **kwargs)
  File "/home/shivamkumarsain/Projects/Creworder-Django/shipment/views.py", line 90, in get
    data = checkServiceability(request.user.profile.branch_id,request.user.profile.company_id, request.data['pincode'])
  File "/home/shivamkumarsain/Projects/Creworder-Django/services/shipment/shipment_service.py", line 109, in checkServiceability
    token=getShipRocketToken(data['credential_username'],data['credential_password'])
  File "/home/shivamkumarsain/Projects/Creworder-Django/services/shipment/shipment_service.py", line 28, in getShipRocketToken
    if response.json()['status_code']==200:
KeyError: 'status_code'
2024-10-08 17:43:24,299 - django.request - ERROR - Internal Server Error: /api/check-serviceability/
Traceback (most recent call last):
  File "/usr/local/lib/python3.10/dist-packages/django/core/handlers/exception.py", line 55, in inner
    response = get_response(request)
  File "/usr/local/lib/python3.10/dist-packages/django/core/handlers/base.py", line 197, in _get_response
    response = wrapped_callback(request, *callback_args, **callback_kwargs)
  File "/usr/local/lib/python3.10/dist-packages/django/views/decorators/csrf.py", line 65, in _view_wrapper
    return view_func(request, *args, **kwargs)
  File "/usr/local/lib/python3.10/dist-packages/django/views/generic/base.py", line 104, in view
    return self.dispatch(request, *args, **kwargs)
  File "/usr/local/lib/python3.10/dist-packages/rest_framework/views.py", line 509, in dispatch
    response = self.handle_exception(exc)
  File "/usr/local/lib/python3.10/dist-packages/rest_framework/views.py", line 469, in handle_exception
    self.raise_uncaught_exception(exc)
  File "/usr/local/lib/python3.10/dist-packages/rest_framework/views.py", line 480, in raise_uncaught_exception
    raise exc
  File "/usr/local/lib/python3.10/dist-packages/rest_framework/views.py", line 506, in dispatch
    response = handler(request, *args, **kwargs)
  File "/home/shivamkumarsain/Projects/Creworder-Django/shipment/views.py", line 90, in get
    data = checkServiceability(request.user.profile.branch_id,request.user.profile.company_id, request.data['pincode'])
  File "/home/shivamkumarsain/Projects/Creworder-Django/services/shipment/shipment_service.py", line 109, in checkServiceability
    token=getShipRocketToken(data['credential_username'],data['credential_password'])
  File "/home/shivamkumarsain/Projects/Creworder-Django/services/shipment/shipment_service.py", line 28, in getShipRocketToken
    if response.json()['status_code']==200:
KeyError: 'status_code'
2024-10-08 17:43:56,284 - django.request - WARNING - Not Found: /api/check-serviceability/
2024-10-08 17:44:07,627 - django.request - WARNING - Not Found: /api/check-serviceability/
2024-10-08 18:01:32,308 - django.request - ERROR - Internal Server Error: /api/check-serviceability/
Traceback (most recent call last):
  File "/usr/local/lib/python3.10/dist-packages/django/core/handlers/exception.py", line 55, in inner
    response = get_response(request)
  File "/usr/local/lib/python3.10/dist-packages/django/core/handlers/base.py", line 197, in _get_response
    response = wrapped_callback(request, *callback_args, **callback_kwargs)
  File "/usr/local/lib/python3.10/dist-packages/django/views/decorators/csrf.py", line 65, in _view_wrapper
    return view_func(request, *args, **kwargs)
  File "/usr/local/lib/python3.10/dist-packages/django/views/generic/base.py", line 104, in view
    return self.dispatch(request, *args, **kwargs)
  File "/usr/local/lib/python3.10/dist-packages/rest_framework/views.py", line 509, in dispatch
    response = self.handle_exception(exc)
  File "/usr/local/lib/python3.10/dist-packages/rest_framework/views.py", line 469, in handle_exception
    self.raise_uncaught_exception(exc)
  File "/usr/local/lib/python3.10/dist-packages/rest_framework/views.py", line 480, in raise_uncaught_exception
    raise exc
  File "/usr/local/lib/python3.10/dist-packages/rest_framework/views.py", line 506, in dispatch
    response = handler(request, *args, **kwargs)
  File "/home/shivamkumarsain/Projects/Creworder-Django/shipment/views.py", line 90, in get
    data = checkServiceability(request.user.profile.branch_id,request.user.profile.company_id, request.data['pincode'])
  File "/home/shivamkumarsain/Projects/Creworder-Django/services/shipment/shipment_service.py", line 109, in checkServiceability
    token=getShipRocketToken(data['credential_username'],data['credential_password'])
  File "/home/shivamkumarsain/Projects/Creworder-Django/services/shipment/shipment_service.py", line 28, in getShipRocketToken
    if response.json()['status_code']==200:
KeyError: 'status_code'
2024-10-08 18:04:11,616 - django.request - ERROR - Internal Server Error: /api/check-serviceability/
Traceback (most recent call last):
  File "/usr/local/lib/python3.10/dist-packages/django/core/handlers/exception.py", line 55, in inner
    response = get_response(request)
  File "/usr/local/lib/python3.10/dist-packages/django/core/handlers/base.py", line 197, in _get_response
    response = wrapped_callback(request, *callback_args, **callback_kwargs)
  File "/usr/local/lib/python3.10/dist-packages/django/views/decorators/csrf.py", line 65, in _view_wrapper
    return view_func(request, *args, **kwargs)
  File "/usr/local/lib/python3.10/dist-packages/django/views/generic/base.py", line 104, in view
    return self.dispatch(request, *args, **kwargs)
  File "/usr/local/lib/python3.10/dist-packages/rest_framework/views.py", line 509, in dispatch
    response = self.handle_exception(exc)
  File "/usr/local/lib/python3.10/dist-packages/rest_framework/views.py", line 469, in handle_exception
    self.raise_uncaught_exception(exc)
  File "/usr/local/lib/python3.10/dist-packages/rest_framework/views.py", line 480, in raise_uncaught_exception
    raise exc
  File "/usr/local/lib/python3.10/dist-packages/rest_framework/views.py", line 506, in dispatch
    response = handler(request, *args, **kwargs)
  File "/home/shivamkumarsain/Projects/Creworder-Django/shipment/views.py", line 90, in get
    data = checkServiceability(request.user.profile.branch_id,request.user.profile.company_id, request.data['pincode'])
  File "/home/shivamkumarsain/Projects/Creworder-Django/services/shipment/shipment_service.py", line 110, in checkServiceability
    token=getShipRocketToken(data['credential_username'],data['credential_password'])
  File "/home/shivamkumarsain/Projects/Creworder-Django/services/shipment/shipment_service.py", line 29, in getShipRocketToken
    if response.json()['status_code']==200:
KeyError: 'status_code'
2024-10-08 18:05:34,914 - django.request - ERROR - Internal Server Error: /api/check-serviceability/
Traceback (most recent call last):
  File "/usr/local/lib/python3.10/dist-packages/django/core/handlers/exception.py", line 55, in inner
    response = get_response(request)
  File "/usr/local/lib/python3.10/dist-packages/django/core/handlers/base.py", line 197, in _get_response
    response = wrapped_callback(request, *callback_args, **callback_kwargs)
  File "/usr/local/lib/python3.10/dist-packages/django/views/decorators/csrf.py", line 65, in _view_wrapper
    return view_func(request, *args, **kwargs)
  File "/usr/local/lib/python3.10/dist-packages/django/views/generic/base.py", line 104, in view
    return self.dispatch(request, *args, **kwargs)
  File "/usr/local/lib/python3.10/dist-packages/rest_framework/views.py", line 509, in dispatch
    response = self.handle_exception(exc)
  File "/usr/local/lib/python3.10/dist-packages/rest_framework/views.py", line 469, in handle_exception
    self.raise_uncaught_exception(exc)
  File "/usr/local/lib/python3.10/dist-packages/rest_framework/views.py", line 480, in raise_uncaught_exception
    raise exc
  File "/usr/local/lib/python3.10/dist-packages/rest_framework/views.py", line 506, in dispatch
    response = handler(request, *args, **kwargs)
  File "/home/shivamkumarsain/Projects/Creworder-Django/shipment/views.py", line 90, in get
    data = checkServiceability(request.user.profile.branch_id,request.user.profile.company_id, request.data['pincode'])
  File "/home/shivamkumarsain/Projects/Creworder-Django/services/shipment/shipment_service.py", line 110, in checkServiceability
    token=getShipRocketToken(data['credential_username'],data['credential_password'])
  File "/home/shivamkumarsain/Projects/Creworder-Django/services/shipment/shipment_service.py", line 29, in getShipRocketToken
    if response.json()['status_code']==200:
KeyError: 'status_code'
2024-10-08 18:06:04,549 - django.request - WARNING - Not Found: /api/check-serviceability/
2024-10-08 18:06:18,071 - django.request - WARNING - Not Found: /api/check-serviceability/
2024-10-09 10:15:57,440 - django.request - WARNING - Not Found: /favicon.ico
2024-10-09 12:19:33,460 - django.request - ERROR - Internal Server Error: /api/check-serviceability/
Traceback (most recent call last):
  File "/usr/local/lib/python3.10/dist-packages/django/core/handlers/exception.py", line 55, in inner
    response = get_response(request)
  File "/usr/local/lib/python3.10/dist-packages/django/core/handlers/base.py", line 197, in _get_response
    response = wrapped_callback(request, *callback_args, **callback_kwargs)
  File "/usr/local/lib/python3.10/dist-packages/django/views/decorators/csrf.py", line 65, in _view_wrapper
    return view_func(request, *args, **kwargs)
  File "/usr/local/lib/python3.10/dist-packages/django/views/generic/base.py", line 104, in view
    return self.dispatch(request, *args, **kwargs)
  File "/usr/local/lib/python3.10/dist-packages/rest_framework/views.py", line 509, in dispatch
    response = self.handle_exception(exc)
  File "/usr/local/lib/python3.10/dist-packages/rest_framework/views.py", line 469, in handle_exception
    self.raise_uncaught_exception(exc)
  File "/usr/local/lib/python3.10/dist-packages/rest_framework/views.py", line 480, in raise_uncaught_exception
    raise exc
  File "/usr/local/lib/python3.10/dist-packages/rest_framework/views.py", line 506, in dispatch
    response = handler(request, *args, **kwargs)
  File "/home/shivamkumarsain/Projects/Creworder-Django/orders/views.py", line 299, in get
    data = checkServiceability(request.user.profile.branch_id,request.user.profile.company_id, request.data['pincode'])
  File "/home/shivamkumarsain/Projects/Creworder-Django/services/orders/order_service.py", line 271, in checkServiceability
    trackdata = ShipmentModel.objects.filter(branch=branch_id,company=company_id,status=1)
NameError: name 'ShipmentModel' is not defined
2024-10-09 12:20:17,124 - django.request - ERROR - Internal Server Error: /api/check-serviceability/
Traceback (most recent call last):
  File "/usr/local/lib/python3.10/dist-packages/django/core/handlers/exception.py", line 55, in inner
    response = get_response(request)
  File "/usr/local/lib/python3.10/dist-packages/django/core/handlers/base.py", line 197, in _get_response
    response = wrapped_callback(request, *callback_args, **callback_kwargs)
  File "/usr/local/lib/python3.10/dist-packages/django/views/decorators/csrf.py", line 65, in _view_wrapper
    return view_func(request, *args, **kwargs)
  File "/usr/local/lib/python3.10/dist-packages/django/views/generic/base.py", line 104, in view
    return self.dispatch(request, *args, **kwargs)
  File "/usr/local/lib/python3.10/dist-packages/rest_framework/views.py", line 509, in dispatch
    response = self.handle_exception(exc)
  File "/usr/local/lib/python3.10/dist-packages/rest_framework/views.py", line 469, in handle_exception
    self.raise_uncaught_exception(exc)
  File "/usr/local/lib/python3.10/dist-packages/rest_framework/views.py", line 480, in raise_uncaught_exception
    raise exc
  File "/usr/local/lib/python3.10/dist-packages/rest_framework/views.py", line 506, in dispatch
    response = handler(request, *args, **kwargs)
  File "/home/shivamkumarsain/Projects/Creworder-Django/orders/views.py", line 299, in get
    data = checkServiceability(request.user.profile.branch_id,request.user.profile.company_id, request.data['pincode'])
  File "/home/shivamkumarsain/Projects/Creworder-Django/services/orders/order_service.py", line 274, in checkServiceability
    pickUppointData = PickUpPoint.objects.filter(company=company_id,status=1)
NameError: name 'PickUpPoint' is not defined
2024-10-09 12:20:51,403 - django.request - ERROR - Internal Server Error: /api/check-serviceability/
Traceback (most recent call last):
  File "/usr/local/lib/python3.10/dist-packages/django/core/handlers/exception.py", line 55, in inner
    response = get_response(request)
  File "/usr/local/lib/python3.10/dist-packages/django/core/handlers/base.py", line 197, in _get_response
    response = wrapped_callback(request, *callback_args, **callback_kwargs)
  File "/usr/local/lib/python3.10/dist-packages/django/views/decorators/csrf.py", line 65, in _view_wrapper
    return view_func(request, *args, **kwargs)
  File "/usr/local/lib/python3.10/dist-packages/django/views/generic/base.py", line 104, in view
    return self.dispatch(request, *args, **kwargs)
  File "/usr/local/lib/python3.10/dist-packages/rest_framework/views.py", line 509, in dispatch
    response = self.handle_exception(exc)
  File "/usr/local/lib/python3.10/dist-packages/rest_framework/views.py", line 469, in handle_exception
    self.raise_uncaught_exception(exc)
  File "/usr/local/lib/python3.10/dist-packages/rest_framework/views.py", line 480, in raise_uncaught_exception
    raise exc
  File "/usr/local/lib/python3.10/dist-packages/rest_framework/views.py", line 506, in dispatch
    response = handler(request, *args, **kwargs)
  File "/home/shivamkumarsain/Projects/Creworder-Django/orders/views.py", line 299, in get
    data = checkServiceability(request.user.profile.branch_id,request.user.profile.company_id, request.data['pincode'])
  File "/home/shivamkumarsain/Projects/Creworder-Django/services/orders/order_service.py", line 276, in checkServiceability
    pickUpSerializerData = PickUpPointSerializer(pickUppointData, many=True)
NameError: name 'PickUpPointSerializer' is not defined
2024-10-09 12:31:30,616 - django.request - ERROR - Internal Server Error: /api/check-serviceability/
Traceback (most recent call last):
  File "/usr/local/lib/python3.10/dist-packages/django/core/handlers/exception.py", line 55, in inner
    response = get_response(request)
  File "/usr/local/lib/python3.10/dist-packages/django/core/handlers/base.py", line 197, in _get_response
    response = wrapped_callback(request, *callback_args, **callback_kwargs)
  File "/usr/local/lib/python3.10/dist-packages/django/views/decorators/csrf.py", line 65, in _view_wrapper
    return view_func(request, *args, **kwargs)
  File "/usr/local/lib/python3.10/dist-packages/django/views/generic/base.py", line 104, in view
    return self.dispatch(request, *args, **kwargs)
  File "/usr/local/lib/python3.10/dist-packages/rest_framework/views.py", line 509, in dispatch
    response = self.handle_exception(exc)
  File "/usr/local/lib/python3.10/dist-packages/rest_framework/views.py", line 469, in handle_exception
    self.raise_uncaught_exception(exc)
  File "/usr/local/lib/python3.10/dist-packages/rest_framework/views.py", line 480, in raise_uncaught_exception
    raise exc
  File "/usr/local/lib/python3.10/dist-packages/rest_framework/views.py", line 506, in dispatch
    response = handler(request, *args, **kwargs)
  File "/home/shivamkumarsain/Projects/Creworder-Django/orders/views.py", line 299, in get
    data = checkServiceability(request.user.profile.branch_id,request.user.profile.company_id, {request.data['pincode'],request.data['mobile']})
  File "/home/shivamkumarsain/Projects/Creworder-Django/services/orders/order_service.py", line 274, in checkServiceability
    pincode=data['pincode']
TypeError: 'set' object is not subscriptable
2024-10-09 12:32:10,905 - django.request - ERROR - Internal Server Error: /api/check-serviceability/
Traceback (most recent call last):
  File "/usr/local/lib/python3.10/dist-packages/django/core/handlers/exception.py", line 55, in inner
    response = get_response(request)
  File "/usr/local/lib/python3.10/dist-packages/django/core/handlers/base.py", line 197, in _get_response
    response = wrapped_callback(request, *callback_args, **callback_kwargs)
  File "/usr/local/lib/python3.10/dist-packages/django/views/decorators/csrf.py", line 65, in _view_wrapper
    return view_func(request, *args, **kwargs)
  File "/usr/local/lib/python3.10/dist-packages/django/views/generic/base.py", line 104, in view
    return self.dispatch(request, *args, **kwargs)
  File "/usr/local/lib/python3.10/dist-packages/rest_framework/views.py", line 509, in dispatch
    response = self.handle_exception(exc)
  File "/usr/local/lib/python3.10/dist-packages/rest_framework/views.py", line 469, in handle_exception
    self.raise_uncaught_exception(exc)
  File "/usr/local/lib/python3.10/dist-packages/rest_framework/views.py", line 480, in raise_uncaught_exception
    raise exc
  File "/usr/local/lib/python3.10/dist-packages/rest_framework/views.py", line 506, in dispatch
    response = handler(request, *args, **kwargs)
  File "/home/shivamkumarsain/Projects/Creworder-Django/orders/views.py", line 299, in get
    data = checkServiceability(request.user.profile.branch_id,request.user.profile.company_id, {request.data['pincode'],request.data['mobile']})
  File "/home/shivamkumarsain/Projects/Creworder-Django/services/orders/order_service.py", line 275, in checkServiceability
    pincode=data['pincode']
TypeError: 'set' object is not subscriptable
2024-10-09 12:42:19,789 - django.request - WARNING - Bad Request: /api/orders/
2024-10-09 12:43:52,878 - django.request - WARNING - Bad Request: /api/orders/
2024-10-09 12:47:35,910 - django.request - WARNING - Bad Request: /api/orders/
2024-10-09 12:49:24,501 - django.request - WARNING - Bad Request: /api/orders/
2024-10-09 12:50:09,158 - django.request - WARNING - Bad Request: /api/orders/
2024-10-09 12:50:26,910 - django.request - WARNING - Bad Request: /api/orders/
2024-10-09 12:50:34,882 - django.request - WARNING - Bad Request: /api/orders/
2024-10-09 12:50:43,797 - django.request - ERROR - Internal Server Error: /api/orders/
Traceback (most recent call last):
  File "/usr/local/lib/python3.10/dist-packages/django/core/handlers/exception.py", line 55, in inner
    response = get_response(request)
  File "/usr/local/lib/python3.10/dist-packages/django/core/handlers/base.py", line 197, in _get_response
    response = wrapped_callback(request, *callback_args, **callback_kwargs)
  File "/usr/local/lib/python3.10/dist-packages/django/views/decorators/csrf.py", line 65, in _view_wrapper
    return view_func(request, *args, **kwargs)
  File "/usr/local/lib/python3.10/dist-packages/django/views/generic/base.py", line 104, in view
    return self.dispatch(request, *args, **kwargs)
  File "/usr/local/lib/python3.10/dist-packages/rest_framework/views.py", line 509, in dispatch
    response = self.handle_exception(exc)
  File "/usr/local/lib/python3.10/dist-packages/rest_framework/views.py", line 469, in handle_exception
    self.raise_uncaught_exception(exc)
  File "/usr/local/lib/python3.10/dist-packages/rest_framework/views.py", line 480, in raise_uncaught_exception
    raise exc
  File "/usr/local/lib/python3.10/dist-packages/rest_framework/views.py", line 506, in dispatch
    response = handler(request, *args, **kwargs)
  File "/home/shivamkumarsain/Projects/Creworder-Django/orders/views.py", line 29, in post
    createOrdersResponse = createOrders(request.data, request.user.id)
  File "/home/shivamkumarsain/Projects/Creworder-Django/services/orders/order_service.py", line 161, in createOrders
    products = ProductModel.objects.filter(id=product['product']).first()
KeyError: 'product'
2024-10-09 12:51:28,200 - django.request - WARNING - Bad Request: /api/orders/
2024-10-09 12:52:06,796 - django.request - ERROR - Internal Server Error: /api/orders/
Traceback (most recent call last):
  File "/usr/local/lib/python3.10/dist-packages/django/core/handlers/exception.py", line 55, in inner
    response = get_response(request)
  File "/usr/local/lib/python3.10/dist-packages/django/core/handlers/base.py", line 197, in _get_response
    response = wrapped_callback(request, *callback_args, **callback_kwargs)
  File "/usr/local/lib/python3.10/dist-packages/django/views/decorators/csrf.py", line 65, in _view_wrapper
    return view_func(request, *args, **kwargs)
  File "/usr/local/lib/python3.10/dist-packages/django/views/generic/base.py", line 104, in view
    return self.dispatch(request, *args, **kwargs)
  File "/usr/local/lib/python3.10/dist-packages/rest_framework/views.py", line 509, in dispatch
    response = self.handle_exception(exc)
  File "/usr/local/lib/python3.10/dist-packages/rest_framework/views.py", line 469, in handle_exception
    self.raise_uncaught_exception(exc)
  File "/usr/local/lib/python3.10/dist-packages/rest_framework/views.py", line 480, in raise_uncaught_exception
    raise exc
  File "/usr/local/lib/python3.10/dist-packages/rest_framework/views.py", line 506, in dispatch
    response = handler(request, *args, **kwargs)
  File "/home/shivamkumarsain/Projects/Creworder-Django/orders/views.py", line 29, in post
    createOrdersResponse = createOrders(request.data, request.user.id)
  File "/home/shivamkumarsain/Projects/Creworder-Django/services/orders/order_service.py", line 161, in createOrders
    products = ProductModel.objects.filter(id=product['product']).first()
KeyError: 'product'
2024-10-09 13:42:06,489 - django.request - WARNING - Bad Request: /api/orders/
2024-10-09 13:42:07,045 - django.request - WARNING - Bad Request: /api/orders/
2024-10-09 13:42:36,567 - django.request - ERROR - Internal Server Error: /api/orders/
Traceback (most recent call last):
  File "/usr/local/lib/python3.10/dist-packages/django/core/handlers/exception.py", line 55, in inner
    response = get_response(request)
  File "/usr/local/lib/python3.10/dist-packages/django/core/handlers/base.py", line 197, in _get_response
    response = wrapped_callback(request, *callback_args, **callback_kwargs)
  File "/usr/local/lib/python3.10/dist-packages/django/views/decorators/csrf.py", line 65, in _view_wrapper
    return view_func(request, *args, **kwargs)
  File "/usr/local/lib/python3.10/dist-packages/django/views/generic/base.py", line 104, in view
    return self.dispatch(request, *args, **kwargs)
  File "/usr/local/lib/python3.10/dist-packages/rest_framework/views.py", line 509, in dispatch
    response = self.handle_exception(exc)
  File "/usr/local/lib/python3.10/dist-packages/rest_framework/views.py", line 469, in handle_exception
    self.raise_uncaught_exception(exc)
  File "/usr/local/lib/python3.10/dist-packages/rest_framework/views.py", line 480, in raise_uncaught_exception
    raise exc
  File "/usr/local/lib/python3.10/dist-packages/rest_framework/views.py", line 506, in dispatch
    response = handler(request, *args, **kwargs)
  File "/home/shivamkumarsain/Projects/Creworder-Django/orders/views.py", line 29, in post
    createOrdersResponse = createOrders(request.data, request.user.id)
  File "/home/shivamkumarsain/Projects/Creworder-Django/services/orders/order_service.py", line 162, in createOrders
    products = ProductModel.objects.filter(id=product['product']).first()
KeyError: 'product'
2024-10-09 13:45:08,686 - django.request - WARNING - Bad Request: /api/orders/
2024-10-09 13:45:39,034 - django.request - ERROR - Internal Server Error: /api/orders/
Traceback (most recent call last):
  File "/usr/local/lib/python3.10/dist-packages/django/core/handlers/exception.py", line 55, in inner
    response = get_response(request)
  File "/usr/local/lib/python3.10/dist-packages/django/core/handlers/base.py", line 197, in _get_response
    response = wrapped_callback(request, *callback_args, **callback_kwargs)
  File "/usr/local/lib/python3.10/dist-packages/django/views/decorators/csrf.py", line 65, in _view_wrapper
    return view_func(request, *args, **kwargs)
  File "/usr/local/lib/python3.10/dist-packages/django/views/generic/base.py", line 104, in view
    return self.dispatch(request, *args, **kwargs)
  File "/usr/local/lib/python3.10/dist-packages/rest_framework/views.py", line 509, in dispatch
    response = self.handle_exception(exc)
  File "/usr/local/lib/python3.10/dist-packages/rest_framework/views.py", line 469, in handle_exception
    self.raise_uncaught_exception(exc)
  File "/usr/local/lib/python3.10/dist-packages/rest_framework/views.py", line 480, in raise_uncaught_exception
    raise exc
  File "/usr/local/lib/python3.10/dist-packages/rest_framework/views.py", line 506, in dispatch
    response = handler(request, *args, **kwargs)
  File "/home/shivamkumarsain/Projects/Creworder-Django/orders/views.py", line 29, in post
    createOrdersResponse = createOrders(request.data, request.user.id)
  File "/home/shivamkumarsain/Projects/Creworder-Django/services/orders/order_service.py", line 161, in createOrders
    products = ProductModel.objects.filter(id=product['product']).first()
KeyError: 'product'
2024-10-09 13:46:13,641 - django.request - WARNING - Bad Request: /api/orders/
2024-10-09 13:46:30,650 - django.request - WARNING - Bad Request: /api/orders/
2024-10-09 13:57:30,706 - django.request - WARNING - Bad Request: /api/orders/
2024-10-09 13:57:50,421 - django.request - ERROR - Internal Server Error: /api/orders/
Traceback (most recent call last):
  File "/usr/local/lib/python3.10/dist-packages/django/core/handlers/exception.py", line 55, in inner
    response = get_response(request)
  File "/usr/local/lib/python3.10/dist-packages/django/core/handlers/base.py", line 197, in _get_response
    response = wrapped_callback(request, *callback_args, **callback_kwargs)
  File "/usr/local/lib/python3.10/dist-packages/django/views/decorators/csrf.py", line 65, in _view_wrapper
    return view_func(request, *args, **kwargs)
  File "/usr/local/lib/python3.10/dist-packages/django/views/generic/base.py", line 104, in view
    return self.dispatch(request, *args, **kwargs)
  File "/usr/local/lib/python3.10/dist-packages/rest_framework/views.py", line 509, in dispatch
    response = self.handle_exception(exc)
  File "/usr/local/lib/python3.10/dist-packages/rest_framework/views.py", line 469, in handle_exception
    self.raise_uncaught_exception(exc)
  File "/usr/local/lib/python3.10/dist-packages/rest_framework/views.py", line 480, in raise_uncaught_exception
    raise exc
  File "/usr/local/lib/python3.10/dist-packages/rest_framework/views.py", line 506, in dispatch
    response = handler(request, *args, **kwargs)
  File "/home/shivamkumarsain/Projects/Creworder-Django/orders/views.py", line 29, in post
    createOrdersResponse = createOrders(request.data, request.user.id)
  File "/home/shivamkumarsain/Projects/Creworder-Django/services/orders/order_service.py", line 162, in createOrders
    products = ProductModel.objects.filter(id=product['product']).first()
KeyError: 'product'
2024-10-09 14:02:59,855 - django.request - WARNING - Bad Request: /api/orders/
2024-10-09 14:03:39,339 - django.request - WARNING - Bad Request: /api/orders/
2024-10-09 14:03:49,944 - django.request - ERROR - Internal Server Error: /api/orders/
Traceback (most recent call last):
  File "/usr/local/lib/python3.10/dist-packages/django/core/handlers/exception.py", line 55, in inner
    response = get_response(request)
  File "/usr/local/lib/python3.10/dist-packages/django/core/handlers/base.py", line 197, in _get_response
    response = wrapped_callback(request, *callback_args, **callback_kwargs)
  File "/usr/local/lib/python3.10/dist-packages/django/views/decorators/csrf.py", line 65, in _view_wrapper
    return view_func(request, *args, **kwargs)
  File "/usr/local/lib/python3.10/dist-packages/django/views/generic/base.py", line 104, in view
    return self.dispatch(request, *args, **kwargs)
  File "/usr/local/lib/python3.10/dist-packages/rest_framework/views.py", line 509, in dispatch
    response = self.handle_exception(exc)
  File "/usr/local/lib/python3.10/dist-packages/rest_framework/views.py", line 469, in handle_exception
    self.raise_uncaught_exception(exc)
  File "/usr/local/lib/python3.10/dist-packages/rest_framework/views.py", line 480, in raise_uncaught_exception
    raise exc
  File "/usr/local/lib/python3.10/dist-packages/rest_framework/views.py", line 506, in dispatch
    response = handler(request, *args, **kwargs)
  File "/home/shivamkumarsain/Projects/Creworder-Django/orders/views.py", line 29, in post
    createOrdersResponse = createOrders(request.data, request.user.id)
  File "/home/shivamkumarsain/Projects/Creworder-Django/services/orders/order_service.py", line 162, in createOrders
    products = ProductModel.objects.filter(id=product['product']).first()
KeyError: 'product'
2024-10-09 14:04:02,901 - django.request - WARNING - Bad Request: /api/orders/
2024-10-09 14:13:55,175 - django.request - WARNING - Bad Request: /api/orders/
2024-10-09 14:50:06,733 - django.request - ERROR - Internal Server Error: /api/check-serviceability/
Traceback (most recent call last):
  File "/usr/local/lib/python3.10/dist-packages/django/core/handlers/exception.py", line 55, in inner
    response = get_response(request)
  File "/usr/local/lib/python3.10/dist-packages/django/core/handlers/base.py", line 197, in _get_response
    response = wrapped_callback(request, *callback_args, **callback_kwargs)
  File "/usr/local/lib/python3.10/dist-packages/django/views/decorators/csrf.py", line 65, in _view_wrapper
    return view_func(request, *args, **kwargs)
  File "/usr/local/lib/python3.10/dist-packages/django/views/generic/base.py", line 104, in view
    return self.dispatch(request, *args, **kwargs)
  File "/usr/local/lib/python3.10/dist-packages/rest_framework/views.py", line 509, in dispatch
    response = self.handle_exception(exc)
  File "/usr/local/lib/python3.10/dist-packages/rest_framework/views.py", line 469, in handle_exception
    self.raise_uncaught_exception(exc)
  File "/usr/local/lib/python3.10/dist-packages/rest_framework/views.py", line 480, in raise_uncaught_exception
    raise exc
  File "/usr/local/lib/python3.10/dist-packages/rest_framework/views.py", line 506, in dispatch
    response = handler(request, *args, **kwargs)
  File "/home/shivamkumarsain/Projects/Creworder-Django/orders/views.py", line 301, in get
    data = checkServiceability(request.user.profile.branch_id,request.user.profile.company_id, {"pincode":request.data['pincode'],"mobile":request.data['mobile']})
KeyError: 'pincode'
2024-10-09 14:50:14,971 - django.request - ERROR - Internal Server Error: /api/check-serviceability/
Traceback (most recent call last):
  File "/usr/local/lib/python3.10/dist-packages/django/core/handlers/exception.py", line 55, in inner
    response = get_response(request)
  File "/usr/local/lib/python3.10/dist-packages/django/core/handlers/base.py", line 197, in _get_response
    response = wrapped_callback(request, *callback_args, **callback_kwargs)
  File "/usr/local/lib/python3.10/dist-packages/django/views/decorators/csrf.py", line 65, in _view_wrapper
    return view_func(request, *args, **kwargs)
  File "/usr/local/lib/python3.10/dist-packages/django/views/generic/base.py", line 104, in view
    return self.dispatch(request, *args, **kwargs)
  File "/usr/local/lib/python3.10/dist-packages/rest_framework/views.py", line 509, in dispatch
    response = self.handle_exception(exc)
  File "/usr/local/lib/python3.10/dist-packages/rest_framework/views.py", line 469, in handle_exception
    self.raise_uncaught_exception(exc)
  File "/usr/local/lib/python3.10/dist-packages/rest_framework/views.py", line 480, in raise_uncaught_exception
    raise exc
  File "/usr/local/lib/python3.10/dist-packages/rest_framework/views.py", line 506, in dispatch
    response = handler(request, *args, **kwargs)
  File "/home/shivamkumarsain/Projects/Creworder-Django/orders/views.py", line 301, in get
    data = checkServiceability(request.user.profile.branch_id,request.user.profile.company_id, {"pincode":request.data['pincode'],"mobile":request.data['mobile']})
KeyError: 'pincode'
2024-10-09 14:53:31,432 - django.request - ERROR - Internal Server Error: /api/check-serviceability/
Traceback (most recent call last):
  File "/usr/local/lib/python3.10/dist-packages/django/core/handlers/exception.py", line 55, in inner
    response = get_response(request)
  File "/usr/local/lib/python3.10/dist-packages/django/core/handlers/base.py", line 197, in _get_response
    response = wrapped_callback(request, *callback_args, **callback_kwargs)
  File "/usr/local/lib/python3.10/dist-packages/django/views/decorators/csrf.py", line 65, in _view_wrapper
    return view_func(request, *args, **kwargs)
  File "/usr/local/lib/python3.10/dist-packages/django/views/generic/base.py", line 104, in view
    return self.dispatch(request, *args, **kwargs)
  File "/usr/local/lib/python3.10/dist-packages/rest_framework/views.py", line 509, in dispatch
    response = self.handle_exception(exc)
  File "/usr/local/lib/python3.10/dist-packages/rest_framework/views.py", line 469, in handle_exception
    self.raise_uncaught_exception(exc)
  File "/usr/local/lib/python3.10/dist-packages/rest_framework/views.py", line 480, in raise_uncaught_exception
    raise exc
  File "/usr/local/lib/python3.10/dist-packages/rest_framework/views.py", line 506, in dispatch
    response = handler(request, *args, **kwargs)
  File "/home/shivamkumarsain/Projects/Creworder-Django/orders/views.py", line 301, in get
    data = checkServiceability(request.user.profile.branch_id,request.user.profile.company_id, {"pincode":request.data['pincode'],"mobile":request.data['mobile']})
KeyError: 'pincode'
2024-10-09 14:58:37,305 - django.request - ERROR - Internal Server Error: /api/check-serviceability/
Traceback (most recent call last):
  File "/usr/local/lib/python3.10/dist-packages/django/core/handlers/exception.py", line 55, in inner
    response = get_response(request)
  File "/usr/local/lib/python3.10/dist-packages/django/core/handlers/base.py", line 197, in _get_response
    response = wrapped_callback(request, *callback_args, **callback_kwargs)
  File "/usr/local/lib/python3.10/dist-packages/django/views/decorators/csrf.py", line 65, in _view_wrapper
    return view_func(request, *args, **kwargs)
  File "/usr/local/lib/python3.10/dist-packages/django/views/generic/base.py", line 104, in view
    return self.dispatch(request, *args, **kwargs)
  File "/usr/local/lib/python3.10/dist-packages/rest_framework/views.py", line 509, in dispatch
    response = self.handle_exception(exc)
  File "/usr/local/lib/python3.10/dist-packages/rest_framework/views.py", line 469, in handle_exception
    self.raise_uncaught_exception(exc)
  File "/usr/local/lib/python3.10/dist-packages/rest_framework/views.py", line 480, in raise_uncaught_exception
    raise exc
  File "/usr/local/lib/python3.10/dist-packages/rest_framework/views.py", line 506, in dispatch
    response = handler(request, *args, **kwargs)
  File "/home/shivamkumarsain/Projects/Creworder-Django/orders/views.py", line 301, in get
    data = checkServiceability(request.user.profile.branch_id,request.user.profile.company_id, {"pincode":request.data['pincode'],"mobile":request.data['mobile']})
KeyError: 'pincode'
2024-10-09 14:59:17,693 - django.request - ERROR - Internal Server Error: /api/check-serviceability/
Traceback (most recent call last):
  File "/usr/local/lib/python3.10/dist-packages/django/core/handlers/exception.py", line 55, in inner
    response = get_response(request)
  File "/usr/local/lib/python3.10/dist-packages/django/core/handlers/base.py", line 197, in _get_response
    response = wrapped_callback(request, *callback_args, **callback_kwargs)
  File "/usr/local/lib/python3.10/dist-packages/django/views/decorators/csrf.py", line 65, in _view_wrapper
    return view_func(request, *args, **kwargs)
  File "/usr/local/lib/python3.10/dist-packages/django/views/generic/base.py", line 104, in view
    return self.dispatch(request, *args, **kwargs)
  File "/usr/local/lib/python3.10/dist-packages/rest_framework/views.py", line 509, in dispatch
    response = self.handle_exception(exc)
  File "/usr/local/lib/python3.10/dist-packages/rest_framework/views.py", line 469, in handle_exception
    self.raise_uncaught_exception(exc)
  File "/usr/local/lib/python3.10/dist-packages/rest_framework/views.py", line 480, in raise_uncaught_exception
    raise exc
  File "/usr/local/lib/python3.10/dist-packages/rest_framework/views.py", line 506, in dispatch
    response = handler(request, *args, **kwargs)
  File "/home/shivamkumarsain/Projects/Creworder-Django/orders/views.py", line 302, in get
    data = checkServiceability(request.user.profile.branch_id,request.user.profile.company_id, {"pincode":request.data['pincode'],"mobile":request.data['mobile']})
KeyError: 'pincode'
2024-10-09 14:59:44,946 - django.request - ERROR - Internal Server Error: /api/check-serviceability/
Traceback (most recent call last):
  File "/usr/local/lib/python3.10/dist-packages/django/core/handlers/exception.py", line 55, in inner
    response = get_response(request)
  File "/usr/local/lib/python3.10/dist-packages/django/core/handlers/base.py", line 197, in _get_response
    response = wrapped_callback(request, *callback_args, **callback_kwargs)
  File "/usr/local/lib/python3.10/dist-packages/django/views/decorators/csrf.py", line 65, in _view_wrapper
    return view_func(request, *args, **kwargs)
  File "/usr/local/lib/python3.10/dist-packages/django/views/generic/base.py", line 104, in view
    return self.dispatch(request, *args, **kwargs)
  File "/usr/local/lib/python3.10/dist-packages/rest_framework/views.py", line 509, in dispatch
    response = self.handle_exception(exc)
  File "/usr/local/lib/python3.10/dist-packages/rest_framework/views.py", line 469, in handle_exception
    self.raise_uncaught_exception(exc)
  File "/usr/local/lib/python3.10/dist-packages/rest_framework/views.py", line 480, in raise_uncaught_exception
    raise exc
  File "/usr/local/lib/python3.10/dist-packages/rest_framework/views.py", line 506, in dispatch
    response = handler(request, *args, **kwargs)
  File "/home/shivamkumarsain/Projects/Creworder-Django/orders/views.py", line 302, in get
    data = checkServiceability(request.user.profile.branch_id,request.user.profile.company_id, {"pincode":request.data['pincode'],"mobile":request.data['mobile']})
KeyError: 'pincode'
2024-10-09 15:09:22,772 - django.request - ERROR - Internal Server Error: /api/check-serviceability/
Traceback (most recent call last):
  File "/usr/local/lib/python3.10/dist-packages/django/utils/datastructures.py", line 84, in __getitem__
    list_ = super().__getitem__(key)
KeyError: 'pincode'

During handling of the above exception, another exception occurred:

Traceback (most recent call last):
  File "/usr/local/lib/python3.10/dist-packages/django/core/handlers/exception.py", line 55, in inner
    response = get_response(request)
  File "/usr/local/lib/python3.10/dist-packages/django/core/handlers/base.py", line 197, in _get_response
    response = wrapped_callback(request, *callback_args, **callback_kwargs)
  File "/usr/local/lib/python3.10/dist-packages/django/views/decorators/csrf.py", line 65, in _view_wrapper
    return view_func(request, *args, **kwargs)
  File "/usr/local/lib/python3.10/dist-packages/django/views/generic/base.py", line 104, in view
    return self.dispatch(request, *args, **kwargs)
  File "/usr/local/lib/python3.10/dist-packages/rest_framework/views.py", line 509, in dispatch
    response = self.handle_exception(exc)
  File "/usr/local/lib/python3.10/dist-packages/rest_framework/views.py", line 469, in handle_exception
    self.raise_uncaught_exception(exc)
  File "/usr/local/lib/python3.10/dist-packages/rest_framework/views.py", line 480, in raise_uncaught_exception
    raise exc
  File "/usr/local/lib/python3.10/dist-packages/rest_framework/views.py", line 506, in dispatch
    response = handler(request, *args, **kwargs)
  File "/home/shivamkumarsain/Projects/Creworder-Django/orders/views.py", line 304, in get
    print(f"All parameters: {all_params['pincode']}")
  File "/usr/local/lib/python3.10/dist-packages/django/utils/datastructures.py", line 86, in __getitem__
    raise MultiValueDictKeyError(key)
django.utils.datastructures.MultiValueDictKeyError: 'pincode'
2024-10-09 15:11:23,660 - django.request - ERROR - Internal Server Error: /api/check-serviceability/
Traceback (most recent call last):
  File "/usr/local/lib/python3.10/dist-packages/django/utils/datastructures.py", line 84, in __getitem__
    list_ = super().__getitem__(key)
KeyError: 'pincode'

During handling of the above exception, another exception occurred:

Traceback (most recent call last):
  File "/usr/local/lib/python3.10/dist-packages/django/core/handlers/exception.py", line 55, in inner
    response = get_response(request)
  File "/usr/local/lib/python3.10/dist-packages/django/core/handlers/base.py", line 197, in _get_response
    response = wrapped_callback(request, *callback_args, **callback_kwargs)
  File "/usr/local/lib/python3.10/dist-packages/django/views/decorators/csrf.py", line 65, in _view_wrapper
    return view_func(request, *args, **kwargs)
  File "/usr/local/lib/python3.10/dist-packages/django/views/generic/base.py", line 104, in view
    return self.dispatch(request, *args, **kwargs)
  File "/usr/local/lib/python3.10/dist-packages/rest_framework/views.py", line 509, in dispatch
    response = self.handle_exception(exc)
  File "/usr/local/lib/python3.10/dist-packages/rest_framework/views.py", line 469, in handle_exception
    self.raise_uncaught_exception(exc)
  File "/usr/local/lib/python3.10/dist-packages/rest_framework/views.py", line 480, in raise_uncaught_exception
    raise exc
  File "/usr/local/lib/python3.10/dist-packages/rest_framework/views.py", line 506, in dispatch
    response = handler(request, *args, **kwargs)
  File "/home/shivamkumarsain/Projects/Creworder-Django/orders/views.py", line 301, in get
    print(request.GET['pincode'])
  File "/usr/local/lib/python3.10/dist-packages/django/utils/datastructures.py", line 86, in __getitem__
    raise MultiValueDictKeyError(key)
django.utils.datastructures.MultiValueDictKeyError: 'pincode'
2024-10-09 15:17:29,589 - django.request - ERROR - Internal Server Error: /api/check-serviceability/
Traceback (most recent call last):
  File "/usr/local/lib/python3.10/dist-packages/django/utils/datastructures.py", line 84, in __getitem__
    list_ = super().__getitem__(key)
KeyError: 'pincode'

During handling of the above exception, another exception occurred:

Traceback (most recent call last):
  File "/usr/local/lib/python3.10/dist-packages/django/core/handlers/exception.py", line 55, in inner
    response = get_response(request)
  File "/usr/local/lib/python3.10/dist-packages/django/core/handlers/base.py", line 197, in _get_response
    response = wrapped_callback(request, *callback_args, **callback_kwargs)
  File "/usr/local/lib/python3.10/dist-packages/django/views/decorators/csrf.py", line 65, in _view_wrapper
    return view_func(request, *args, **kwargs)
  File "/usr/local/lib/python3.10/dist-packages/django/views/generic/base.py", line 104, in view
    return self.dispatch(request, *args, **kwargs)
  File "/usr/local/lib/python3.10/dist-packages/rest_framework/views.py", line 509, in dispatch
    response = self.handle_exception(exc)
  File "/usr/local/lib/python3.10/dist-packages/rest_framework/views.py", line 469, in handle_exception
    self.raise_uncaught_exception(exc)
  File "/usr/local/lib/python3.10/dist-packages/rest_framework/views.py", line 480, in raise_uncaught_exception
    raise exc
  File "/usr/local/lib/python3.10/dist-packages/rest_framework/views.py", line 506, in dispatch
    response = handler(request, *args, **kwargs)
  File "/home/shivamkumarsain/Projects/Creworder-Django/orders/views.py", line 302, in get
    print(all_params['pincode'])
  File "/usr/local/lib/python3.10/dist-packages/django/utils/datastructures.py", line 86, in __getitem__
    raise MultiValueDictKeyError(key)
django.utils.datastructures.MultiValueDictKeyError: 'pincode'
2024-10-09 15:18:09,273 - django.request - ERROR - Internal Server Error: /api/check-serviceability/
Traceback (most recent call last):
  File "/usr/local/lib/python3.10/dist-packages/django/utils/datastructures.py", line 84, in __getitem__
    list_ = super().__getitem__(key)
KeyError: 'pincode'

During handling of the above exception, another exception occurred:

Traceback (most recent call last):
  File "/usr/local/lib/python3.10/dist-packages/django/core/handlers/exception.py", line 55, in inner
    response = get_response(request)
  File "/usr/local/lib/python3.10/dist-packages/django/core/handlers/base.py", line 197, in _get_response
    response = wrapped_callback(request, *callback_args, **callback_kwargs)
  File "/usr/local/lib/python3.10/dist-packages/django/views/decorators/csrf.py", line 65, in _view_wrapper
    return view_func(request, *args, **kwargs)
  File "/usr/local/lib/python3.10/dist-packages/django/views/generic/base.py", line 104, in view
    return self.dispatch(request, *args, **kwargs)
  File "/usr/local/lib/python3.10/dist-packages/rest_framework/views.py", line 509, in dispatch
    response = self.handle_exception(exc)
  File "/usr/local/lib/python3.10/dist-packages/rest_framework/views.py", line 469, in handle_exception
    self.raise_uncaught_exception(exc)
  File "/usr/local/lib/python3.10/dist-packages/rest_framework/views.py", line 480, in raise_uncaught_exception
    raise exc
  File "/usr/local/lib/python3.10/dist-packages/rest_framework/views.py", line 506, in dispatch
    response = handler(request, *args, **kwargs)
  File "/home/shivamkumarsain/Projects/Creworder-Django/orders/views.py", line 302, in get
    print(all_params['pincode'])
  File "/usr/local/lib/python3.10/dist-packages/django/utils/datastructures.py", line 86, in __getitem__
    raise MultiValueDictKeyError(key)
django.utils.datastructures.MultiValueDictKeyError: 'pincode'
2024-10-09 15:23:28,981 - django.request - ERROR - Internal Server Error: /api/check-serviceability/
Traceback (most recent call last):
  File "/usr/local/lib/python3.10/dist-packages/django/core/handlers/exception.py", line 55, in inner
    response = get_response(request)
  File "/usr/local/lib/python3.10/dist-packages/django/core/handlers/base.py", line 197, in _get_response
    response = wrapped_callback(request, *callback_args, **callback_kwargs)
  File "/usr/local/lib/python3.10/dist-packages/django/views/decorators/csrf.py", line 65, in _view_wrapper
    return view_func(request, *args, **kwargs)
  File "/usr/local/lib/python3.10/dist-packages/django/views/generic/base.py", line 104, in view
    return self.dispatch(request, *args, **kwargs)
  File "/usr/local/lib/python3.10/dist-packages/rest_framework/views.py", line 509, in dispatch
    response = self.handle_exception(exc)
  File "/usr/local/lib/python3.10/dist-packages/rest_framework/views.py", line 469, in handle_exception
    self.raise_uncaught_exception(exc)
  File "/usr/local/lib/python3.10/dist-packages/rest_framework/views.py", line 480, in raise_uncaught_exception
    raise exc
  File "/usr/local/lib/python3.10/dist-packages/rest_framework/views.py", line 506, in dispatch
    response = handler(request, *args, **kwargs)
  File "/home/shivamkumarsain/Projects/Creworder-Django/orders/views.py", line 301, in get
    data = checkServiceability(request.user.profile.branch_id,request.user.profile.company_id, {"pincode":request.data['pincode'],"mobile":request.data['mobile']})
KeyError: 'pincode'
2024-10-09 15:24:14,843 - django.request - ERROR - Internal Server Error: /api/check-serviceability/
Traceback (most recent call last):
  File "/usr/local/lib/python3.10/dist-packages/django/core/handlers/exception.py", line 55, in inner
    response = get_response(request)
  File "/usr/local/lib/python3.10/dist-packages/django/core/handlers/base.py", line 197, in _get_response
    response = wrapped_callback(request, *callback_args, **callback_kwargs)
  File "/usr/local/lib/python3.10/dist-packages/django/views/decorators/csrf.py", line 65, in _view_wrapper
    return view_func(request, *args, **kwargs)
  File "/usr/local/lib/python3.10/dist-packages/django/views/generic/base.py", line 104, in view
    return self.dispatch(request, *args, **kwargs)
  File "/usr/local/lib/python3.10/dist-packages/rest_framework/views.py", line 509, in dispatch
    response = self.handle_exception(exc)
  File "/usr/local/lib/python3.10/dist-packages/rest_framework/views.py", line 469, in handle_exception
    self.raise_uncaught_exception(exc)
  File "/usr/local/lib/python3.10/dist-packages/rest_framework/views.py", line 480, in raise_uncaught_exception
    raise exc
  File "/usr/local/lib/python3.10/dist-packages/rest_framework/views.py", line 506, in dispatch
    response = handler(request, *args, **kwargs)
  File "/home/shivamkumarsain/Projects/Creworder-Django/orders/views.py", line 301, in get
    data = checkServiceability(request.user.profile.branch_id,request.user.profile.company_id, {"pincode":request.data['pincode'],"mobile":request.data['mobile']})
KeyError: 'pincode'
2024-10-09 15:25:43,837 - django.request - ERROR - Internal Server Error: /api/check-serviceability/
Traceback (most recent call last):
  File "/usr/local/lib/python3.10/dist-packages/django/core/handlers/exception.py", line 55, in inner
    response = get_response(request)
  File "/usr/local/lib/python3.10/dist-packages/django/core/handlers/base.py", line 197, in _get_response
    response = wrapped_callback(request, *callback_args, **callback_kwargs)
  File "/usr/local/lib/python3.10/dist-packages/django/views/decorators/csrf.py", line 65, in _view_wrapper
    return view_func(request, *args, **kwargs)
  File "/usr/local/lib/python3.10/dist-packages/django/views/generic/base.py", line 104, in view
    return self.dispatch(request, *args, **kwargs)
  File "/usr/local/lib/python3.10/dist-packages/rest_framework/views.py", line 509, in dispatch
    response = self.handle_exception(exc)
  File "/usr/local/lib/python3.10/dist-packages/rest_framework/views.py", line 469, in handle_exception
    self.raise_uncaught_exception(exc)
  File "/usr/local/lib/python3.10/dist-packages/rest_framework/views.py", line 480, in raise_uncaught_exception
    raise exc
  File "/usr/local/lib/python3.10/dist-packages/rest_framework/views.py", line 506, in dispatch
    response = handler(request, *args, **kwargs)
  File "/home/shivamkumarsain/Projects/Creworder-Django/orders/views.py", line 301, in get
    data = checkServiceability(request.user.profile.branch_id,request.user.profile.company_id, {"pincode":request.data['pincode'],"mobile":request.data['mobile']})
KeyError: 'pincode'
2024-10-09 15:27:28,995 - django.request - ERROR - Internal Server Error: /api/check-serviceability/
Traceback (most recent call last):
  File "/usr/local/lib/python3.10/dist-packages/django/core/handlers/exception.py", line 55, in inner
    response = get_response(request)
  File "/usr/local/lib/python3.10/dist-packages/django/core/handlers/base.py", line 197, in _get_response
    response = wrapped_callback(request, *callback_args, **callback_kwargs)
  File "/usr/local/lib/python3.10/dist-packages/django/views/decorators/csrf.py", line 65, in _view_wrapper
    return view_func(request, *args, **kwargs)
  File "/usr/local/lib/python3.10/dist-packages/django/views/generic/base.py", line 104, in view
    return self.dispatch(request, *args, **kwargs)
  File "/usr/local/lib/python3.10/dist-packages/rest_framework/views.py", line 509, in dispatch
    response = self.handle_exception(exc)
  File "/usr/local/lib/python3.10/dist-packages/rest_framework/views.py", line 469, in handle_exception
    self.raise_uncaught_exception(exc)
  File "/usr/local/lib/python3.10/dist-packages/rest_framework/views.py", line 480, in raise_uncaught_exception
    raise exc
  File "/usr/local/lib/python3.10/dist-packages/rest_framework/views.py", line 506, in dispatch
    response = handler(request, *args, **kwargs)
  File "/home/shivamkumarsain/Projects/Creworder-Django/orders/views.py", line 305, in get
    data = checkServiceability(request.user.profile.branch_id,request.user.profile.company_id, {"pincode":request.data['pincode'],"mobile":request.data['mobile']})
KeyError: 'pincode'
2024-10-09 18:59:10,685 - django.request - ERROR - Internal Server Error: /api/product/
Traceback (most recent call last):
  File "/usr/local/lib/python3.10/dist-packages/django/core/handlers/exception.py", line 55, in inner
    response = get_response(request)
  File "/usr/local/lib/python3.10/dist-packages/django/core/handlers/base.py", line 197, in _get_response
    response = wrapped_callback(request, *callback_args, **callback_kwargs)
  File "/usr/local/lib/python3.10/dist-packages/django/views/decorators/csrf.py", line 65, in _view_wrapper
    return view_func(request, *args, **kwargs)
  File "/usr/local/lib/python3.10/dist-packages/django/views/generic/base.py", line 104, in view
    return self.dispatch(request, *args, **kwargs)
  File "/usr/local/lib/python3.10/dist-packages/rest_framework/views.py", line 509, in dispatch
    response = self.handle_exception(exc)
  File "/usr/local/lib/python3.10/dist-packages/rest_framework/views.py", line 469, in handle_exception
    self.raise_uncaught_exception(exc)
  File "/usr/local/lib/python3.10/dist-packages/rest_framework/views.py", line 480, in raise_uncaught_exception
    raise exc
  File "/usr/local/lib/python3.10/dist-packages/rest_framework/views.py", line 506, in dispatch
    response = handler(request, *args, **kwargs)
TypeError: ProductView.get() missing 1 required positional argument: 'pk'
2024-10-09 18:59:26,778 - django.request - WARNING - Not Found: /api/product/2/
2024-10-10 10:16:21,915 - django.request - WARNING - Not Found: /favicon.ico
2024-10-10 17:05:57,622 - django.request - WARNING - Forbidden: /api/branches/
2024-10-10 17:05:58,778 - django.request - WARNING - Forbidden: /api/branches/
2024-10-10 17:06:03,984 - django.request - WARNING - Forbidden: /api/get-module/0/
2024-10-10 17:06:04,000 - django.request - WARNING - Forbidden: /api/branches/
2024-10-10 17:06:04,064 - django.request - WARNING - Forbidden: /api/get-module/0/
2024-10-10 17:06:05,699 - django.request - WARNING - Forbidden: /api/branches/
2024-10-10 17:06:08,590 - django.request - WARNING - Forbidden: /api/branches/
2024-10-10 17:06:13,424 - django.request - WARNING - Forbidden: /api/branches/
2024-10-10 17:06:21,132 - django.request - WARNING - Forbidden: /api/branches/
2024-10-10 17:07:48,136 - django.request - WARNING - Not Found: /favicon.ico
2024-10-10 18:56:12,439 - django.request - WARNING - Bad Request: /api/orders/
2024-10-10 18:56:52,691 - django.request - WARNING - Bad Request: /api/orders/
2024-10-11 10:38:51,062 - django.request - WARNING - Not Found: /favicon.ico
2024-10-11 11:29:24,746 - django.request - WARNING - Bad Request: /api/orders/
2024-10-15 10:25:23,949 - django.request - WARNING - Not Found: /favicon.ico
2024-10-15 10:27:09,503 - django.request - WARNING - Bad Request: /api/orders/
2024-10-15 12:25:46,417 - django.request - ERROR - Internal Server Error: /api/check-serviceability/
Traceback (most recent call last):
  File "/usr/local/lib/python3.10/dist-packages/django/core/handlers/exception.py", line 55, in inner
    response = get_response(request)
  File "/usr/local/lib/python3.10/dist-packages/django/core/handlers/base.py", line 197, in _get_response
    response = wrapped_callback(request, *callback_args, **callback_kwargs)
  File "/usr/local/lib/python3.10/dist-packages/django/views/decorators/csrf.py", line 65, in _view_wrapper
    return view_func(request, *args, **kwargs)
  File "/usr/local/lib/python3.10/dist-packages/django/views/generic/base.py", line 104, in view
    return self.dispatch(request, *args, **kwargs)
  File "/usr/local/lib/python3.10/dist-packages/rest_framework/views.py", line 509, in dispatch
    response = self.handle_exception(exc)
  File "/usr/local/lib/python3.10/dist-packages/rest_framework/views.py", line 469, in handle_exception
    self.raise_uncaught_exception(exc)
  File "/usr/local/lib/python3.10/dist-packages/rest_framework/views.py", line 480, in raise_uncaught_exception
    raise exc
  File "/usr/local/lib/python3.10/dist-packages/rest_framework/views.py", line 506, in dispatch
    response = handler(request, *args, **kwargs)
  File "/home/shivamkumarsain/Projects/Creworder-Django/orders/views.py", line 326, in get
    "data": {"massage":f"Non serviceable {request.data['pincode']}"},
KeyError: 'pincode'
2024-10-15 14:31:15,603 - django.request - ERROR - Internal Server Error: /api/check-serviceability/
Traceback (most recent call last):
  File "/usr/local/lib/python3.10/dist-packages/django/core/handlers/exception.py", line 55, in inner
    response = get_response(request)
  File "/usr/local/lib/python3.10/dist-packages/django/core/handlers/base.py", line 197, in _get_response
    response = wrapped_callback(request, *callback_args, **callback_kwargs)
  File "/usr/local/lib/python3.10/dist-packages/django/views/decorators/csrf.py", line 65, in _view_wrapper
    return view_func(request, *args, **kwargs)
  File "/usr/local/lib/python3.10/dist-packages/django/views/generic/base.py", line 104, in view
    return self.dispatch(request, *args, **kwargs)
  File "/usr/local/lib/python3.10/dist-packages/rest_framework/views.py", line 509, in dispatch
    response = self.handle_exception(exc)
  File "/usr/local/lib/python3.10/dist-packages/rest_framework/views.py", line 469, in handle_exception
    self.raise_uncaught_exception(exc)
  File "/usr/local/lib/python3.10/dist-packages/rest_framework/views.py", line 480, in raise_uncaught_exception
    raise exc
  File "/usr/local/lib/python3.10/dist-packages/rest_framework/views.py", line 506, in dispatch
    response = handler(request, *args, **kwargs)
  File "/home/shivamkumarsain/Projects/Creworder-Django/orders/views.py", line 326, in get
    "data": {"massage":f"Non serviceable {request.data['pincode']}"},
KeyError: 'pincode'
2024-10-15 14:31:20,265 - django.request - ERROR - Internal Server Error: /api/check-serviceability/
Traceback (most recent call last):
  File "/usr/local/lib/python3.10/dist-packages/django/core/handlers/exception.py", line 55, in inner
    response = get_response(request)
  File "/usr/local/lib/python3.10/dist-packages/django/core/handlers/base.py", line 197, in _get_response
    response = wrapped_callback(request, *callback_args, **callback_kwargs)
  File "/usr/local/lib/python3.10/dist-packages/django/views/decorators/csrf.py", line 65, in _view_wrapper
    return view_func(request, *args, **kwargs)
  File "/usr/local/lib/python3.10/dist-packages/django/views/generic/base.py", line 104, in view
    return self.dispatch(request, *args, **kwargs)
  File "/usr/local/lib/python3.10/dist-packages/rest_framework/views.py", line 509, in dispatch
    response = self.handle_exception(exc)
  File "/usr/local/lib/python3.10/dist-packages/rest_framework/views.py", line 469, in handle_exception
    self.raise_uncaught_exception(exc)
  File "/usr/local/lib/python3.10/dist-packages/rest_framework/views.py", line 480, in raise_uncaught_exception
    raise exc
  File "/usr/local/lib/python3.10/dist-packages/rest_framework/views.py", line 506, in dispatch
    response = handler(request, *args, **kwargs)
  File "/home/shivamkumarsain/Projects/Creworder-Django/orders/views.py", line 326, in get
    "data": {"massage":f"Non serviceable {request.data['pincode']}"},
KeyError: 'pincode'
2024-10-15 14:31:25,295 - django.request - ERROR - Internal Server Error: /api/check-serviceability/
Traceback (most recent call last):
  File "/usr/local/lib/python3.10/dist-packages/django/core/handlers/exception.py", line 55, in inner
    response = get_response(request)
  File "/usr/local/lib/python3.10/dist-packages/django/core/handlers/base.py", line 197, in _get_response
    response = wrapped_callback(request, *callback_args, **callback_kwargs)
  File "/usr/local/lib/python3.10/dist-packages/django/views/decorators/csrf.py", line 65, in _view_wrapper
    return view_func(request, *args, **kwargs)
  File "/usr/local/lib/python3.10/dist-packages/django/views/generic/base.py", line 104, in view
    return self.dispatch(request, *args, **kwargs)
  File "/usr/local/lib/python3.10/dist-packages/rest_framework/views.py", line 509, in dispatch
    response = self.handle_exception(exc)
  File "/usr/local/lib/python3.10/dist-packages/rest_framework/views.py", line 469, in handle_exception
    self.raise_uncaught_exception(exc)
  File "/usr/local/lib/python3.10/dist-packages/rest_framework/views.py", line 480, in raise_uncaught_exception
    raise exc
  File "/usr/local/lib/python3.10/dist-packages/rest_framework/views.py", line 506, in dispatch
    response = handler(request, *args, **kwargs)
  File "/home/shivamkumarsain/Projects/Creworder-Django/orders/views.py", line 326, in get
    "data": {"massage":f"Non serviceable {request.data['pincode']}"},
KeyError: 'pincode'
2024-10-15 14:31:36,334 - django.request - ERROR - Internal Server Error: /api/check-serviceability/
Traceback (most recent call last):
  File "/usr/local/lib/python3.10/dist-packages/django/core/handlers/exception.py", line 55, in inner
    response = get_response(request)
  File "/usr/local/lib/python3.10/dist-packages/django/core/handlers/base.py", line 197, in _get_response
    response = wrapped_callback(request, *callback_args, **callback_kwargs)
  File "/usr/local/lib/python3.10/dist-packages/django/views/decorators/csrf.py", line 65, in _view_wrapper
    return view_func(request, *args, **kwargs)
  File "/usr/local/lib/python3.10/dist-packages/django/views/generic/base.py", line 104, in view
    return self.dispatch(request, *args, **kwargs)
  File "/usr/local/lib/python3.10/dist-packages/rest_framework/views.py", line 509, in dispatch
    response = self.handle_exception(exc)
  File "/usr/local/lib/python3.10/dist-packages/rest_framework/views.py", line 469, in handle_exception
    self.raise_uncaught_exception(exc)
  File "/usr/local/lib/python3.10/dist-packages/rest_framework/views.py", line 480, in raise_uncaught_exception
    raise exc
  File "/usr/local/lib/python3.10/dist-packages/rest_framework/views.py", line 506, in dispatch
    response = handler(request, *args, **kwargs)
  File "/home/shivamkumarsain/Projects/Creworder-Django/orders/views.py", line 326, in get
    "data": {"massage":f"Non serviceable {request.data['pincode']}"},
KeyError: 'pincode'
2024-10-15 14:33:48,397 - django.request - ERROR - Internal Server Error: /api/check-serviceability/
Traceback (most recent call last):
  File "/usr/local/lib/python3.10/dist-packages/django/core/handlers/exception.py", line 55, in inner
    response = get_response(request)
  File "/usr/local/lib/python3.10/dist-packages/django/core/handlers/base.py", line 197, in _get_response
    response = wrapped_callback(request, *callback_args, **callback_kwargs)
  File "/usr/local/lib/python3.10/dist-packages/django/views/decorators/csrf.py", line 65, in _view_wrapper
    return view_func(request, *args, **kwargs)
  File "/usr/local/lib/python3.10/dist-packages/django/views/generic/base.py", line 104, in view
    return self.dispatch(request, *args, **kwargs)
  File "/usr/local/lib/python3.10/dist-packages/rest_framework/views.py", line 509, in dispatch
    response = self.handle_exception(exc)
  File "/usr/local/lib/python3.10/dist-packages/rest_framework/views.py", line 469, in handle_exception
    self.raise_uncaught_exception(exc)
  File "/usr/local/lib/python3.10/dist-packages/rest_framework/views.py", line 480, in raise_uncaught_exception
    raise exc
  File "/usr/local/lib/python3.10/dist-packages/rest_framework/views.py", line 506, in dispatch
    response = handler(request, *args, **kwargs)
  File "/home/shivamkumarsain/Projects/Creworder-Django/orders/views.py", line 326, in get
    "data": {"massage":f"Non serviceable {request.data['pincode']}"},
KeyError: 'pincode'
2024-10-15 14:34:53,018 - django.request - ERROR - Internal Server Error: /api/check-serviceability/
Traceback (most recent call last):
  File "/usr/local/lib/python3.10/dist-packages/django/core/handlers/exception.py", line 55, in inner
    response = get_response(request)
  File "/usr/local/lib/python3.10/dist-packages/django/core/handlers/base.py", line 197, in _get_response
    response = wrapped_callback(request, *callback_args, **callback_kwargs)
  File "/usr/local/lib/python3.10/dist-packages/django/views/decorators/csrf.py", line 65, in _view_wrapper
    return view_func(request, *args, **kwargs)
  File "/usr/local/lib/python3.10/dist-packages/django/views/generic/base.py", line 104, in view
    return self.dispatch(request, *args, **kwargs)
  File "/usr/local/lib/python3.10/dist-packages/rest_framework/views.py", line 509, in dispatch
    response = self.handle_exception(exc)
  File "/usr/local/lib/python3.10/dist-packages/rest_framework/views.py", line 469, in handle_exception
    self.raise_uncaught_exception(exc)
  File "/usr/local/lib/python3.10/dist-packages/rest_framework/views.py", line 480, in raise_uncaught_exception
    raise exc
  File "/usr/local/lib/python3.10/dist-packages/rest_framework/views.py", line 506, in dispatch
    response = handler(request, *args, **kwargs)
  File "/home/shivamkumarsain/Projects/Creworder-Django/orders/views.py", line 326, in get
    "data": {"massage":f"Non serviceable {request.data['pincode']}"},
KeyError: 'pincode'
2024-10-15 14:36:07,524 - django.request - ERROR - Internal Server Error: /api/check-serviceability/
Traceback (most recent call last):
  File "/usr/local/lib/python3.10/dist-packages/django/core/handlers/exception.py", line 55, in inner
    response = get_response(request)
  File "/usr/local/lib/python3.10/dist-packages/django/core/handlers/base.py", line 197, in _get_response
    response = wrapped_callback(request, *callback_args, **callback_kwargs)
  File "/usr/local/lib/python3.10/dist-packages/django/views/decorators/csrf.py", line 65, in _view_wrapper
    return view_func(request, *args, **kwargs)
  File "/usr/local/lib/python3.10/dist-packages/django/views/generic/base.py", line 104, in view
    return self.dispatch(request, *args, **kwargs)
  File "/usr/local/lib/python3.10/dist-packages/rest_framework/views.py", line 509, in dispatch
    response = self.handle_exception(exc)
  File "/usr/local/lib/python3.10/dist-packages/rest_framework/views.py", line 469, in handle_exception
    self.raise_uncaught_exception(exc)
  File "/usr/local/lib/python3.10/dist-packages/rest_framework/views.py", line 480, in raise_uncaught_exception
    raise exc
  File "/usr/local/lib/python3.10/dist-packages/rest_framework/views.py", line 506, in dispatch
    response = handler(request, *args, **kwargs)
  File "/home/shivamkumarsain/Projects/Creworder-Django/orders/views.py", line 326, in get
    "data": {"massage":f"Non serviceable {request.data['pincode']}"},
KeyError: 'pincode'
2024-10-15 14:37:26,017 - django.request - ERROR - Internal Server Error: /api/check-serviceability/
Traceback (most recent call last):
  File "/usr/local/lib/python3.10/dist-packages/django/core/handlers/exception.py", line 55, in inner
    response = get_response(request)
  File "/usr/local/lib/python3.10/dist-packages/django/core/handlers/base.py", line 197, in _get_response
    response = wrapped_callback(request, *callback_args, **callback_kwargs)
  File "/usr/local/lib/python3.10/dist-packages/django/views/decorators/csrf.py", line 65, in _view_wrapper
    return view_func(request, *args, **kwargs)
  File "/usr/local/lib/python3.10/dist-packages/django/views/generic/base.py", line 104, in view
    return self.dispatch(request, *args, **kwargs)
  File "/usr/local/lib/python3.10/dist-packages/rest_framework/views.py", line 509, in dispatch
    response = self.handle_exception(exc)
  File "/usr/local/lib/python3.10/dist-packages/rest_framework/views.py", line 469, in handle_exception
    self.raise_uncaught_exception(exc)
  File "/usr/local/lib/python3.10/dist-packages/rest_framework/views.py", line 480, in raise_uncaught_exception
    raise exc
  File "/usr/local/lib/python3.10/dist-packages/rest_framework/views.py", line 506, in dispatch
    response = handler(request, *args, **kwargs)
  File "/home/shivamkumarsain/Projects/Creworder-Django/orders/views.py", line 326, in get
    "data": {"massage":f"Non serviceable {request.data['pincode']}"},
KeyError: 'pincode'
2024-10-15 15:04:20,683 - django.request - ERROR - Internal Server Error: /api/check-serviceability/
Traceback (most recent call last):
  File "/usr/local/lib/python3.10/dist-packages/django/core/handlers/exception.py", line 55, in inner
    response = get_response(request)
  File "/usr/local/lib/python3.10/dist-packages/django/core/handlers/base.py", line 197, in _get_response
    response = wrapped_callback(request, *callback_args, **callback_kwargs)
  File "/usr/local/lib/python3.10/dist-packages/django/views/decorators/csrf.py", line 65, in _view_wrapper
    return view_func(request, *args, **kwargs)
  File "/usr/local/lib/python3.10/dist-packages/django/views/generic/base.py", line 104, in view
    return self.dispatch(request, *args, **kwargs)
  File "/usr/local/lib/python3.10/dist-packages/rest_framework/views.py", line 509, in dispatch
    response = self.handle_exception(exc)
  File "/usr/local/lib/python3.10/dist-packages/rest_framework/views.py", line 469, in handle_exception
    self.raise_uncaught_exception(exc)
  File "/usr/local/lib/python3.10/dist-packages/rest_framework/views.py", line 480, in raise_uncaught_exception
    raise exc
  File "/usr/local/lib/python3.10/dist-packages/rest_framework/views.py", line 506, in dispatch
    response = handler(request, *args, **kwargs)
  File "/home/shivamkumarsain/Projects/Creworder-Django/orders/views.py", line 326, in get
    "data": {"massage":f"Non serviceable {request.data['pincode']}"},
KeyError: 'pincode'
2024-10-15 15:04:22,293 - django.request - ERROR - Internal Server Error: /api/check-serviceability/
Traceback (most recent call last):
  File "/usr/local/lib/python3.10/dist-packages/django/core/handlers/exception.py", line 55, in inner
    response = get_response(request)
  File "/usr/local/lib/python3.10/dist-packages/django/core/handlers/base.py", line 197, in _get_response
    response = wrapped_callback(request, *callback_args, **callback_kwargs)
  File "/usr/local/lib/python3.10/dist-packages/django/views/decorators/csrf.py", line 65, in _view_wrapper
    return view_func(request, *args, **kwargs)
  File "/usr/local/lib/python3.10/dist-packages/django/views/generic/base.py", line 104, in view
    return self.dispatch(request, *args, **kwargs)
  File "/usr/local/lib/python3.10/dist-packages/rest_framework/views.py", line 509, in dispatch
    response = self.handle_exception(exc)
  File "/usr/local/lib/python3.10/dist-packages/rest_framework/views.py", line 469, in handle_exception
    self.raise_uncaught_exception(exc)
  File "/usr/local/lib/python3.10/dist-packages/rest_framework/views.py", line 480, in raise_uncaught_exception
    raise exc
  File "/usr/local/lib/python3.10/dist-packages/rest_framework/views.py", line 506, in dispatch
    response = handler(request, *args, **kwargs)
  File "/home/shivamkumarsain/Projects/Creworder-Django/orders/views.py", line 326, in get
    "data": {"massage":f"Non serviceable {request.data['pincode']}"},
KeyError: 'pincode'
2024-10-15 15:04:25,811 - django.request - ERROR - Internal Server Error: /api/check-serviceability/
Traceback (most recent call last):
  File "/usr/local/lib/python3.10/dist-packages/django/core/handlers/exception.py", line 55, in inner
    response = get_response(request)
  File "/usr/local/lib/python3.10/dist-packages/django/core/handlers/base.py", line 197, in _get_response
    response = wrapped_callback(request, *callback_args, **callback_kwargs)
  File "/usr/local/lib/python3.10/dist-packages/django/views/decorators/csrf.py", line 65, in _view_wrapper
    return view_func(request, *args, **kwargs)
  File "/usr/local/lib/python3.10/dist-packages/django/views/generic/base.py", line 104, in view
    return self.dispatch(request, *args, **kwargs)
  File "/usr/local/lib/python3.10/dist-packages/rest_framework/views.py", line 509, in dispatch
    response = self.handle_exception(exc)
  File "/usr/local/lib/python3.10/dist-packages/rest_framework/views.py", line 469, in handle_exception
    self.raise_uncaught_exception(exc)
  File "/usr/local/lib/python3.10/dist-packages/rest_framework/views.py", line 480, in raise_uncaught_exception
    raise exc
  File "/usr/local/lib/python3.10/dist-packages/rest_framework/views.py", line 506, in dispatch
    response = handler(request, *args, **kwargs)
  File "/home/shivamkumarsain/Projects/Creworder-Django/orders/views.py", line 326, in get
    "data": {"massage":f"Non serviceable {request.data['pincode']}"},
KeyError: 'pincode'
2024-10-15 15:10:52,036 - django.request - WARNING - Bad Request: /api/orders/
2024-10-15 15:45:53,645 - django.request - WARNING - Bad Request: /api/orders/
2024-10-15 15:48:36,223 - django.request - WARNING - Bad Request: /api/orders/
2024-10-15 15:53:29,153 - django.request - WARNING - Bad Request: /api/orders/
2024-10-15 15:55:47,095 - django.request - WARNING - Bad Request: /api/orders/
2024-10-15 16:01:36,641 - django.request - WARNING - Not Found: /api//orders/
2024-10-15 16:02:30,236 - django.request - WARNING - Not Found: /api//orders/
2024-10-15 16:03:46,320 - django.request - WARNING - Not Found: /api//orders/
2024-10-15 16:04:16,508 - django.request - WARNING - Bad Request: /api/orders/
2024-10-15 16:05:51,098 - django.request - WARNING - Bad Request: /api/orders/
2024-10-15 18:15:32,425 - django.request - WARNING - Bad Request: /api/orders/
2024-10-15 18:16:18,289 - django.request - WARNING - Bad Request: /api/orders/
2024-10-15 18:26:58,520 - django.request - WARNING - Bad Request: /api/orders/
2024-10-16 11:23:47,799 - django.request - WARNING - Bad Request: /api/orders/
2024-10-16 11:56:42,659 - django.request - WARNING - Bad Request: /api/createFollowUp/
2024-10-16 11:57:21,570 - django.request - WARNING - Method Not Allowed: /api/createFollowUp/
