2024-10-22 15:25:56,521 - django.request - ERROR - Internal Server Error: /api/branches/
Traceback (most recent call last):
  File "/usr/local/lib/python3.10/dist-packages/django/core/handlers/exception.py", line 55, in inner
    response = get_response(request)
  File "/usr/local/lib/python3.10/dist-packages/django/core/handlers/base.py", line 197, in _get_response
    response = wrapped_callback(request, *callback_args, **callback_kwargs)
  File "/usr/local/lib/python3.10/dist-packages/django/views/decorators/csrf.py", line 65, in _view_wrapper
    return view_func(request, *args, **kwargs)
  File "/usr/local/lib/python3.10/dist-packages/rest_framework/viewsets.py", line 124, in view
    return self.dispatch(request, *args, **kwargs)
  File "/usr/local/lib/python3.10/dist-packages/rest_framework/views.py", line 509, in dispatch
    response = self.handle_exception(exc)
  File "/usr/local/lib/python3.10/dist-packages/rest_framework/views.py", line 469, in handle_exception
    self.raise_uncaught_exception(exc)
  File "/usr/local/lib/python3.10/dist-packages/rest_framework/views.py", line 480, in raise_uncaught_exception
    raise exc
  File "/usr/local/lib/python3.10/dist-packages/rest_framework/views.py", line 497, in dispatch
    self.initial(request, *args, **kwargs)
  File "/usr/local/lib/python3.10/dist-packages/rest_framework/views.py", line 415, in initial
    self.check_permissions(request)
  File "/usr/local/lib/python3.10/dist-packages/rest_framework/views.py", line 332, in check_permissions
    if not permission.has_permission(request, self):
  File "/usr/local/lib/python3.10/dist-packages/rest_framework/permissions.py", line 243, in has_permission
    queryset = self._queryset(view)
  File "/usr/local/lib/python3.10/dist-packages/rest_framework/permissions.py", line 226, in _queryset
    queryset = view.get_queryset()
  File "/home/shivamkumarsain/Projects/Creworder-Django/accounts/views.py", line 138, in get_queryset
    if user.role.role == "admin" or user.role.role == "agent":
AttributeError: 'User' object has no attribute 'role'
2024-10-22 15:25:58,092 - django.request - ERROR - Internal Server Error: /api/branches/
Traceback (most recent call last):
  File "/usr/local/lib/python3.10/dist-packages/django/core/handlers/exception.py", line 55, in inner
    response = get_response(request)
  File "/usr/local/lib/python3.10/dist-packages/django/core/handlers/base.py", line 197, in _get_response
    response = wrapped_callback(request, *callback_args, **callback_kwargs)
  File "/usr/local/lib/python3.10/dist-packages/django/views/decorators/csrf.py", line 65, in _view_wrapper
    return view_func(request, *args, **kwargs)
  File "/usr/local/lib/python3.10/dist-packages/rest_framework/viewsets.py", line 124, in view
    return self.dispatch(request, *args, **kwargs)
  File "/usr/local/lib/python3.10/dist-packages/rest_framework/views.py", line 509, in dispatch
    response = self.handle_exception(exc)
  File "/usr/local/lib/python3.10/dist-packages/rest_framework/views.py", line 469, in handle_exception
    self.raise_uncaught_exception(exc)
  File "/usr/local/lib/python3.10/dist-packages/rest_framework/views.py", line 480, in raise_uncaught_exception
    raise exc
  File "/usr/local/lib/python3.10/dist-packages/rest_framework/views.py", line 497, in dispatch
    self.initial(request, *args, **kwargs)
  File "/usr/local/lib/python3.10/dist-packages/rest_framework/views.py", line 415, in initial
    self.check_permissions(request)
  File "/usr/local/lib/python3.10/dist-packages/rest_framework/views.py", line 332, in check_permissions
    if not permission.has_permission(request, self):
  File "/usr/local/lib/python3.10/dist-packages/rest_framework/permissions.py", line 243, in has_permission
    queryset = self._queryset(view)
  File "/usr/local/lib/python3.10/dist-packages/rest_framework/permissions.py", line 226, in _queryset
    queryset = view.get_queryset()
  File "/home/shivamkumarsain/Projects/Creworder-Django/accounts/views.py", line 138, in get_queryset
    if user.role.role == "admin" or user.role.role == "agent":
AttributeError: 'User' object has no attribute 'role'
2024-10-22 15:26:00,222 - django.request - ERROR - Internal Server Error: /api/branches/
Traceback (most recent call last):
  File "/usr/local/lib/python3.10/dist-packages/django/core/handlers/exception.py", line 55, in inner
    response = get_response(request)
  File "/usr/local/lib/python3.10/dist-packages/django/core/handlers/base.py", line 197, in _get_response
    response = wrapped_callback(request, *callback_args, **callback_kwargs)
  File "/usr/local/lib/python3.10/dist-packages/django/views/decorators/csrf.py", line 65, in _view_wrapper
    return view_func(request, *args, **kwargs)
  File "/usr/local/lib/python3.10/dist-packages/rest_framework/viewsets.py", line 124, in view
    return self.dispatch(request, *args, **kwargs)
  File "/usr/local/lib/python3.10/dist-packages/rest_framework/views.py", line 509, in dispatch
    response = self.handle_exception(exc)
  File "/usr/local/lib/python3.10/dist-packages/rest_framework/views.py", line 469, in handle_exception
    self.raise_uncaught_exception(exc)
  File "/usr/local/lib/python3.10/dist-packages/rest_framework/views.py", line 480, in raise_uncaught_exception
    raise exc
  File "/usr/local/lib/python3.10/dist-packages/rest_framework/views.py", line 497, in dispatch
    self.initial(request, *args, **kwargs)
  File "/usr/local/lib/python3.10/dist-packages/rest_framework/views.py", line 415, in initial
    self.check_permissions(request)
  File "/usr/local/lib/python3.10/dist-packages/rest_framework/views.py", line 332, in check_permissions
    if not permission.has_permission(request, self):
  File "/usr/local/lib/python3.10/dist-packages/rest_framework/permissions.py", line 243, in has_permission
    queryset = self._queryset(view)
  File "/usr/local/lib/python3.10/dist-packages/rest_framework/permissions.py", line 226, in _queryset
    queryset = view.get_queryset()
  File "/home/shivamkumarsain/Projects/Creworder-Django/accounts/views.py", line 138, in get_queryset
    if user.role.role == "admin" or user.role.role == "agent":
AttributeError: 'User' object has no attribute 'role'
2024-10-22 15:26:04,310 - django.request - ERROR - Internal Server Error: /api/branches/
Traceback (most recent call last):
  File "/usr/local/lib/python3.10/dist-packages/django/core/handlers/exception.py", line 55, in inner
    response = get_response(request)
  File "/usr/local/lib/python3.10/dist-packages/django/core/handlers/base.py", line 197, in _get_response
    response = wrapped_callback(request, *callback_args, **callback_kwargs)
  File "/usr/local/lib/python3.10/dist-packages/django/views/decorators/csrf.py", line 65, in _view_wrapper
    return view_func(request, *args, **kwargs)
  File "/usr/local/lib/python3.10/dist-packages/rest_framework/viewsets.py", line 124, in view
    return self.dispatch(request, *args, **kwargs)
  File "/usr/local/lib/python3.10/dist-packages/rest_framework/views.py", line 509, in dispatch
    response = self.handle_exception(exc)
  File "/usr/local/lib/python3.10/dist-packages/rest_framework/views.py", line 469, in handle_exception
    self.raise_uncaught_exception(exc)
  File "/usr/local/lib/python3.10/dist-packages/rest_framework/views.py", line 480, in raise_uncaught_exception
    raise exc
  File "/usr/local/lib/python3.10/dist-packages/rest_framework/views.py", line 497, in dispatch
    self.initial(request, *args, **kwargs)
  File "/usr/local/lib/python3.10/dist-packages/rest_framework/views.py", line 415, in initial
    self.check_permissions(request)
  File "/usr/local/lib/python3.10/dist-packages/rest_framework/views.py", line 332, in check_permissions
    if not permission.has_permission(request, self):
  File "/usr/local/lib/python3.10/dist-packages/rest_framework/permissions.py", line 243, in has_permission
    queryset = self._queryset(view)
  File "/usr/local/lib/python3.10/dist-packages/rest_framework/permissions.py", line 226, in _queryset
    queryset = view.get_queryset()
  File "/home/shivamkumarsain/Projects/Creworder-Django/accounts/views.py", line 138, in get_queryset
    if user.role.role == "admin" or user.role.role == "agent":
AttributeError: 'User' object has no attribute 'role'
2024-10-22 15:33:50,795 - django.request - ERROR - Internal Server Error: /api/branches/
Traceback (most recent call last):
  File "/usr/local/lib/python3.10/dist-packages/django/core/handlers/exception.py", line 55, in inner
    response = get_response(request)
  File "/usr/local/lib/python3.10/dist-packages/django/core/handlers/base.py", line 197, in _get_response
    response = wrapped_callback(request, *callback_args, **callback_kwargs)
  File "/usr/local/lib/python3.10/dist-packages/django/views/decorators/csrf.py", line 65, in _view_wrapper
    return view_func(request, *args, **kwargs)
  File "/usr/local/lib/python3.10/dist-packages/rest_framework/viewsets.py", line 124, in view
    return self.dispatch(request, *args, **kwargs)
  File "/usr/local/lib/python3.10/dist-packages/rest_framework/views.py", line 509, in dispatch
    response = self.handle_exception(exc)
  File "/usr/local/lib/python3.10/dist-packages/rest_framework/views.py", line 469, in handle_exception
    self.raise_uncaught_exception(exc)
  File "/usr/local/lib/python3.10/dist-packages/rest_framework/views.py", line 480, in raise_uncaught_exception
    raise exc
  File "/usr/local/lib/python3.10/dist-packages/rest_framework/views.py", line 497, in dispatch
    self.initial(request, *args, **kwargs)
  File "/usr/local/lib/python3.10/dist-packages/rest_framework/views.py", line 415, in initial
    self.check_permissions(request)
  File "/usr/local/lib/python3.10/dist-packages/rest_framework/views.py", line 332, in check_permissions
    if not permission.has_permission(request, self):
  File "/usr/local/lib/python3.10/dist-packages/rest_framework/permissions.py", line 243, in has_permission
    queryset = self._queryset(view)
  File "/usr/local/lib/python3.10/dist-packages/rest_framework/permissions.py", line 226, in _queryset
    queryset = view.get_queryset()
  File "/home/shivamkumarsain/Projects/Creworder-Django/accounts/views.py", line 138, in get_queryset
    if user.role.role == "admin" or user.role.role == "agent":
AttributeError: 'User' object has no attribute 'role'
2024-10-22 15:33:52,223 - django.request - ERROR - Internal Server Error: /api/branches/
Traceback (most recent call last):
  File "/usr/local/lib/python3.10/dist-packages/django/core/handlers/exception.py", line 55, in inner
    response = get_response(request)
  File "/usr/local/lib/python3.10/dist-packages/django/core/handlers/base.py", line 197, in _get_response
    response = wrapped_callback(request, *callback_args, **callback_kwargs)
  File "/usr/local/lib/python3.10/dist-packages/django/views/decorators/csrf.py", line 65, in _view_wrapper
    return view_func(request, *args, **kwargs)
  File "/usr/local/lib/python3.10/dist-packages/rest_framework/viewsets.py", line 124, in view
    return self.dispatch(request, *args, **kwargs)
  File "/usr/local/lib/python3.10/dist-packages/rest_framework/views.py", line 509, in dispatch
    response = self.handle_exception(exc)
  File "/usr/local/lib/python3.10/dist-packages/rest_framework/views.py", line 469, in handle_exception
    self.raise_uncaught_exception(exc)
  File "/usr/local/lib/python3.10/dist-packages/rest_framework/views.py", line 480, in raise_uncaught_exception
    raise exc
  File "/usr/local/lib/python3.10/dist-packages/rest_framework/views.py", line 497, in dispatch
    self.initial(request, *args, **kwargs)
  File "/usr/local/lib/python3.10/dist-packages/rest_framework/views.py", line 415, in initial
    self.check_permissions(request)
  File "/usr/local/lib/python3.10/dist-packages/rest_framework/views.py", line 332, in check_permissions
    if not permission.has_permission(request, self):
  File "/usr/local/lib/python3.10/dist-packages/rest_framework/permissions.py", line 243, in has_permission
    queryset = self._queryset(view)
  File "/usr/local/lib/python3.10/dist-packages/rest_framework/permissions.py", line 226, in _queryset
    queryset = view.get_queryset()
  File "/home/shivamkumarsain/Projects/Creworder-Django/accounts/views.py", line 138, in get_queryset
    if user.role.role == "admin" or user.role.role == "agent":
AttributeError: 'User' object has no attribute 'role'
2024-10-22 15:33:54,371 - django.request - ERROR - Internal Server Error: /api/branches/
Traceback (most recent call last):
  File "/usr/local/lib/python3.10/dist-packages/django/core/handlers/exception.py", line 55, in inner
    response = get_response(request)
  File "/usr/local/lib/python3.10/dist-packages/django/core/handlers/base.py", line 197, in _get_response
    response = wrapped_callback(request, *callback_args, **callback_kwargs)
  File "/usr/local/lib/python3.10/dist-packages/django/views/decorators/csrf.py", line 65, in _view_wrapper
    return view_func(request, *args, **kwargs)
  File "/usr/local/lib/python3.10/dist-packages/rest_framework/viewsets.py", line 124, in view
    return self.dispatch(request, *args, **kwargs)
  File "/usr/local/lib/python3.10/dist-packages/rest_framework/views.py", line 509, in dispatch
    response = self.handle_exception(exc)
  File "/usr/local/lib/python3.10/dist-packages/rest_framework/views.py", line 469, in handle_exception
    self.raise_uncaught_exception(exc)
  File "/usr/local/lib/python3.10/dist-packages/rest_framework/views.py", line 480, in raise_uncaught_exception
    raise exc
  File "/usr/local/lib/python3.10/dist-packages/rest_framework/views.py", line 497, in dispatch
    self.initial(request, *args, **kwargs)
  File "/usr/local/lib/python3.10/dist-packages/rest_framework/views.py", line 415, in initial
    self.check_permissions(request)
  File "/usr/local/lib/python3.10/dist-packages/rest_framework/views.py", line 332, in check_permissions
    if not permission.has_permission(request, self):
  File "/usr/local/lib/python3.10/dist-packages/rest_framework/permissions.py", line 243, in has_permission
    queryset = self._queryset(view)
  File "/usr/local/lib/python3.10/dist-packages/rest_framework/permissions.py", line 226, in _queryset
    queryset = view.get_queryset()
  File "/home/shivamkumarsain/Projects/Creworder-Django/accounts/views.py", line 138, in get_queryset
    if user.role.role == "admin" or user.role.role == "agent":
AttributeError: 'User' object has no attribute 'role'
2024-10-22 15:33:58,504 - django.request - ERROR - Internal Server Error: /api/branches/
Traceback (most recent call last):
  File "/usr/local/lib/python3.10/dist-packages/django/core/handlers/exception.py", line 55, in inner
    response = get_response(request)
  File "/usr/local/lib/python3.10/dist-packages/django/core/handlers/base.py", line 197, in _get_response
    response = wrapped_callback(request, *callback_args, **callback_kwargs)
  File "/usr/local/lib/python3.10/dist-packages/django/views/decorators/csrf.py", line 65, in _view_wrapper
    return view_func(request, *args, **kwargs)
  File "/usr/local/lib/python3.10/dist-packages/rest_framework/viewsets.py", line 124, in view
    return self.dispatch(request, *args, **kwargs)
  File "/usr/local/lib/python3.10/dist-packages/rest_framework/views.py", line 509, in dispatch
    response = self.handle_exception(exc)
  File "/usr/local/lib/python3.10/dist-packages/rest_framework/views.py", line 469, in handle_exception
    self.raise_uncaught_exception(exc)
  File "/usr/local/lib/python3.10/dist-packages/rest_framework/views.py", line 480, in raise_uncaught_exception
    raise exc
  File "/usr/local/lib/python3.10/dist-packages/rest_framework/views.py", line 497, in dispatch
    self.initial(request, *args, **kwargs)
  File "/usr/local/lib/python3.10/dist-packages/rest_framework/views.py", line 415, in initial
    self.check_permissions(request)
  File "/usr/local/lib/python3.10/dist-packages/rest_framework/views.py", line 332, in check_permissions
    if not permission.has_permission(request, self):
  File "/usr/local/lib/python3.10/dist-packages/rest_framework/permissions.py", line 243, in has_permission
    queryset = self._queryset(view)
  File "/usr/local/lib/python3.10/dist-packages/rest_framework/permissions.py", line 226, in _queryset
    queryset = view.get_queryset()
  File "/home/shivamkumarsain/Projects/Creworder-Django/accounts/views.py", line 138, in get_queryset
    if user.role.role == "admin" or user.role.role == "agent":
AttributeError: 'User' object has no attribute 'role'
2024-10-22 15:34:03,468 - django.request - ERROR - Internal Server Error: /api/branches/
Traceback (most recent call last):
  File "/usr/local/lib/python3.10/dist-packages/django/core/handlers/exception.py", line 55, in inner
    response = get_response(request)
  File "/usr/local/lib/python3.10/dist-packages/django/core/handlers/base.py", line 197, in _get_response
    response = wrapped_callback(request, *callback_args, **callback_kwargs)
  File "/usr/local/lib/python3.10/dist-packages/django/views/decorators/csrf.py", line 65, in _view_wrapper
    return view_func(request, *args, **kwargs)
  File "/usr/local/lib/python3.10/dist-packages/rest_framework/viewsets.py", line 124, in view
    return self.dispatch(request, *args, **kwargs)
  File "/usr/local/lib/python3.10/dist-packages/rest_framework/views.py", line 509, in dispatch
    response = self.handle_exception(exc)
  File "/usr/local/lib/python3.10/dist-packages/rest_framework/views.py", line 469, in handle_exception
    self.raise_uncaught_exception(exc)
  File "/usr/local/lib/python3.10/dist-packages/rest_framework/views.py", line 480, in raise_uncaught_exception
    raise exc
  File "/usr/local/lib/python3.10/dist-packages/rest_framework/views.py", line 497, in dispatch
    self.initial(request, *args, **kwargs)
  File "/usr/local/lib/python3.10/dist-packages/rest_framework/views.py", line 415, in initial
    self.check_permissions(request)
  File "/usr/local/lib/python3.10/dist-packages/rest_framework/views.py", line 332, in check_permissions
    if not permission.has_permission(request, self):
  File "/usr/local/lib/python3.10/dist-packages/rest_framework/permissions.py", line 243, in has_permission
    queryset = self._queryset(view)
  File "/usr/local/lib/python3.10/dist-packages/rest_framework/permissions.py", line 226, in _queryset
    queryset = view.get_queryset()
  File "/home/shivamkumarsain/Projects/Creworder-Django/accounts/views.py", line 138, in get_queryset
    if user.role.role == "admin" or user.role.role == "agent":
AttributeError: 'User' object has no attribute 'role'
2024-10-22 15:34:04,885 - django.request - ERROR - Internal Server Error: /api/branches/
Traceback (most recent call last):
  File "/usr/local/lib/python3.10/dist-packages/django/core/handlers/exception.py", line 55, in inner
    response = get_response(request)
  File "/usr/local/lib/python3.10/dist-packages/django/core/handlers/base.py", line 197, in _get_response
    response = wrapped_callback(request, *callback_args, **callback_kwargs)
  File "/usr/local/lib/python3.10/dist-packages/django/views/decorators/csrf.py", line 65, in _view_wrapper
    return view_func(request, *args, **kwargs)
  File "/usr/local/lib/python3.10/dist-packages/rest_framework/viewsets.py", line 124, in view
    return self.dispatch(request, *args, **kwargs)
  File "/usr/local/lib/python3.10/dist-packages/rest_framework/views.py", line 509, in dispatch
    response = self.handle_exception(exc)
  File "/usr/local/lib/python3.10/dist-packages/rest_framework/views.py", line 469, in handle_exception
    self.raise_uncaught_exception(exc)
  File "/usr/local/lib/python3.10/dist-packages/rest_framework/views.py", line 480, in raise_uncaught_exception
    raise exc
  File "/usr/local/lib/python3.10/dist-packages/rest_framework/views.py", line 497, in dispatch
    self.initial(request, *args, **kwargs)
  File "/usr/local/lib/python3.10/dist-packages/rest_framework/views.py", line 415, in initial
    self.check_permissions(request)
  File "/usr/local/lib/python3.10/dist-packages/rest_framework/views.py", line 332, in check_permissions
    if not permission.has_permission(request, self):
  File "/usr/local/lib/python3.10/dist-packages/rest_framework/permissions.py", line 243, in has_permission
    queryset = self._queryset(view)
  File "/usr/local/lib/python3.10/dist-packages/rest_framework/permissions.py", line 226, in _queryset
    queryset = view.get_queryset()
  File "/home/shivamkumarsain/Projects/Creworder-Django/accounts/views.py", line 138, in get_queryset
    if user.role.role == "admin" or user.role.role == "agent":
AttributeError: 'User' object has no attribute 'role'
2024-10-22 15:34:06,965 - django.request - ERROR - Internal Server Error: /api/branches/
Traceback (most recent call last):
  File "/usr/local/lib/python3.10/dist-packages/django/core/handlers/exception.py", line 55, in inner
    response = get_response(request)
  File "/usr/local/lib/python3.10/dist-packages/django/core/handlers/base.py", line 197, in _get_response
    response = wrapped_callback(request, *callback_args, **callback_kwargs)
  File "/usr/local/lib/python3.10/dist-packages/django/views/decorators/csrf.py", line 65, in _view_wrapper
    return view_func(request, *args, **kwargs)
  File "/usr/local/lib/python3.10/dist-packages/rest_framework/viewsets.py", line 124, in view
    return self.dispatch(request, *args, **kwargs)
  File "/usr/local/lib/python3.10/dist-packages/rest_framework/views.py", line 509, in dispatch
    response = self.handle_exception(exc)
  File "/usr/local/lib/python3.10/dist-packages/rest_framework/views.py", line 469, in handle_exception
    self.raise_uncaught_exception(exc)
  File "/usr/local/lib/python3.10/dist-packages/rest_framework/views.py", line 480, in raise_uncaught_exception
    raise exc
  File "/usr/local/lib/python3.10/dist-packages/rest_framework/views.py", line 497, in dispatch
    self.initial(request, *args, **kwargs)
  File "/usr/local/lib/python3.10/dist-packages/rest_framework/views.py", line 415, in initial
    self.check_permissions(request)
  File "/usr/local/lib/python3.10/dist-packages/rest_framework/views.py", line 332, in check_permissions
    if not permission.has_permission(request, self):
  File "/usr/local/lib/python3.10/dist-packages/rest_framework/permissions.py", line 243, in has_permission
    queryset = self._queryset(view)
  File "/usr/local/lib/python3.10/dist-packages/rest_framework/permissions.py", line 226, in _queryset
    queryset = view.get_queryset()
  File "/home/shivamkumarsain/Projects/Creworder-Django/accounts/views.py", line 138, in get_queryset
    if user.role.role == "admin" or user.role.role == "agent":
AttributeError: 'User' object has no attribute 'role'
2024-10-22 15:34:11,045 - django.request - ERROR - Internal Server Error: /api/branches/
Traceback (most recent call last):
  File "/usr/local/lib/python3.10/dist-packages/django/core/handlers/exception.py", line 55, in inner
    response = get_response(request)
  File "/usr/local/lib/python3.10/dist-packages/django/core/handlers/base.py", line 197, in _get_response
    response = wrapped_callback(request, *callback_args, **callback_kwargs)
  File "/usr/local/lib/python3.10/dist-packages/django/views/decorators/csrf.py", line 65, in _view_wrapper
    return view_func(request, *args, **kwargs)
  File "/usr/local/lib/python3.10/dist-packages/rest_framework/viewsets.py", line 124, in view
    return self.dispatch(request, *args, **kwargs)
  File "/usr/local/lib/python3.10/dist-packages/rest_framework/views.py", line 509, in dispatch
    response = self.handle_exception(exc)
  File "/usr/local/lib/python3.10/dist-packages/rest_framework/views.py", line 469, in handle_exception
    self.raise_uncaught_exception(exc)
  File "/usr/local/lib/python3.10/dist-packages/rest_framework/views.py", line 480, in raise_uncaught_exception
    raise exc
  File "/usr/local/lib/python3.10/dist-packages/rest_framework/views.py", line 497, in dispatch
    self.initial(request, *args, **kwargs)
  File "/usr/local/lib/python3.10/dist-packages/rest_framework/views.py", line 415, in initial
    self.check_permissions(request)
  File "/usr/local/lib/python3.10/dist-packages/rest_framework/views.py", line 332, in check_permissions
    if not permission.has_permission(request, self):
  File "/usr/local/lib/python3.10/dist-packages/rest_framework/permissions.py", line 243, in has_permission
    queryset = self._queryset(view)
  File "/usr/local/lib/python3.10/dist-packages/rest_framework/permissions.py", line 226, in _queryset
    queryset = view.get_queryset()
  File "/home/shivamkumarsain/Projects/Creworder-Django/accounts/views.py", line 138, in get_queryset
    if user.role.role == "admin" or user.role.role == "agent":
AttributeError: 'User' object has no attribute 'role'
2024-10-22 15:35:15,341 - django.request - WARNING - Bad Request: /api/orders/
2024-10-22 15:36:43,991 - django.request - ERROR - Internal Server Error: /api/branches/
Traceback (most recent call last):
  File "/usr/local/lib/python3.10/dist-packages/django/core/handlers/exception.py", line 55, in inner
    response = get_response(request)
  File "/usr/local/lib/python3.10/dist-packages/django/core/handlers/base.py", line 197, in _get_response
    response = wrapped_callback(request, *callback_args, **callback_kwargs)
  File "/usr/local/lib/python3.10/dist-packages/django/views/decorators/csrf.py", line 65, in _view_wrapper
    return view_func(request, *args, **kwargs)
  File "/usr/local/lib/python3.10/dist-packages/rest_framework/viewsets.py", line 124, in view
    return self.dispatch(request, *args, **kwargs)
  File "/usr/local/lib/python3.10/dist-packages/rest_framework/views.py", line 509, in dispatch
    response = self.handle_exception(exc)
  File "/usr/local/lib/python3.10/dist-packages/rest_framework/views.py", line 469, in handle_exception
    self.raise_uncaught_exception(exc)
  File "/usr/local/lib/python3.10/dist-packages/rest_framework/views.py", line 480, in raise_uncaught_exception
    raise exc
  File "/usr/local/lib/python3.10/dist-packages/rest_framework/views.py", line 497, in dispatch
    self.initial(request, *args, **kwargs)
  File "/usr/local/lib/python3.10/dist-packages/rest_framework/views.py", line 415, in initial
    self.check_permissions(request)
  File "/usr/local/lib/python3.10/dist-packages/rest_framework/views.py", line 332, in check_permissions
    if not permission.has_permission(request, self):
  File "/usr/local/lib/python3.10/dist-packages/rest_framework/permissions.py", line 243, in has_permission
    queryset = self._queryset(view)
  File "/usr/local/lib/python3.10/dist-packages/rest_framework/permissions.py", line 226, in _queryset
    queryset = view.get_queryset()
  File "/home/shivamkumarsain/Projects/Creworder-Django/accounts/views.py", line 138, in get_queryset
    if user.role.role == "admin" or user.role.role == "agent":
AttributeError: 'User' object has no attribute 'role'
2024-10-22 15:36:45,417 - django.request - ERROR - Internal Server Error: /api/branches/
Traceback (most recent call last):
  File "/usr/local/lib/python3.10/dist-packages/django/core/handlers/exception.py", line 55, in inner
    response = get_response(request)
  File "/usr/local/lib/python3.10/dist-packages/django/core/handlers/base.py", line 197, in _get_response
    response = wrapped_callback(request, *callback_args, **callback_kwargs)
  File "/usr/local/lib/python3.10/dist-packages/django/views/decorators/csrf.py", line 65, in _view_wrapper
    return view_func(request, *args, **kwargs)
  File "/usr/local/lib/python3.10/dist-packages/rest_framework/viewsets.py", line 124, in view
    return self.dispatch(request, *args, **kwargs)
  File "/usr/local/lib/python3.10/dist-packages/rest_framework/views.py", line 509, in dispatch
    response = self.handle_exception(exc)
  File "/usr/local/lib/python3.10/dist-packages/rest_framework/views.py", line 469, in handle_exception
    self.raise_uncaught_exception(exc)
  File "/usr/local/lib/python3.10/dist-packages/rest_framework/views.py", line 480, in raise_uncaught_exception
    raise exc
  File "/usr/local/lib/python3.10/dist-packages/rest_framework/views.py", line 497, in dispatch
    self.initial(request, *args, **kwargs)
  File "/usr/local/lib/python3.10/dist-packages/rest_framework/views.py", line 415, in initial
    self.check_permissions(request)
  File "/usr/local/lib/python3.10/dist-packages/rest_framework/views.py", line 332, in check_permissions
    if not permission.has_permission(request, self):
  File "/usr/local/lib/python3.10/dist-packages/rest_framework/permissions.py", line 243, in has_permission
    queryset = self._queryset(view)
  File "/usr/local/lib/python3.10/dist-packages/rest_framework/permissions.py", line 226, in _queryset
    queryset = view.get_queryset()
  File "/home/shivamkumarsain/Projects/Creworder-Django/accounts/views.py", line 138, in get_queryset
    if user.role.role == "admin" or user.role.role == "agent":
AttributeError: 'User' object has no attribute 'role'
2024-10-22 15:36:47,540 - django.request - ERROR - Internal Server Error: /api/branches/
Traceback (most recent call last):
  File "/usr/local/lib/python3.10/dist-packages/django/core/handlers/exception.py", line 55, in inner
    response = get_response(request)
  File "/usr/local/lib/python3.10/dist-packages/django/core/handlers/base.py", line 197, in _get_response
    response = wrapped_callback(request, *callback_args, **callback_kwargs)
  File "/usr/local/lib/python3.10/dist-packages/django/views/decorators/csrf.py", line 65, in _view_wrapper
    return view_func(request, *args, **kwargs)
  File "/usr/local/lib/python3.10/dist-packages/rest_framework/viewsets.py", line 124, in view
    return self.dispatch(request, *args, **kwargs)
  File "/usr/local/lib/python3.10/dist-packages/rest_framework/views.py", line 509, in dispatch
    response = self.handle_exception(exc)
  File "/usr/local/lib/python3.10/dist-packages/rest_framework/views.py", line 469, in handle_exception
    self.raise_uncaught_exception(exc)
  File "/usr/local/lib/python3.10/dist-packages/rest_framework/views.py", line 480, in raise_uncaught_exception
    raise exc
  File "/usr/local/lib/python3.10/dist-packages/rest_framework/views.py", line 497, in dispatch
    self.initial(request, *args, **kwargs)
  File "/usr/local/lib/python3.10/dist-packages/rest_framework/views.py", line 415, in initial
    self.check_permissions(request)
  File "/usr/local/lib/python3.10/dist-packages/rest_framework/views.py", line 332, in check_permissions
    if not permission.has_permission(request, self):
  File "/usr/local/lib/python3.10/dist-packages/rest_framework/permissions.py", line 243, in has_permission
    queryset = self._queryset(view)
  File "/usr/local/lib/python3.10/dist-packages/rest_framework/permissions.py", line 226, in _queryset
    queryset = view.get_queryset()
  File "/home/shivamkumarsain/Projects/Creworder-Django/accounts/views.py", line 138, in get_queryset
    if user.role.role == "admin" or user.role.role == "agent":
AttributeError: 'User' object has no attribute 'role'
2024-10-22 15:36:51,611 - django.request - ERROR - Internal Server Error: /api/branches/
Traceback (most recent call last):
  File "/usr/local/lib/python3.10/dist-packages/django/core/handlers/exception.py", line 55, in inner
    response = get_response(request)
  File "/usr/local/lib/python3.10/dist-packages/django/core/handlers/base.py", line 197, in _get_response
    response = wrapped_callback(request, *callback_args, **callback_kwargs)
  File "/usr/local/lib/python3.10/dist-packages/django/views/decorators/csrf.py", line 65, in _view_wrapper
    return view_func(request, *args, **kwargs)
  File "/usr/local/lib/python3.10/dist-packages/rest_framework/viewsets.py", line 124, in view
    return self.dispatch(request, *args, **kwargs)
  File "/usr/local/lib/python3.10/dist-packages/rest_framework/views.py", line 509, in dispatch
    response = self.handle_exception(exc)
  File "/usr/local/lib/python3.10/dist-packages/rest_framework/views.py", line 469, in handle_exception
    self.raise_uncaught_exception(exc)
  File "/usr/local/lib/python3.10/dist-packages/rest_framework/views.py", line 480, in raise_uncaught_exception
    raise exc
  File "/usr/local/lib/python3.10/dist-packages/rest_framework/views.py", line 497, in dispatch
    self.initial(request, *args, **kwargs)
  File "/usr/local/lib/python3.10/dist-packages/rest_framework/views.py", line 415, in initial
    self.check_permissions(request)
  File "/usr/local/lib/python3.10/dist-packages/rest_framework/views.py", line 332, in check_permissions
    if not permission.has_permission(request, self):
  File "/usr/local/lib/python3.10/dist-packages/rest_framework/permissions.py", line 243, in has_permission
    queryset = self._queryset(view)
  File "/usr/local/lib/python3.10/dist-packages/rest_framework/permissions.py", line 226, in _queryset
    queryset = view.get_queryset()
  File "/home/shivamkumarsain/Projects/Creworder-Django/accounts/views.py", line 138, in get_queryset
    if user.role.role == "admin" or user.role.role == "agent":
AttributeError: 'User' object has no attribute 'role'
2024-10-22 15:40:40,431 - django.request - ERROR - Internal Server Error: /api/branches/
Traceback (most recent call last):
  File "/usr/local/lib/python3.10/dist-packages/django/core/handlers/exception.py", line 55, in inner
    response = get_response(request)
  File "/usr/local/lib/python3.10/dist-packages/django/core/handlers/base.py", line 197, in _get_response
    response = wrapped_callback(request, *callback_args, **callback_kwargs)
  File "/usr/local/lib/python3.10/dist-packages/django/views/decorators/csrf.py", line 65, in _view_wrapper
    return view_func(request, *args, **kwargs)
  File "/usr/local/lib/python3.10/dist-packages/rest_framework/viewsets.py", line 124, in view
    return self.dispatch(request, *args, **kwargs)
  File "/usr/local/lib/python3.10/dist-packages/rest_framework/views.py", line 509, in dispatch
    response = self.handle_exception(exc)
  File "/usr/local/lib/python3.10/dist-packages/rest_framework/views.py", line 469, in handle_exception
    self.raise_uncaught_exception(exc)
  File "/usr/local/lib/python3.10/dist-packages/rest_framework/views.py", line 480, in raise_uncaught_exception
    raise exc
  File "/usr/local/lib/python3.10/dist-packages/rest_framework/views.py", line 497, in dispatch
    self.initial(request, *args, **kwargs)
  File "/usr/local/lib/python3.10/dist-packages/rest_framework/views.py", line 415, in initial
    self.check_permissions(request)
  File "/usr/local/lib/python3.10/dist-packages/rest_framework/views.py", line 332, in check_permissions
    if not permission.has_permission(request, self):
  File "/usr/local/lib/python3.10/dist-packages/rest_framework/permissions.py", line 243, in has_permission
    queryset = self._queryset(view)
  File "/usr/local/lib/python3.10/dist-packages/rest_framework/permissions.py", line 226, in _queryset
    queryset = view.get_queryset()
  File "/home/shivamkumarsain/Projects/Creworder-Django/accounts/views.py", line 138, in get_queryset
    if user.role.role == "admin" or user.role.role == "agent":
AttributeError: 'User' object has no attribute 'role'
2024-10-22 15:40:42,029 - django.request - ERROR - Internal Server Error: /api/branches/
Traceback (most recent call last):
  File "/usr/local/lib/python3.10/dist-packages/django/core/handlers/exception.py", line 55, in inner
    response = get_response(request)
  File "/usr/local/lib/python3.10/dist-packages/django/core/handlers/base.py", line 197, in _get_response
    response = wrapped_callback(request, *callback_args, **callback_kwargs)
  File "/usr/local/lib/python3.10/dist-packages/django/views/decorators/csrf.py", line 65, in _view_wrapper
    return view_func(request, *args, **kwargs)
  File "/usr/local/lib/python3.10/dist-packages/rest_framework/viewsets.py", line 124, in view
    return self.dispatch(request, *args, **kwargs)
  File "/usr/local/lib/python3.10/dist-packages/rest_framework/views.py", line 509, in dispatch
    response = self.handle_exception(exc)
  File "/usr/local/lib/python3.10/dist-packages/rest_framework/views.py", line 469, in handle_exception
    self.raise_uncaught_exception(exc)
  File "/usr/local/lib/python3.10/dist-packages/rest_framework/views.py", line 480, in raise_uncaught_exception
    raise exc
  File "/usr/local/lib/python3.10/dist-packages/rest_framework/views.py", line 497, in dispatch
    self.initial(request, *args, **kwargs)
  File "/usr/local/lib/python3.10/dist-packages/rest_framework/views.py", line 415, in initial
    self.check_permissions(request)
  File "/usr/local/lib/python3.10/dist-packages/rest_framework/views.py", line 332, in check_permissions
    if not permission.has_permission(request, self):
  File "/usr/local/lib/python3.10/dist-packages/rest_framework/permissions.py", line 243, in has_permission
    queryset = self._queryset(view)
  File "/usr/local/lib/python3.10/dist-packages/rest_framework/permissions.py", line 226, in _queryset
    queryset = view.get_queryset()
  File "/home/shivamkumarsain/Projects/Creworder-Django/accounts/views.py", line 138, in get_queryset
    if user.role.role == "admin" or user.role.role == "agent":
AttributeError: 'User' object has no attribute 'role'
2024-10-22 15:49:59,312 - django.request - WARNING - Bad Request: /api/users/
2024-10-22 15:52:41,332 - django.request - ERROR - Internal Server Error: /api/branches/
Traceback (most recent call last):
  File "/usr/local/lib/python3.10/dist-packages/django/core/handlers/exception.py", line 55, in inner
    response = get_response(request)
  File "/usr/local/lib/python3.10/dist-packages/django/core/handlers/base.py", line 197, in _get_response
    response = wrapped_callback(request, *callback_args, **callback_kwargs)
  File "/usr/local/lib/python3.10/dist-packages/django/views/decorators/csrf.py", line 65, in _view_wrapper
    return view_func(request, *args, **kwargs)
  File "/usr/local/lib/python3.10/dist-packages/rest_framework/viewsets.py", line 124, in view
    return self.dispatch(request, *args, **kwargs)
  File "/usr/local/lib/python3.10/dist-packages/rest_framework/views.py", line 509, in dispatch
    response = self.handle_exception(exc)
  File "/usr/local/lib/python3.10/dist-packages/rest_framework/views.py", line 469, in handle_exception
    self.raise_uncaught_exception(exc)
  File "/usr/local/lib/python3.10/dist-packages/rest_framework/views.py", line 480, in raise_uncaught_exception
    raise exc
  File "/usr/local/lib/python3.10/dist-packages/rest_framework/views.py", line 497, in dispatch
    self.initial(request, *args, **kwargs)
  File "/usr/local/lib/python3.10/dist-packages/rest_framework/views.py", line 415, in initial
    self.check_permissions(request)
  File "/usr/local/lib/python3.10/dist-packages/rest_framework/views.py", line 332, in check_permissions
    if not permission.has_permission(request, self):
  File "/usr/local/lib/python3.10/dist-packages/rest_framework/permissions.py", line 243, in has_permission
    queryset = self._queryset(view)
  File "/usr/local/lib/python3.10/dist-packages/rest_framework/permissions.py", line 226, in _queryset
    queryset = view.get_queryset()
  File "/home/shivamkumarsain/Projects/Creworder-Django/accounts/views.py", line 138, in get_queryset
    if user.role.role == "admin" or user.role.role == "agent":
AttributeError: 'User' object has no attribute 'role'
2024-10-22 15:52:45,821 - django.request - ERROR - Internal Server Error: /api/branches/
Traceback (most recent call last):
  File "/usr/local/lib/python3.10/dist-packages/django/core/handlers/exception.py", line 55, in inner
    response = get_response(request)
  File "/usr/local/lib/python3.10/dist-packages/django/core/handlers/base.py", line 197, in _get_response
    response = wrapped_callback(request, *callback_args, **callback_kwargs)
  File "/usr/local/lib/python3.10/dist-packages/django/views/decorators/csrf.py", line 65, in _view_wrapper
    return view_func(request, *args, **kwargs)
  File "/usr/local/lib/python3.10/dist-packages/rest_framework/viewsets.py", line 124, in view
    return self.dispatch(request, *args, **kwargs)
  File "/usr/local/lib/python3.10/dist-packages/rest_framework/views.py", line 509, in dispatch
    response = self.handle_exception(exc)
  File "/usr/local/lib/python3.10/dist-packages/rest_framework/views.py", line 469, in handle_exception
    self.raise_uncaught_exception(exc)
  File "/usr/local/lib/python3.10/dist-packages/rest_framework/views.py", line 480, in raise_uncaught_exception
    raise exc
  File "/usr/local/lib/python3.10/dist-packages/rest_framework/views.py", line 497, in dispatch
    self.initial(request, *args, **kwargs)
  File "/usr/local/lib/python3.10/dist-packages/rest_framework/views.py", line 415, in initial
    self.check_permissions(request)
  File "/usr/local/lib/python3.10/dist-packages/rest_framework/views.py", line 332, in check_permissions
    if not permission.has_permission(request, self):
  File "/usr/local/lib/python3.10/dist-packages/rest_framework/permissions.py", line 243, in has_permission
    queryset = self._queryset(view)
  File "/usr/local/lib/python3.10/dist-packages/rest_framework/permissions.py", line 226, in _queryset
    queryset = view.get_queryset()
  File "/home/shivamkumarsain/Projects/Creworder-Django/accounts/views.py", line 138, in get_queryset
    if user.role.role == "admin" or user.role.role == "agent":
AttributeError: 'User' object has no attribute 'role'
2024-10-22 15:55:13,387 - django.request - WARNING - Bad Request: /api/orders/
2024-10-22 18:02:03,854 - django.request - ERROR - Internal Server Error: /api/branches/
Traceback (most recent call last):
  File "/usr/local/lib/python3.10/dist-packages/django/core/handlers/exception.py", line 55, in inner
    response = get_response(request)
  File "/usr/local/lib/python3.10/dist-packages/django/core/handlers/base.py", line 197, in _get_response
    response = wrapped_callback(request, *callback_args, **callback_kwargs)
  File "/usr/local/lib/python3.10/dist-packages/django/views/decorators/csrf.py", line 65, in _view_wrapper
    return view_func(request, *args, **kwargs)
  File "/usr/local/lib/python3.10/dist-packages/rest_framework/viewsets.py", line 124, in view
    return self.dispatch(request, *args, **kwargs)
  File "/usr/local/lib/python3.10/dist-packages/rest_framework/views.py", line 509, in dispatch
    response = self.handle_exception(exc)
  File "/usr/local/lib/python3.10/dist-packages/rest_framework/views.py", line 469, in handle_exception
    self.raise_uncaught_exception(exc)
  File "/usr/local/lib/python3.10/dist-packages/rest_framework/views.py", line 480, in raise_uncaught_exception
    raise exc
  File "/usr/local/lib/python3.10/dist-packages/rest_framework/views.py", line 497, in dispatch
    self.initial(request, *args, **kwargs)
  File "/usr/local/lib/python3.10/dist-packages/rest_framework/views.py", line 415, in initial
    self.check_permissions(request)
  File "/usr/local/lib/python3.10/dist-packages/rest_framework/views.py", line 332, in check_permissions
    if not permission.has_permission(request, self):
  File "/usr/local/lib/python3.10/dist-packages/rest_framework/permissions.py", line 243, in has_permission
    queryset = self._queryset(view)
  File "/usr/local/lib/python3.10/dist-packages/rest_framework/permissions.py", line 226, in _queryset
    queryset = view.get_queryset()
  File "/home/shivamkumarsain/Projects/Creworder-Django/accounts/views.py", line 138, in get_queryset
    if user.role.role == "admin" or user.role.role == "agent":
AttributeError: 'User' object has no attribute 'role'
2024-10-22 18:02:05,238 - django.request - ERROR - Internal Server Error: /api/branches/
Traceback (most recent call last):
  File "/usr/local/lib/python3.10/dist-packages/django/core/handlers/exception.py", line 55, in inner
    response = get_response(request)
  File "/usr/local/lib/python3.10/dist-packages/django/core/handlers/base.py", line 197, in _get_response
    response = wrapped_callback(request, *callback_args, **callback_kwargs)
  File "/usr/local/lib/python3.10/dist-packages/django/views/decorators/csrf.py", line 65, in _view_wrapper
    return view_func(request, *args, **kwargs)
  File "/usr/local/lib/python3.10/dist-packages/rest_framework/viewsets.py", line 124, in view
    return self.dispatch(request, *args, **kwargs)
  File "/usr/local/lib/python3.10/dist-packages/rest_framework/views.py", line 509, in dispatch
    response = self.handle_exception(exc)
  File "/usr/local/lib/python3.10/dist-packages/rest_framework/views.py", line 469, in handle_exception
    self.raise_uncaught_exception(exc)
  File "/usr/local/lib/python3.10/dist-packages/rest_framework/views.py", line 480, in raise_uncaught_exception
    raise exc
  File "/usr/local/lib/python3.10/dist-packages/rest_framework/views.py", line 497, in dispatch
    self.initial(request, *args, **kwargs)
  File "/usr/local/lib/python3.10/dist-packages/rest_framework/views.py", line 415, in initial
    self.check_permissions(request)
  File "/usr/local/lib/python3.10/dist-packages/rest_framework/views.py", line 332, in check_permissions
    if not permission.has_permission(request, self):
  File "/usr/local/lib/python3.10/dist-packages/rest_framework/permissions.py", line 243, in has_permission
    queryset = self._queryset(view)
  File "/usr/local/lib/python3.10/dist-packages/rest_framework/permissions.py", line 226, in _queryset
    queryset = view.get_queryset()
  File "/home/shivamkumarsain/Projects/Creworder-Django/accounts/views.py", line 138, in get_queryset
    if user.role.role == "admin" or user.role.role == "agent":
AttributeError: 'User' object has no attribute 'role'
2024-10-22 18:02:07,336 - django.request - ERROR - Internal Server Error: /api/branches/
Traceback (most recent call last):
  File "/usr/local/lib/python3.10/dist-packages/django/core/handlers/exception.py", line 55, in inner
    response = get_response(request)
  File "/usr/local/lib/python3.10/dist-packages/django/core/handlers/base.py", line 197, in _get_response
    response = wrapped_callback(request, *callback_args, **callback_kwargs)
  File "/usr/local/lib/python3.10/dist-packages/django/views/decorators/csrf.py", line 65, in _view_wrapper
    return view_func(request, *args, **kwargs)
  File "/usr/local/lib/python3.10/dist-packages/rest_framework/viewsets.py", line 124, in view
    return self.dispatch(request, *args, **kwargs)
  File "/usr/local/lib/python3.10/dist-packages/rest_framework/views.py", line 509, in dispatch
    response = self.handle_exception(exc)
  File "/usr/local/lib/python3.10/dist-packages/rest_framework/views.py", line 469, in handle_exception
    self.raise_uncaught_exception(exc)
  File "/usr/local/lib/python3.10/dist-packages/rest_framework/views.py", line 480, in raise_uncaught_exception
    raise exc
  File "/usr/local/lib/python3.10/dist-packages/rest_framework/views.py", line 497, in dispatch
    self.initial(request, *args, **kwargs)
  File "/usr/local/lib/python3.10/dist-packages/rest_framework/views.py", line 415, in initial
    self.check_permissions(request)
  File "/usr/local/lib/python3.10/dist-packages/rest_framework/views.py", line 332, in check_permissions
    if not permission.has_permission(request, self):
  File "/usr/local/lib/python3.10/dist-packages/rest_framework/permissions.py", line 243, in has_permission
    queryset = self._queryset(view)
  File "/usr/local/lib/python3.10/dist-packages/rest_framework/permissions.py", line 226, in _queryset
    queryset = view.get_queryset()
  File "/home/shivamkumarsain/Projects/Creworder-Django/accounts/views.py", line 138, in get_queryset
    if user.role.role == "admin" or user.role.role == "agent":
AttributeError: 'User' object has no attribute 'role'
2024-10-22 18:02:11,430 - django.request - ERROR - Internal Server Error: /api/branches/
Traceback (most recent call last):
  File "/usr/local/lib/python3.10/dist-packages/django/core/handlers/exception.py", line 55, in inner
    response = get_response(request)
  File "/usr/local/lib/python3.10/dist-packages/django/core/handlers/base.py", line 197, in _get_response
    response = wrapped_callback(request, *callback_args, **callback_kwargs)
  File "/usr/local/lib/python3.10/dist-packages/django/views/decorators/csrf.py", line 65, in _view_wrapper
    return view_func(request, *args, **kwargs)
  File "/usr/local/lib/python3.10/dist-packages/rest_framework/viewsets.py", line 124, in view
    return self.dispatch(request, *args, **kwargs)
  File "/usr/local/lib/python3.10/dist-packages/rest_framework/views.py", line 509, in dispatch
    response = self.handle_exception(exc)
  File "/usr/local/lib/python3.10/dist-packages/rest_framework/views.py", line 469, in handle_exception
    self.raise_uncaught_exception(exc)
  File "/usr/local/lib/python3.10/dist-packages/rest_framework/views.py", line 480, in raise_uncaught_exception
    raise exc
  File "/usr/local/lib/python3.10/dist-packages/rest_framework/views.py", line 497, in dispatch
    self.initial(request, *args, **kwargs)
  File "/usr/local/lib/python3.10/dist-packages/rest_framework/views.py", line 415, in initial
    self.check_permissions(request)
  File "/usr/local/lib/python3.10/dist-packages/rest_framework/views.py", line 332, in check_permissions
    if not permission.has_permission(request, self):
  File "/usr/local/lib/python3.10/dist-packages/rest_framework/permissions.py", line 243, in has_permission
    queryset = self._queryset(view)
  File "/usr/local/lib/python3.10/dist-packages/rest_framework/permissions.py", line 226, in _queryset
    queryset = view.get_queryset()
  File "/home/shivamkumarsain/Projects/Creworder-Django/accounts/views.py", line 138, in get_queryset
    if user.role.role == "admin" or user.role.role == "agent":
AttributeError: 'User' object has no attribute 'role'
2024-10-22 18:02:18,083 - django.request - ERROR - Internal Server Error: /api/branches/
Traceback (most recent call last):
  File "/usr/local/lib/python3.10/dist-packages/django/core/handlers/exception.py", line 55, in inner
    response = get_response(request)
  File "/usr/local/lib/python3.10/dist-packages/django/core/handlers/base.py", line 197, in _get_response
    response = wrapped_callback(request, *callback_args, **callback_kwargs)
  File "/usr/local/lib/python3.10/dist-packages/django/views/decorators/csrf.py", line 65, in _view_wrapper
    return view_func(request, *args, **kwargs)
  File "/usr/local/lib/python3.10/dist-packages/rest_framework/viewsets.py", line 124, in view
    return self.dispatch(request, *args, **kwargs)
  File "/usr/local/lib/python3.10/dist-packages/rest_framework/views.py", line 509, in dispatch
    response = self.handle_exception(exc)
  File "/usr/local/lib/python3.10/dist-packages/rest_framework/views.py", line 469, in handle_exception
    self.raise_uncaught_exception(exc)
  File "/usr/local/lib/python3.10/dist-packages/rest_framework/views.py", line 480, in raise_uncaught_exception
    raise exc
  File "/usr/local/lib/python3.10/dist-packages/rest_framework/views.py", line 497, in dispatch
    self.initial(request, *args, **kwargs)
  File "/usr/local/lib/python3.10/dist-packages/rest_framework/views.py", line 415, in initial
    self.check_permissions(request)
  File "/usr/local/lib/python3.10/dist-packages/rest_framework/views.py", line 332, in check_permissions
    if not permission.has_permission(request, self):
  File "/usr/local/lib/python3.10/dist-packages/rest_framework/permissions.py", line 243, in has_permission
    queryset = self._queryset(view)
  File "/usr/local/lib/python3.10/dist-packages/rest_framework/permissions.py", line 226, in _queryset
    queryset = view.get_queryset()
  File "/home/shivamkumarsain/Projects/Creworder-Django/accounts/views.py", line 138, in get_queryset
    if user.role.role == "admin" or user.role.role == "agent":
AttributeError: 'User' object has no attribute 'role'
2024-10-22 18:02:19,159 - django.request - ERROR - Internal Server Error: /api/branches/
Traceback (most recent call last):
  File "/usr/local/lib/python3.10/dist-packages/django/core/handlers/exception.py", line 55, in inner
    response = get_response(request)
  File "/usr/local/lib/python3.10/dist-packages/django/core/handlers/base.py", line 197, in _get_response
    response = wrapped_callback(request, *callback_args, **callback_kwargs)
  File "/usr/local/lib/python3.10/dist-packages/django/views/decorators/csrf.py", line 65, in _view_wrapper
    return view_func(request, *args, **kwargs)
  File "/usr/local/lib/python3.10/dist-packages/rest_framework/viewsets.py", line 124, in view
    return self.dispatch(request, *args, **kwargs)
  File "/usr/local/lib/python3.10/dist-packages/rest_framework/views.py", line 509, in dispatch
    response = self.handle_exception(exc)
  File "/usr/local/lib/python3.10/dist-packages/rest_framework/views.py", line 469, in handle_exception
    self.raise_uncaught_exception(exc)
  File "/usr/local/lib/python3.10/dist-packages/rest_framework/views.py", line 480, in raise_uncaught_exception
    raise exc
  File "/usr/local/lib/python3.10/dist-packages/rest_framework/views.py", line 497, in dispatch
    self.initial(request, *args, **kwargs)
  File "/usr/local/lib/python3.10/dist-packages/rest_framework/views.py", line 415, in initial
    self.check_permissions(request)
  File "/usr/local/lib/python3.10/dist-packages/rest_framework/views.py", line 332, in check_permissions
    if not permission.has_permission(request, self):
  File "/usr/local/lib/python3.10/dist-packages/rest_framework/permissions.py", line 243, in has_permission
    queryset = self._queryset(view)
  File "/usr/local/lib/python3.10/dist-packages/rest_framework/permissions.py", line 226, in _queryset
    queryset = view.get_queryset()
  File "/home/shivamkumarsain/Projects/Creworder-Django/accounts/views.py", line 138, in get_queryset
    if user.role.role == "admin" or user.role.role == "agent":
AttributeError: 'User' object has no attribute 'role'
2024-10-22 18:02:21,261 - django.request - ERROR - Internal Server Error: /api/branches/
Traceback (most recent call last):
  File "/usr/local/lib/python3.10/dist-packages/django/core/handlers/exception.py", line 55, in inner
    response = get_response(request)
  File "/usr/local/lib/python3.10/dist-packages/django/core/handlers/base.py", line 197, in _get_response
    response = wrapped_callback(request, *callback_args, **callback_kwargs)
  File "/usr/local/lib/python3.10/dist-packages/django/views/decorators/csrf.py", line 65, in _view_wrapper
    return view_func(request, *args, **kwargs)
  File "/usr/local/lib/python3.10/dist-packages/rest_framework/viewsets.py", line 124, in view
    return self.dispatch(request, *args, **kwargs)
  File "/usr/local/lib/python3.10/dist-packages/rest_framework/views.py", line 509, in dispatch
    response = self.handle_exception(exc)
  File "/usr/local/lib/python3.10/dist-packages/rest_framework/views.py", line 469, in handle_exception
    self.raise_uncaught_exception(exc)
  File "/usr/local/lib/python3.10/dist-packages/rest_framework/views.py", line 480, in raise_uncaught_exception
    raise exc
  File "/usr/local/lib/python3.10/dist-packages/rest_framework/views.py", line 497, in dispatch
    self.initial(request, *args, **kwargs)
  File "/usr/local/lib/python3.10/dist-packages/rest_framework/views.py", line 415, in initial
    self.check_permissions(request)
  File "/usr/local/lib/python3.10/dist-packages/rest_framework/views.py", line 332, in check_permissions
    if not permission.has_permission(request, self):
  File "/usr/local/lib/python3.10/dist-packages/rest_framework/permissions.py", line 243, in has_permission
    queryset = self._queryset(view)
  File "/usr/local/lib/python3.10/dist-packages/rest_framework/permissions.py", line 226, in _queryset
    queryset = view.get_queryset()
  File "/home/shivamkumarsain/Projects/Creworder-Django/accounts/views.py", line 138, in get_queryset
    if user.role.role == "admin" or user.role.role == "agent":
AttributeError: 'User' object has no attribute 'role'
2024-10-22 18:02:25,338 - django.request - ERROR - Internal Server Error: /api/branches/
Traceback (most recent call last):
  File "/usr/local/lib/python3.10/dist-packages/django/core/handlers/exception.py", line 55, in inner
    response = get_response(request)
  File "/usr/local/lib/python3.10/dist-packages/django/core/handlers/base.py", line 197, in _get_response
    response = wrapped_callback(request, *callback_args, **callback_kwargs)
  File "/usr/local/lib/python3.10/dist-packages/django/views/decorators/csrf.py", line 65, in _view_wrapper
    return view_func(request, *args, **kwargs)
  File "/usr/local/lib/python3.10/dist-packages/rest_framework/viewsets.py", line 124, in view
    return self.dispatch(request, *args, **kwargs)
  File "/usr/local/lib/python3.10/dist-packages/rest_framework/views.py", line 509, in dispatch
    response = self.handle_exception(exc)
  File "/usr/local/lib/python3.10/dist-packages/rest_framework/views.py", line 469, in handle_exception
    self.raise_uncaught_exception(exc)
  File "/usr/local/lib/python3.10/dist-packages/rest_framework/views.py", line 480, in raise_uncaught_exception
    raise exc
  File "/usr/local/lib/python3.10/dist-packages/rest_framework/views.py", line 497, in dispatch
    self.initial(request, *args, **kwargs)
  File "/usr/local/lib/python3.10/dist-packages/rest_framework/views.py", line 415, in initial
    self.check_permissions(request)
  File "/usr/local/lib/python3.10/dist-packages/rest_framework/views.py", line 332, in check_permissions
    if not permission.has_permission(request, self):
  File "/usr/local/lib/python3.10/dist-packages/rest_framework/permissions.py", line 243, in has_permission
    queryset = self._queryset(view)
  File "/usr/local/lib/python3.10/dist-packages/rest_framework/permissions.py", line 226, in _queryset
    queryset = view.get_queryset()
  File "/home/shivamkumarsain/Projects/Creworder-Django/accounts/views.py", line 138, in get_queryset
    if user.role.role == "admin" or user.role.role == "agent":
AttributeError: 'User' object has no attribute 'role'
2024-10-22 18:03:13,771 - django.request - ERROR - Internal Server Error: /api/branches/
Traceback (most recent call last):
  File "/usr/local/lib/python3.10/dist-packages/django/core/handlers/exception.py", line 55, in inner
    response = get_response(request)
  File "/usr/local/lib/python3.10/dist-packages/django/core/handlers/base.py", line 197, in _get_response
    response = wrapped_callback(request, *callback_args, **callback_kwargs)
  File "/usr/local/lib/python3.10/dist-packages/django/views/decorators/csrf.py", line 65, in _view_wrapper
    return view_func(request, *args, **kwargs)
  File "/usr/local/lib/python3.10/dist-packages/rest_framework/viewsets.py", line 124, in view
    return self.dispatch(request, *args, **kwargs)
  File "/usr/local/lib/python3.10/dist-packages/rest_framework/views.py", line 509, in dispatch
    response = self.handle_exception(exc)
  File "/usr/local/lib/python3.10/dist-packages/rest_framework/views.py", line 469, in handle_exception
    self.raise_uncaught_exception(exc)
  File "/usr/local/lib/python3.10/dist-packages/rest_framework/views.py", line 480, in raise_uncaught_exception
    raise exc
  File "/usr/local/lib/python3.10/dist-packages/rest_framework/views.py", line 497, in dispatch
    self.initial(request, *args, **kwargs)
  File "/usr/local/lib/python3.10/dist-packages/rest_framework/views.py", line 415, in initial
    self.check_permissions(request)
  File "/usr/local/lib/python3.10/dist-packages/rest_framework/views.py", line 332, in check_permissions
    if not permission.has_permission(request, self):
  File "/usr/local/lib/python3.10/dist-packages/rest_framework/permissions.py", line 243, in has_permission
    queryset = self._queryset(view)
  File "/usr/local/lib/python3.10/dist-packages/rest_framework/permissions.py", line 226, in _queryset
    queryset = view.get_queryset()
  File "/home/shivamkumarsain/Projects/Creworder-Django/accounts/views.py", line 138, in get_queryset
    if user.role.role == "admin" or user.role.role == "agent":
AttributeError: 'User' object has no attribute 'role'
2024-10-22 18:03:14,889 - django.request - ERROR - Internal Server Error: /api/branches/
Traceback (most recent call last):
  File "/usr/local/lib/python3.10/dist-packages/django/core/handlers/exception.py", line 55, in inner
    response = get_response(request)
  File "/usr/local/lib/python3.10/dist-packages/django/core/handlers/base.py", line 197, in _get_response
    response = wrapped_callback(request, *callback_args, **callback_kwargs)
  File "/usr/local/lib/python3.10/dist-packages/django/views/decorators/csrf.py", line 65, in _view_wrapper
    return view_func(request, *args, **kwargs)
  File "/usr/local/lib/python3.10/dist-packages/rest_framework/viewsets.py", line 124, in view
    return self.dispatch(request, *args, **kwargs)
  File "/usr/local/lib/python3.10/dist-packages/rest_framework/views.py", line 509, in dispatch
    response = self.handle_exception(exc)
  File "/usr/local/lib/python3.10/dist-packages/rest_framework/views.py", line 469, in handle_exception
    self.raise_uncaught_exception(exc)
  File "/usr/local/lib/python3.10/dist-packages/rest_framework/views.py", line 480, in raise_uncaught_exception
    raise exc
  File "/usr/local/lib/python3.10/dist-packages/rest_framework/views.py", line 497, in dispatch
    self.initial(request, *args, **kwargs)
  File "/usr/local/lib/python3.10/dist-packages/rest_framework/views.py", line 415, in initial
    self.check_permissions(request)
  File "/usr/local/lib/python3.10/dist-packages/rest_framework/views.py", line 332, in check_permissions
    if not permission.has_permission(request, self):
  File "/usr/local/lib/python3.10/dist-packages/rest_framework/permissions.py", line 243, in has_permission
    queryset = self._queryset(view)
  File "/usr/local/lib/python3.10/dist-packages/rest_framework/permissions.py", line 226, in _queryset
    queryset = view.get_queryset()
  File "/home/shivamkumarsain/Projects/Creworder-Django/accounts/views.py", line 138, in get_queryset
    if user.role.role == "admin" or user.role.role == "agent":
AttributeError: 'User' object has no attribute 'role'
2024-10-22 18:03:17,045 - django.request - ERROR - Internal Server Error: /api/branches/
Traceback (most recent call last):
  File "/usr/local/lib/python3.10/dist-packages/django/core/handlers/exception.py", line 55, in inner
    response = get_response(request)
  File "/usr/local/lib/python3.10/dist-packages/django/core/handlers/base.py", line 197, in _get_response
    response = wrapped_callback(request, *callback_args, **callback_kwargs)
  File "/usr/local/lib/python3.10/dist-packages/django/views/decorators/csrf.py", line 65, in _view_wrapper
    return view_func(request, *args, **kwargs)
  File "/usr/local/lib/python3.10/dist-packages/rest_framework/viewsets.py", line 124, in view
    return self.dispatch(request, *args, **kwargs)
  File "/usr/local/lib/python3.10/dist-packages/rest_framework/views.py", line 509, in dispatch
    response = self.handle_exception(exc)
  File "/usr/local/lib/python3.10/dist-packages/rest_framework/views.py", line 469, in handle_exception
    self.raise_uncaught_exception(exc)
  File "/usr/local/lib/python3.10/dist-packages/rest_framework/views.py", line 480, in raise_uncaught_exception
    raise exc
  File "/usr/local/lib/python3.10/dist-packages/rest_framework/views.py", line 497, in dispatch
    self.initial(request, *args, **kwargs)
  File "/usr/local/lib/python3.10/dist-packages/rest_framework/views.py", line 415, in initial
    self.check_permissions(request)
  File "/usr/local/lib/python3.10/dist-packages/rest_framework/views.py", line 332, in check_permissions
    if not permission.has_permission(request, self):
  File "/usr/local/lib/python3.10/dist-packages/rest_framework/permissions.py", line 243, in has_permission
    queryset = self._queryset(view)
  File "/usr/local/lib/python3.10/dist-packages/rest_framework/permissions.py", line 226, in _queryset
    queryset = view.get_queryset()
  File "/home/shivamkumarsain/Projects/Creworder-Django/accounts/views.py", line 138, in get_queryset
    if user.role.role == "admin" or user.role.role == "agent":
AttributeError: 'User' object has no attribute 'role'
2024-10-22 18:03:21,191 - django.request - ERROR - Internal Server Error: /api/branches/
Traceback (most recent call last):
  File "/usr/local/lib/python3.10/dist-packages/django/core/handlers/exception.py", line 55, in inner
    response = get_response(request)
  File "/usr/local/lib/python3.10/dist-packages/django/core/handlers/base.py", line 197, in _get_response
    response = wrapped_callback(request, *callback_args, **callback_kwargs)
  File "/usr/local/lib/python3.10/dist-packages/django/views/decorators/csrf.py", line 65, in _view_wrapper
    return view_func(request, *args, **kwargs)
  File "/usr/local/lib/python3.10/dist-packages/rest_framework/viewsets.py", line 124, in view
    return self.dispatch(request, *args, **kwargs)
  File "/usr/local/lib/python3.10/dist-packages/rest_framework/views.py", line 509, in dispatch
    response = self.handle_exception(exc)
  File "/usr/local/lib/python3.10/dist-packages/rest_framework/views.py", line 469, in handle_exception
    self.raise_uncaught_exception(exc)
  File "/usr/local/lib/python3.10/dist-packages/rest_framework/views.py", line 480, in raise_uncaught_exception
    raise exc
  File "/usr/local/lib/python3.10/dist-packages/rest_framework/views.py", line 497, in dispatch
    self.initial(request, *args, **kwargs)
  File "/usr/local/lib/python3.10/dist-packages/rest_framework/views.py", line 415, in initial
    self.check_permissions(request)
  File "/usr/local/lib/python3.10/dist-packages/rest_framework/views.py", line 332, in check_permissions
    if not permission.has_permission(request, self):
  File "/usr/local/lib/python3.10/dist-packages/rest_framework/permissions.py", line 243, in has_permission
    queryset = self._queryset(view)
  File "/usr/local/lib/python3.10/dist-packages/rest_framework/permissions.py", line 226, in _queryset
    queryset = view.get_queryset()
  File "/home/shivamkumarsain/Projects/Creworder-Django/accounts/views.py", line 138, in get_queryset
    if user.role.role == "admin" or user.role.role == "agent":
AttributeError: 'User' object has no attribute 'role'
2024-10-22 18:09:24,659 - django.request - ERROR - Internal Server Error: /api/branches/
Traceback (most recent call last):
  File "/usr/local/lib/python3.10/dist-packages/django/core/handlers/exception.py", line 55, in inner
    response = get_response(request)
  File "/usr/local/lib/python3.10/dist-packages/django/core/handlers/base.py", line 197, in _get_response
    response = wrapped_callback(request, *callback_args, **callback_kwargs)
  File "/usr/local/lib/python3.10/dist-packages/django/views/decorators/csrf.py", line 65, in _view_wrapper
    return view_func(request, *args, **kwargs)
  File "/usr/local/lib/python3.10/dist-packages/rest_framework/viewsets.py", line 124, in view
    return self.dispatch(request, *args, **kwargs)
  File "/usr/local/lib/python3.10/dist-packages/rest_framework/views.py", line 509, in dispatch
    response = self.handle_exception(exc)
  File "/usr/local/lib/python3.10/dist-packages/rest_framework/views.py", line 469, in handle_exception
    self.raise_uncaught_exception(exc)
  File "/usr/local/lib/python3.10/dist-packages/rest_framework/views.py", line 480, in raise_uncaught_exception
    raise exc
  File "/usr/local/lib/python3.10/dist-packages/rest_framework/views.py", line 497, in dispatch
    self.initial(request, *args, **kwargs)
  File "/usr/local/lib/python3.10/dist-packages/rest_framework/views.py", line 415, in initial
    self.check_permissions(request)
  File "/usr/local/lib/python3.10/dist-packages/rest_framework/views.py", line 332, in check_permissions
    if not permission.has_permission(request, self):
  File "/usr/local/lib/python3.10/dist-packages/rest_framework/permissions.py", line 243, in has_permission
    queryset = self._queryset(view)
  File "/usr/local/lib/python3.10/dist-packages/rest_framework/permissions.py", line 226, in _queryset
    queryset = view.get_queryset()
  File "/home/shivamkumarsain/Projects/Creworder-Django/accounts/views.py", line 138, in get_queryset
    if user.role.role == "admin" or user.role.role == "agent":
AttributeError: 'User' object has no attribute 'role'
2024-10-22 18:09:26,212 - django.request - ERROR - Internal Server Error: /api/branches/
Traceback (most recent call last):
  File "/usr/local/lib/python3.10/dist-packages/django/core/handlers/exception.py", line 55, in inner
    response = get_response(request)
  File "/usr/local/lib/python3.10/dist-packages/django/core/handlers/base.py", line 197, in _get_response
    response = wrapped_callback(request, *callback_args, **callback_kwargs)
  File "/usr/local/lib/python3.10/dist-packages/django/views/decorators/csrf.py", line 65, in _view_wrapper
    return view_func(request, *args, **kwargs)
  File "/usr/local/lib/python3.10/dist-packages/rest_framework/viewsets.py", line 124, in view
    return self.dispatch(request, *args, **kwargs)
  File "/usr/local/lib/python3.10/dist-packages/rest_framework/views.py", line 509, in dispatch
    response = self.handle_exception(exc)
  File "/usr/local/lib/python3.10/dist-packages/rest_framework/views.py", line 469, in handle_exception
    self.raise_uncaught_exception(exc)
  File "/usr/local/lib/python3.10/dist-packages/rest_framework/views.py", line 480, in raise_uncaught_exception
    raise exc
  File "/usr/local/lib/python3.10/dist-packages/rest_framework/views.py", line 497, in dispatch
    self.initial(request, *args, **kwargs)
  File "/usr/local/lib/python3.10/dist-packages/rest_framework/views.py", line 415, in initial
    self.check_permissions(request)
  File "/usr/local/lib/python3.10/dist-packages/rest_framework/views.py", line 332, in check_permissions
    if not permission.has_permission(request, self):
  File "/usr/local/lib/python3.10/dist-packages/rest_framework/permissions.py", line 243, in has_permission
    queryset = self._queryset(view)
  File "/usr/local/lib/python3.10/dist-packages/rest_framework/permissions.py", line 226, in _queryset
    queryset = view.get_queryset()
  File "/home/shivamkumarsain/Projects/Creworder-Django/accounts/views.py", line 138, in get_queryset
    if user.role.role == "admin" or user.role.role == "agent":
AttributeError: 'User' object has no attribute 'role'
2024-10-22 18:09:28,356 - django.request - ERROR - Internal Server Error: /api/branches/
Traceback (most recent call last):
  File "/usr/local/lib/python3.10/dist-packages/django/core/handlers/exception.py", line 55, in inner
    response = get_response(request)
  File "/usr/local/lib/python3.10/dist-packages/django/core/handlers/base.py", line 197, in _get_response
    response = wrapped_callback(request, *callback_args, **callback_kwargs)
  File "/usr/local/lib/python3.10/dist-packages/django/views/decorators/csrf.py", line 65, in _view_wrapper
    return view_func(request, *args, **kwargs)
  File "/usr/local/lib/python3.10/dist-packages/rest_framework/viewsets.py", line 124, in view
    return self.dispatch(request, *args, **kwargs)
  File "/usr/local/lib/python3.10/dist-packages/rest_framework/views.py", line 509, in dispatch
    response = self.handle_exception(exc)
  File "/usr/local/lib/python3.10/dist-packages/rest_framework/views.py", line 469, in handle_exception
    self.raise_uncaught_exception(exc)
  File "/usr/local/lib/python3.10/dist-packages/rest_framework/views.py", line 480, in raise_uncaught_exception
    raise exc
  File "/usr/local/lib/python3.10/dist-packages/rest_framework/views.py", line 497, in dispatch
    self.initial(request, *args, **kwargs)
  File "/usr/local/lib/python3.10/dist-packages/rest_framework/views.py", line 415, in initial
    self.check_permissions(request)
  File "/usr/local/lib/python3.10/dist-packages/rest_framework/views.py", line 332, in check_permissions
    if not permission.has_permission(request, self):
  File "/usr/local/lib/python3.10/dist-packages/rest_framework/permissions.py", line 243, in has_permission
    queryset = self._queryset(view)
  File "/usr/local/lib/python3.10/dist-packages/rest_framework/permissions.py", line 226, in _queryset
    queryset = view.get_queryset()
  File "/home/shivamkumarsain/Projects/Creworder-Django/accounts/views.py", line 138, in get_queryset
    if user.role.role == "admin" or user.role.role == "agent":
AttributeError: 'User' object has no attribute 'role'
2024-10-22 18:09:32,449 - django.request - ERROR - Internal Server Error: /api/branches/
Traceback (most recent call last):
  File "/usr/local/lib/python3.10/dist-packages/django/core/handlers/exception.py", line 55, in inner
    response = get_response(request)
  File "/usr/local/lib/python3.10/dist-packages/django/core/handlers/base.py", line 197, in _get_response
    response = wrapped_callback(request, *callback_args, **callback_kwargs)
  File "/usr/local/lib/python3.10/dist-packages/django/views/decorators/csrf.py", line 65, in _view_wrapper
    return view_func(request, *args, **kwargs)
  File "/usr/local/lib/python3.10/dist-packages/rest_framework/viewsets.py", line 124, in view
    return self.dispatch(request, *args, **kwargs)
  File "/usr/local/lib/python3.10/dist-packages/rest_framework/views.py", line 509, in dispatch
    response = self.handle_exception(exc)
  File "/usr/local/lib/python3.10/dist-packages/rest_framework/views.py", line 469, in handle_exception
    self.raise_uncaught_exception(exc)
  File "/usr/local/lib/python3.10/dist-packages/rest_framework/views.py", line 480, in raise_uncaught_exception
    raise exc
  File "/usr/local/lib/python3.10/dist-packages/rest_framework/views.py", line 497, in dispatch
    self.initial(request, *args, **kwargs)
  File "/usr/local/lib/python3.10/dist-packages/rest_framework/views.py", line 415, in initial
    self.check_permissions(request)
  File "/usr/local/lib/python3.10/dist-packages/rest_framework/views.py", line 332, in check_permissions
    if not permission.has_permission(request, self):
  File "/usr/local/lib/python3.10/dist-packages/rest_framework/permissions.py", line 243, in has_permission
    queryset = self._queryset(view)
  File "/usr/local/lib/python3.10/dist-packages/rest_framework/permissions.py", line 226, in _queryset
    queryset = view.get_queryset()
  File "/home/shivamkumarsain/Projects/Creworder-Django/accounts/views.py", line 138, in get_queryset
    if user.role.role == "admin" or user.role.role == "agent":
AttributeError: 'User' object has no attribute 'role'
2024-10-22 18:09:32,909 - django.request - ERROR - Internal Server Error: /api/branches/
Traceback (most recent call last):
  File "/usr/local/lib/python3.10/dist-packages/django/core/handlers/exception.py", line 55, in inner
    response = get_response(request)
  File "/usr/local/lib/python3.10/dist-packages/django/core/handlers/base.py", line 197, in _get_response
    response = wrapped_callback(request, *callback_args, **callback_kwargs)
  File "/usr/local/lib/python3.10/dist-packages/django/views/decorators/csrf.py", line 65, in _view_wrapper
    return view_func(request, *args, **kwargs)
  File "/usr/local/lib/python3.10/dist-packages/rest_framework/viewsets.py", line 124, in view
    return self.dispatch(request, *args, **kwargs)
  File "/usr/local/lib/python3.10/dist-packages/rest_framework/views.py", line 509, in dispatch
    response = self.handle_exception(exc)
  File "/usr/local/lib/python3.10/dist-packages/rest_framework/views.py", line 469, in handle_exception
    self.raise_uncaught_exception(exc)
  File "/usr/local/lib/python3.10/dist-packages/rest_framework/views.py", line 480, in raise_uncaught_exception
    raise exc
  File "/usr/local/lib/python3.10/dist-packages/rest_framework/views.py", line 497, in dispatch
    self.initial(request, *args, **kwargs)
  File "/usr/local/lib/python3.10/dist-packages/rest_framework/views.py", line 415, in initial
    self.check_permissions(request)
  File "/usr/local/lib/python3.10/dist-packages/rest_framework/views.py", line 332, in check_permissions
    if not permission.has_permission(request, self):
  File "/usr/local/lib/python3.10/dist-packages/rest_framework/permissions.py", line 243, in has_permission
    queryset = self._queryset(view)
  File "/usr/local/lib/python3.10/dist-packages/rest_framework/permissions.py", line 226, in _queryset
    queryset = view.get_queryset()
  File "/home/shivamkumarsain/Projects/Creworder-Django/accounts/views.py", line 138, in get_queryset
    if user.role.role == "admin" or user.role.role == "agent":
AttributeError: 'User' object has no attribute 'role'
2024-10-22 18:09:34,371 - django.request - ERROR - Internal Server Error: /api/branches/
Traceback (most recent call last):
  File "/usr/local/lib/python3.10/dist-packages/django/core/handlers/exception.py", line 55, in inner
    response = get_response(request)
  File "/usr/local/lib/python3.10/dist-packages/django/core/handlers/base.py", line 197, in _get_response
    response = wrapped_callback(request, *callback_args, **callback_kwargs)
  File "/usr/local/lib/python3.10/dist-packages/django/views/decorators/csrf.py", line 65, in _view_wrapper
    return view_func(request, *args, **kwargs)
  File "/usr/local/lib/python3.10/dist-packages/rest_framework/viewsets.py", line 124, in view
    return self.dispatch(request, *args, **kwargs)
  File "/usr/local/lib/python3.10/dist-packages/rest_framework/views.py", line 509, in dispatch
    response = self.handle_exception(exc)
  File "/usr/local/lib/python3.10/dist-packages/rest_framework/views.py", line 469, in handle_exception
    self.raise_uncaught_exception(exc)
  File "/usr/local/lib/python3.10/dist-packages/rest_framework/views.py", line 480, in raise_uncaught_exception
    raise exc
  File "/usr/local/lib/python3.10/dist-packages/rest_framework/views.py", line 497, in dispatch
    self.initial(request, *args, **kwargs)
  File "/usr/local/lib/python3.10/dist-packages/rest_framework/views.py", line 415, in initial
    self.check_permissions(request)
  File "/usr/local/lib/python3.10/dist-packages/rest_framework/views.py", line 332, in check_permissions
    if not permission.has_permission(request, self):
  File "/usr/local/lib/python3.10/dist-packages/rest_framework/permissions.py", line 243, in has_permission
    queryset = self._queryset(view)
  File "/usr/local/lib/python3.10/dist-packages/rest_framework/permissions.py", line 226, in _queryset
    queryset = view.get_queryset()
  File "/home/shivamkumarsain/Projects/Creworder-Django/accounts/views.py", line 138, in get_queryset
    if user.role.role == "admin" or user.role.role == "agent":
AttributeError: 'User' object has no attribute 'role'
2024-10-22 18:09:36,453 - django.request - ERROR - Internal Server Error: /api/branches/
Traceback (most recent call last):
  File "/usr/local/lib/python3.10/dist-packages/django/core/handlers/exception.py", line 55, in inner
    response = get_response(request)
  File "/usr/local/lib/python3.10/dist-packages/django/core/handlers/base.py", line 197, in _get_response
    response = wrapped_callback(request, *callback_args, **callback_kwargs)
  File "/usr/local/lib/python3.10/dist-packages/django/views/decorators/csrf.py", line 65, in _view_wrapper
    return view_func(request, *args, **kwargs)
  File "/usr/local/lib/python3.10/dist-packages/rest_framework/viewsets.py", line 124, in view
    return self.dispatch(request, *args, **kwargs)
  File "/usr/local/lib/python3.10/dist-packages/rest_framework/views.py", line 509, in dispatch
    response = self.handle_exception(exc)
  File "/usr/local/lib/python3.10/dist-packages/rest_framework/views.py", line 469, in handle_exception
    self.raise_uncaught_exception(exc)
  File "/usr/local/lib/python3.10/dist-packages/rest_framework/views.py", line 480, in raise_uncaught_exception
    raise exc
  File "/usr/local/lib/python3.10/dist-packages/rest_framework/views.py", line 497, in dispatch
    self.initial(request, *args, **kwargs)
  File "/usr/local/lib/python3.10/dist-packages/rest_framework/views.py", line 415, in initial
    self.check_permissions(request)
  File "/usr/local/lib/python3.10/dist-packages/rest_framework/views.py", line 332, in check_permissions
    if not permission.has_permission(request, self):
  File "/usr/local/lib/python3.10/dist-packages/rest_framework/permissions.py", line 243, in has_permission
    queryset = self._queryset(view)
  File "/usr/local/lib/python3.10/dist-packages/rest_framework/permissions.py", line 226, in _queryset
    queryset = view.get_queryset()
  File "/home/shivamkumarsain/Projects/Creworder-Django/accounts/views.py", line 138, in get_queryset
    if user.role.role == "admin" or user.role.role == "agent":
AttributeError: 'User' object has no attribute 'role'
