2024-11-27 14:40:47,660 - django.request - WARNING - Forbidden: /api/top-shelling-product-list/
2024-11-28 10:59:52,727 - django.request - WARNING - Not Found: /favicon.ico
2024-11-28 14:00:54,196 - django.request - WARNING - Bad Request: /api/createCloudTelephoneyChannel/
2024-11-28 14:01:20,452 - django.request - WARNING - Method Not Allowed: /api/getCloudTelephoneyChannel/
2024-11-28 16:25:28,540 - django.request - WARNING - Bad Request: /api/createCloudTelephoneyChannel/
2024-11-28 16:26:41,292 - django.request - ERROR - Internal Server Error: /api/createCloudTelephoneyChannel/
Traceback (most recent call last):
  File "/usr/local/lib/python3.10/dist-packages/django/core/handlers/exception.py", line 55, in inner
    response = get_response(request)
  File "/usr/local/lib/python3.10/dist-packages/django/core/handlers/base.py", line 197, in _get_response
    response = wrapped_callback(request, *callback_args, **callback_kwargs)
  File "/usr/local/lib/python3.10/dist-packages/django/views/decorators/csrf.py", line 65, in _view_wrapper
    return view_func(request, *args, **kwargs)
  File "/usr/local/lib/python3.10/dist-packages/django/views/generic/base.py", line 104, in view
    return self.dispatch(request, *args, **kwargs)
  File "/usr/local/lib/python3.10/dist-packages/rest_framework/views.py", line 509, in dispatch
    response = self.handle_exception(exc)
  File "/usr/local/lib/python3.10/dist-packages/rest_framework/views.py", line 469, in handle_exception
    self.raise_uncaught_exception(exc)
  File "/usr/local/lib/python3.10/dist-packages/rest_framework/views.py", line 480, in raise_uncaught_exception
    raise exc
  File "/usr/local/lib/python3.10/dist-packages/rest_framework/views.py", line 506, in dispatch
    response = handler(request, *args, **kwargs)
  File "/home/shivamkumarsain/Projects/Creworder-Django/cloud_telephony/views.py", line 33, in post
    CloudTelephonyChannel = createCloudTelephoneyChannel(
  File "/home/shivamkumarsain/Projects/Creworder-Django/services/cloud_telephoney/cloud_telephoney_service.py", line 17, in createCloudTelephoneyChannel
    data["branch"] = serialized_data["branch"]
  File "/usr/local/lib/python3.10/dist-packages/django/http/request.py", line 562, in __setitem__
    self._assert_mutable()
  File "/usr/local/lib/python3.10/dist-packages/django/http/request.py", line 559, in _assert_mutable
    raise AttributeError("This QueryDict instance is immutable")
AttributeError: This QueryDict instance is immutable
2024-11-28 16:27:42,152 - django.request - ERROR - Internal Server Error: /api/createCloudTelephoneyChannel/
Traceback (most recent call last):
  File "/usr/local/lib/python3.10/dist-packages/django/core/handlers/exception.py", line 55, in inner
    response = get_response(request)
  File "/usr/local/lib/python3.10/dist-packages/django/core/handlers/base.py", line 197, in _get_response
    response = wrapped_callback(request, *callback_args, **callback_kwargs)
  File "/usr/local/lib/python3.10/dist-packages/django/views/decorators/csrf.py", line 65, in _view_wrapper
    return view_func(request, *args, **kwargs)
  File "/usr/local/lib/python3.10/dist-packages/django/views/generic/base.py", line 104, in view
    return self.dispatch(request, *args, **kwargs)
  File "/usr/local/lib/python3.10/dist-packages/rest_framework/views.py", line 509, in dispatch
    response = self.handle_exception(exc)
  File "/usr/local/lib/python3.10/dist-packages/rest_framework/views.py", line 469, in handle_exception
    self.raise_uncaught_exception(exc)
  File "/usr/local/lib/python3.10/dist-packages/rest_framework/views.py", line 480, in raise_uncaught_exception
    raise exc
  File "/usr/local/lib/python3.10/dist-packages/rest_framework/views.py", line 506, in dispatch
    response = handler(request, *args, **kwargs)
  File "/home/shivamkumarsain/Projects/Creworder-Django/cloud_telephony/views.py", line 33, in post
    CloudTelephonyChannel = createCloudTelephoneyChannel(
  File "/home/shivamkumarsain/Projects/Creworder-Django/services/cloud_telephoney/cloud_telephoney_service.py", line 17, in createCloudTelephoneyChannel
    data["branch"] = serialized_data["branch"]
  File "/usr/local/lib/python3.10/dist-packages/django/http/request.py", line 562, in __setitem__
    self._assert_mutable()
  File "/usr/local/lib/python3.10/dist-packages/django/http/request.py", line 559, in _assert_mutable
    raise AttributeError("This QueryDict instance is immutable")
AttributeError: This QueryDict instance is immutable
2024-11-28 16:28:08,421 - django.request - WARNING - Bad Request: /api/createCloudTelephoneyChannel/
2024-11-28 16:28:16,553 - django.request - WARNING - Bad Request: /api/createCloudTelephoneyChannel/
2024-11-28 16:29:04,825 - django.request - WARNING - Bad Request: /api/createCloudTelephoneyChannel/
2024-11-28 16:30:24,766 - django.request - WARNING - Bad Request: /api/createCloudTelephoneyChannel/
2024-11-28 16:30:48,908 - django.request - WARNING - Bad Request: /api/createCloudTelephoneyChannel/
2024-11-28 16:32:15,285 - django.request - WARNING - Bad Request: /api/createCloudTelephoneyChannel/
2024-11-28 16:33:45,942 - django.request - WARNING - Bad Request: /api/createCloudTelephoneyChannel/
2024-11-28 16:33:54,019 - django.request - ERROR - Internal Server Error: /api/createCloudTelephoneyChannel/
Traceback (most recent call last):
  File "/usr/local/lib/python3.10/dist-packages/django/core/handlers/exception.py", line 55, in inner
    response = get_response(request)
  File "/usr/local/lib/python3.10/dist-packages/django/core/handlers/base.py", line 197, in _get_response
    response = wrapped_callback(request, *callback_args, **callback_kwargs)
  File "/usr/local/lib/python3.10/dist-packages/django/views/decorators/csrf.py", line 65, in _view_wrapper
    return view_func(request, *args, **kwargs)
  File "/usr/local/lib/python3.10/dist-packages/django/views/generic/base.py", line 104, in view
    return self.dispatch(request, *args, **kwargs)
  File "/usr/local/lib/python3.10/dist-packages/rest_framework/views.py", line 509, in dispatch
    response = self.handle_exception(exc)
  File "/usr/local/lib/python3.10/dist-packages/rest_framework/views.py", line 469, in handle_exception
    self.raise_uncaught_exception(exc)
  File "/usr/local/lib/python3.10/dist-packages/rest_framework/views.py", line 480, in raise_uncaught_exception
    raise exc
  File "/usr/local/lib/python3.10/dist-packages/rest_framework/views.py", line 506, in dispatch
    response = handler(request, *args, **kwargs)
  File "/home/shivamkumarsain/Projects/Creworder-Django/cloud_telephony/views.py", line 33, in post
    CloudTelephonyChannel = createCloudTelephoneyChannel(
  File "/home/shivamkumarsain/Projects/Creworder-Django/services/cloud_telephoney/cloud_telephoney_service.py", line 17, in createCloudTelephoneyChannel
    data["branch"] = serialized_data["branch"]
  File "/usr/local/lib/python3.10/dist-packages/django/http/request.py", line 562, in __setitem__
    self._assert_mutable()
  File "/usr/local/lib/python3.10/dist-packages/django/http/request.py", line 559, in _assert_mutable
    raise AttributeError("This QueryDict instance is immutable")
AttributeError: This QueryDict instance is immutable
2024-11-28 16:40:13,732 - django.request - ERROR - Internal Server Error: /api/createCloudTelephoneyChannel/
Traceback (most recent call last):
  File "/usr/local/lib/python3.10/dist-packages/django/core/handlers/exception.py", line 55, in inner
    response = get_response(request)
  File "/usr/local/lib/python3.10/dist-packages/django/core/handlers/base.py", line 197, in _get_response
    response = wrapped_callback(request, *callback_args, **callback_kwargs)
  File "/usr/local/lib/python3.10/dist-packages/django/views/decorators/csrf.py", line 65, in _view_wrapper
    return view_func(request, *args, **kwargs)
  File "/usr/local/lib/python3.10/dist-packages/django/views/generic/base.py", line 104, in view
    return self.dispatch(request, *args, **kwargs)
  File "/usr/local/lib/python3.10/dist-packages/rest_framework/views.py", line 509, in dispatch
    response = self.handle_exception(exc)
  File "/usr/local/lib/python3.10/dist-packages/rest_framework/views.py", line 469, in handle_exception
    self.raise_uncaught_exception(exc)
  File "/usr/local/lib/python3.10/dist-packages/rest_framework/views.py", line 480, in raise_uncaught_exception
    raise exc
  File "/usr/local/lib/python3.10/dist-packages/rest_framework/views.py", line 506, in dispatch
    response = handler(request, *args, **kwargs)
  File "/home/shivamkumarsain/Projects/Creworder-Django/cloud_telephony/views.py", line 34, in post
    CloudTelephonyChannel = createCloudTelephoneyChannel(
  File "/home/shivamkumarsain/Projects/Creworder-Django/services/cloud_telephoney/cloud_telephoney_service.py", line 17, in createCloudTelephoneyChannel
    data["branch"] = serialized_data["branch"]
  File "/usr/local/lib/python3.10/dist-packages/django/http/request.py", line 562, in __setitem__
    self._assert_mutable()
  File "/usr/local/lib/python3.10/dist-packages/django/http/request.py", line 559, in _assert_mutable
    raise AttributeError("This QueryDict instance is immutable")
AttributeError: This QueryDict instance is immutable
2024-11-28 16:40:43,042 - django.request - WARNING - Bad Request: /api/createCloudTelephoneyChannel/
2024-11-28 16:41:02,222 - django.request - ERROR - Internal Server Error: /api/createCloudTelephoneyChannel/
Traceback (most recent call last):
  File "/usr/local/lib/python3.10/dist-packages/django/core/handlers/exception.py", line 55, in inner
    response = get_response(request)
  File "/usr/local/lib/python3.10/dist-packages/django/core/handlers/base.py", line 197, in _get_response
    response = wrapped_callback(request, *callback_args, **callback_kwargs)
  File "/usr/local/lib/python3.10/dist-packages/django/views/decorators/csrf.py", line 65, in _view_wrapper
    return view_func(request, *args, **kwargs)
  File "/usr/local/lib/python3.10/dist-packages/django/views/generic/base.py", line 104, in view
    return self.dispatch(request, *args, **kwargs)
  File "/usr/local/lib/python3.10/dist-packages/rest_framework/views.py", line 509, in dispatch
    response = self.handle_exception(exc)
  File "/usr/local/lib/python3.10/dist-packages/rest_framework/views.py", line 469, in handle_exception
    self.raise_uncaught_exception(exc)
  File "/usr/local/lib/python3.10/dist-packages/rest_framework/views.py", line 480, in raise_uncaught_exception
    raise exc
  File "/usr/local/lib/python3.10/dist-packages/rest_framework/views.py", line 506, in dispatch
    response = handler(request, *args, **kwargs)
  File "/home/shivamkumarsain/Projects/Creworder-Django/cloud_telephony/views.py", line 34, in post
    CloudTelephonyChannel = createCloudTelephoneyChannel(
  File "/home/shivamkumarsain/Projects/Creworder-Django/services/cloud_telephoney/cloud_telephoney_service.py", line 17, in createCloudTelephoneyChannel
    data["branch"] = serialized_data["branch"]
  File "/usr/local/lib/python3.10/dist-packages/django/http/request.py", line 562, in __setitem__
    self._assert_mutable()
  File "/usr/local/lib/python3.10/dist-packages/django/http/request.py", line 559, in _assert_mutable
    raise AttributeError("This QueryDict instance is immutable")
AttributeError: This QueryDict instance is immutable
2024-11-28 16:44:36,237 - django.request - WARNING - Bad Request: /api/createCloudTelephoneyChannel/
2024-11-28 18:45:18,055 - django.request - WARNING - Forbidden: /api/schedule-orders/
2024-11-28 18:45:46,371 - django.request - ERROR - Internal Server Error: /api/schedule-orders/
Traceback (most recent call last):
  File "/usr/local/lib/python3.10/dist-packages/rest_framework/request.py", line 421, in __getattr__
    return getattr(_request, attr)
AttributeError: 'WSGIRequest' object has no attribute 'profile'

During handling of the above exception, another exception occurred:

Traceback (most recent call last):
  File "/usr/local/lib/python3.10/dist-packages/django/core/handlers/exception.py", line 55, in inner
    response = get_response(request)
  File "/usr/local/lib/python3.10/dist-packages/django/core/handlers/base.py", line 197, in _get_response
    response = wrapped_callback(request, *callback_args, **callback_kwargs)
  File "/usr/local/lib/python3.10/dist-packages/django/views/decorators/csrf.py", line 65, in _view_wrapper
    return view_func(request, *args, **kwargs)
  File "/usr/local/lib/python3.10/dist-packages/rest_framework/viewsets.py", line 124, in view
    return self.dispatch(request, *args, **kwargs)
  File "/usr/local/lib/python3.10/dist-packages/rest_framework/views.py", line 509, in dispatch
    response = self.handle_exception(exc)
  File "/usr/local/lib/python3.10/dist-packages/rest_framework/views.py", line 469, in handle_exception
    self.raise_uncaught_exception(exc)
  File "/usr/local/lib/python3.10/dist-packages/rest_framework/views.py", line 480, in raise_uncaught_exception
    raise exc
  File "/usr/local/lib/python3.10/dist-packages/rest_framework/views.py", line 506, in dispatch
    response = handler(request, *args, **kwargs)
  File "/usr/lib/python3.10/contextlib.py", line 79, in inner
    return func(*args, **kwds)
  File "/home/shivamkumarsain/Projects/Creworder-Django/shipment/views.py", line 143, in create
    trackdata = ShipmentModel.objects.filter(branch=request.profile.branch.id,company=request.profile.company.id,status=1)
  File "/usr/local/lib/python3.10/dist-packages/rest_framework/request.py", line 423, in __getattr__
    return self.__getattribute__(attr)
AttributeError: 'Request' object has no attribute 'profile'
2024-11-28 18:46:43,974 - django.request - ERROR - Internal Server Error: /api/schedule-orders/
Traceback (most recent call last):
  File "/usr/local/lib/python3.10/dist-packages/rest_framework/request.py", line 421, in __getattr__
    return getattr(_request, attr)
AttributeError: 'WSGIRequest' object has no attribute 'profile'

During handling of the above exception, another exception occurred:

Traceback (most recent call last):
  File "/usr/local/lib/python3.10/dist-packages/django/core/handlers/exception.py", line 55, in inner
    response = get_response(request)
  File "/usr/local/lib/python3.10/dist-packages/django/core/handlers/base.py", line 197, in _get_response
    response = wrapped_callback(request, *callback_args, **callback_kwargs)
  File "/usr/local/lib/python3.10/dist-packages/django/views/decorators/csrf.py", line 65, in _view_wrapper
    return view_func(request, *args, **kwargs)
  File "/usr/local/lib/python3.10/dist-packages/rest_framework/viewsets.py", line 124, in view
    return self.dispatch(request, *args, **kwargs)
  File "/usr/local/lib/python3.10/dist-packages/rest_framework/views.py", line 509, in dispatch
    response = self.handle_exception(exc)
  File "/usr/local/lib/python3.10/dist-packages/rest_framework/views.py", line 469, in handle_exception
    self.raise_uncaught_exception(exc)
  File "/usr/local/lib/python3.10/dist-packages/rest_framework/views.py", line 480, in raise_uncaught_exception
    raise exc
  File "/usr/local/lib/python3.10/dist-packages/rest_framework/views.py", line 506, in dispatch
    response = handler(request, *args, **kwargs)
  File "/usr/lib/python3.10/contextlib.py", line 79, in inner
    return func(*args, **kwds)
  File "/home/shivamkumarsain/Projects/Creworder-Django/shipment/views.py", line 143, in create
    trackdata = ShipmentModel.objects.filter(branch=user.profile.branch.id,company=user.profile.company.id,status=1)
  File "/usr/local/lib/python3.10/dist-packages/rest_framework/request.py", line 423, in __getattr__
    return self.__getattribute__(attr)
AttributeError: 'Request' object has no attribute 'profile'
2024-11-28 18:48:50,714 - django.request - ERROR - Internal Server Error: /api/schedule-orders/
Traceback (most recent call last):
  File "/usr/local/lib/python3.10/dist-packages/django/core/handlers/exception.py", line 55, in inner
    response = get_response(request)
  File "/usr/local/lib/python3.10/dist-packages/django/core/handlers/base.py", line 197, in _get_response
    response = wrapped_callback(request, *callback_args, **callback_kwargs)
  File "/usr/local/lib/python3.10/dist-packages/django/views/decorators/csrf.py", line 65, in _view_wrapper
    return view_func(request, *args, **kwargs)
  File "/usr/local/lib/python3.10/dist-packages/rest_framework/viewsets.py", line 124, in view
    return self.dispatch(request, *args, **kwargs)
  File "/usr/local/lib/python3.10/dist-packages/rest_framework/views.py", line 509, in dispatch
    response = self.handle_exception(exc)
  File "/usr/local/lib/python3.10/dist-packages/rest_framework/views.py", line 469, in handle_exception
    self.raise_uncaught_exception(exc)
  File "/usr/local/lib/python3.10/dist-packages/rest_framework/views.py", line 480, in raise_uncaught_exception
    raise exc
  File "/usr/local/lib/python3.10/dist-packages/rest_framework/views.py", line 506, in dispatch
    response = handler(request, *args, **kwargs)
  File "/usr/lib/python3.10/contextlib.py", line 79, in inner
    return func(*args, **kwds)
  File "/home/shivamkumarsain/Projects/Creworder-Django/shipment/views.py", line 146, in create
    return Response(serialized_data.data)
AttributeError: 'ReturnList' object has no attribute 'data'
2024-11-28 18:50:16,919 - django.request - ERROR - Internal Server Error: /api/schedule-orders/
Traceback (most recent call last):
  File "/usr/local/lib/python3.10/dist-packages/django/core/handlers/exception.py", line 55, in inner
    response = get_response(request)
  File "/usr/local/lib/python3.10/dist-packages/django/core/handlers/base.py", line 197, in _get_response
    response = wrapped_callback(request, *callback_args, **callback_kwargs)
  File "/usr/local/lib/python3.10/dist-packages/django/views/decorators/csrf.py", line 65, in _view_wrapper
    return view_func(request, *args, **kwargs)
  File "/usr/local/lib/python3.10/dist-packages/rest_framework/viewsets.py", line 124, in view
    return self.dispatch(request, *args, **kwargs)
  File "/usr/local/lib/python3.10/dist-packages/rest_framework/views.py", line 509, in dispatch
    response = self.handle_exception(exc)
  File "/usr/local/lib/python3.10/dist-packages/rest_framework/views.py", line 469, in handle_exception
    self.raise_uncaught_exception(exc)
  File "/usr/local/lib/python3.10/dist-packages/rest_framework/views.py", line 480, in raise_uncaught_exception
    raise exc
  File "/usr/local/lib/python3.10/dist-packages/rest_framework/views.py", line 506, in dispatch
    response = handler(request, *args, **kwargs)
  File "/usr/lib/python3.10/contextlib.py", line 79, in inner
    return func(*args, **kwds)
  File "/home/shivamkumarsain/Projects/Creworder-Django/shipment/views.py", line 146, in create
    for shipmentData in serialized_data:
TypeError: 'ListSerializer' object is not iterable
2024-11-28 18:50:40,353 - django.request - ERROR - Internal Server Error: /api/schedule-orders/
Traceback (most recent call last):
  File "/usr/local/lib/python3.10/dist-packages/django/core/handlers/exception.py", line 55, in inner
    response = get_response(request)
  File "/usr/local/lib/python3.10/dist-packages/django/core/handlers/base.py", line 197, in _get_response
    response = wrapped_callback(request, *callback_args, **callback_kwargs)
  File "/usr/local/lib/python3.10/dist-packages/django/views/decorators/csrf.py", line 65, in _view_wrapper
    return view_func(request, *args, **kwargs)
  File "/usr/local/lib/python3.10/dist-packages/rest_framework/viewsets.py", line 124, in view
    return self.dispatch(request, *args, **kwargs)
  File "/usr/local/lib/python3.10/dist-packages/rest_framework/views.py", line 511, in dispatch
    self.response = self.finalize_response(request, response, *args, **kwargs)
  File "/usr/local/lib/python3.10/dist-packages/rest_framework/views.py", line 423, in finalize_response
    assert isinstance(response, HttpResponseBase), (
AssertionError: Expected a `Response`, `HttpResponse` or `StreamingHttpResponse` to be returned from the view, but received a `<class 'NoneType'>`
2024-11-29 11:19:01,892 - django.request - ERROR - Internal Server Error: /api/schedule-orders/
Traceback (most recent call last):
  File "/usr/local/lib/python3.10/dist-packages/django/core/handlers/exception.py", line 55, in inner
    response = get_response(request)
  File "/usr/local/lib/python3.10/dist-packages/django/core/handlers/base.py", line 197, in _get_response
    response = wrapped_callback(request, *callback_args, **callback_kwargs)
  File "/usr/local/lib/python3.10/dist-packages/django/views/decorators/csrf.py", line 65, in _view_wrapper
    return view_func(request, *args, **kwargs)
  File "/usr/local/lib/python3.10/dist-packages/rest_framework/viewsets.py", line 124, in view
    return self.dispatch(request, *args, **kwargs)
  File "/usr/local/lib/python3.10/dist-packages/rest_framework/views.py", line 511, in dispatch
    self.response = self.finalize_response(request, response, *args, **kwargs)
  File "/usr/local/lib/python3.10/dist-packages/rest_framework/views.py", line 423, in finalize_response
    assert isinstance(response, HttpResponseBase), (
AssertionError: Expected a `Response`, `HttpResponse` or `StreamingHttpResponse` to be returned from the view, but received a `<class 'NoneType'>`
2024-11-29 11:59:52,739 - django.request - ERROR - Internal Server Error: /api/schedule-orders/
Traceback (most recent call last):
  File "/usr/local/lib/python3.10/dist-packages/django/core/handlers/exception.py", line 55, in inner
    response = get_response(request)
  File "/usr/local/lib/python3.10/dist-packages/django/core/handlers/base.py", line 197, in _get_response
    response = wrapped_callback(request, *callback_args, **callback_kwargs)
  File "/usr/local/lib/python3.10/dist-packages/django/views/decorators/csrf.py", line 65, in _view_wrapper
    return view_func(request, *args, **kwargs)
  File "/usr/local/lib/python3.10/dist-packages/rest_framework/viewsets.py", line 124, in view
    return self.dispatch(request, *args, **kwargs)
  File "/usr/local/lib/python3.10/dist-packages/rest_framework/views.py", line 511, in dispatch
    self.response = self.finalize_response(request, response, *args, **kwargs)
  File "/usr/local/lib/python3.10/dist-packages/rest_framework/views.py", line 423, in finalize_response
    assert isinstance(response, HttpResponseBase), (
AssertionError: Expected a `Response`, `HttpResponse` or `StreamingHttpResponse` to be returned from the view, but received a `<class 'NoneType'>`
2024-11-29 12:11:59,506 - django.request - ERROR - Internal Server Error: /api/schedule-orders/
Traceback (most recent call last):
  File "/usr/local/lib/python3.10/dist-packages/django/core/handlers/exception.py", line 55, in inner
    response = get_response(request)
  File "/usr/local/lib/python3.10/dist-packages/django/core/handlers/base.py", line 197, in _get_response
    response = wrapped_callback(request, *callback_args, **callback_kwargs)
  File "/usr/local/lib/python3.10/dist-packages/django/views/decorators/csrf.py", line 65, in _view_wrapper
    return view_func(request, *args, **kwargs)
  File "/usr/local/lib/python3.10/dist-packages/rest_framework/viewsets.py", line 124, in view
    return self.dispatch(request, *args, **kwargs)
  File "/usr/local/lib/python3.10/dist-packages/rest_framework/views.py", line 511, in dispatch
    self.response = self.finalize_response(request, response, *args, **kwargs)
  File "/usr/local/lib/python3.10/dist-packages/rest_framework/views.py", line 423, in finalize_response
    assert isinstance(response, HttpResponseBase), (
AssertionError: Expected a `Response`, `HttpResponse` or `StreamingHttpResponse` to be returned from the view, but received a `<class 'NoneType'>`
2024-11-29 12:12:39,090 - django.request - ERROR - Internal Server Error: /api/schedule-orders/
Traceback (most recent call last):
  File "/usr/local/lib/python3.10/dist-packages/django/core/handlers/exception.py", line 55, in inner
    response = get_response(request)
  File "/usr/local/lib/python3.10/dist-packages/django/core/handlers/base.py", line 197, in _get_response
    response = wrapped_callback(request, *callback_args, **callback_kwargs)
  File "/usr/local/lib/python3.10/dist-packages/django/views/decorators/csrf.py", line 65, in _view_wrapper
    return view_func(request, *args, **kwargs)
  File "/usr/local/lib/python3.10/dist-packages/rest_framework/viewsets.py", line 124, in view
    return self.dispatch(request, *args, **kwargs)
  File "/usr/local/lib/python3.10/dist-packages/rest_framework/views.py", line 511, in dispatch
    self.response = self.finalize_response(request, response, *args, **kwargs)
  File "/usr/local/lib/python3.10/dist-packages/rest_framework/views.py", line 423, in finalize_response
    assert isinstance(response, HttpResponseBase), (
AssertionError: Expected a `Response`, `HttpResponse` or `StreamingHttpResponse` to be returned from the view, but received a `<class 'NoneType'>`
2024-11-29 12:14:15,963 - django.request - ERROR - Internal Server Error: /api/schedule-orders/
Traceback (most recent call last):
  File "/usr/local/lib/python3.10/dist-packages/django/core/handlers/exception.py", line 55, in inner
    response = get_response(request)
  File "/usr/local/lib/python3.10/dist-packages/django/core/handlers/base.py", line 197, in _get_response
    response = wrapped_callback(request, *callback_args, **callback_kwargs)
  File "/usr/local/lib/python3.10/dist-packages/django/views/decorators/csrf.py", line 65, in _view_wrapper
    return view_func(request, *args, **kwargs)
  File "/usr/local/lib/python3.10/dist-packages/rest_framework/viewsets.py", line 124, in view
    return self.dispatch(request, *args, **kwargs)
  File "/usr/local/lib/python3.10/dist-packages/rest_framework/views.py", line 511, in dispatch
    self.response = self.finalize_response(request, response, *args, **kwargs)
  File "/usr/local/lib/python3.10/dist-packages/rest_framework/views.py", line 423, in finalize_response
    assert isinstance(response, HttpResponseBase), (
AssertionError: Expected a `Response`, `HttpResponse` or `StreamingHttpResponse` to be returned from the view, but received a `<class 'NoneType'>`
2024-11-29 12:33:03,115 - django.request - ERROR - Internal Server Error: /api/schedule-orders/
Traceback (most recent call last):
  File "/usr/local/lib/python3.10/dist-packages/django/core/handlers/exception.py", line 55, in inner
    response = get_response(request)
  File "/usr/local/lib/python3.10/dist-packages/django/core/handlers/base.py", line 197, in _get_response
    response = wrapped_callback(request, *callback_args, **callback_kwargs)
  File "/usr/local/lib/python3.10/dist-packages/django/views/decorators/csrf.py", line 65, in _view_wrapper
    return view_func(request, *args, **kwargs)
  File "/usr/local/lib/python3.10/dist-packages/rest_framework/viewsets.py", line 124, in view
    return self.dispatch(request, *args, **kwargs)
  File "/usr/local/lib/python3.10/dist-packages/rest_framework/views.py", line 509, in dispatch
    response = self.handle_exception(exc)
  File "/usr/local/lib/python3.10/dist-packages/rest_framework/views.py", line 469, in handle_exception
    self.raise_uncaught_exception(exc)
  File "/usr/local/lib/python3.10/dist-packages/rest_framework/views.py", line 480, in raise_uncaught_exception
    raise exc
  File "/usr/local/lib/python3.10/dist-packages/rest_framework/views.py", line 506, in dispatch
    response = handler(request, *args, **kwargs)
  File "/usr/lib/python3.10/contextlib.py", line 79, in inner
    return func(*args, **kwds)
  File "/home/shivamkumarsain/Projects/Creworder-Django/shipment/views.py", line 153, in create
    {
TypeError: unhashable type: 'dict'
2024-11-29 14:11:47,514 - django.request - WARNING - Bad Request: /api/pixel-code/
2024-11-29 14:25:16,714 - django.request - WARNING - Bad Request: /api/banner/
2024-11-29 14:25:36,846 - django.request - WARNING - Bad Request: /api/banner/
2024-11-29 15:12:13,337 - django.request - ERROR - Internal Server Error: /api/schedule-orders/
Traceback (most recent call last):
  File "/usr/local/lib/python3.10/dist-packages/django/core/handlers/exception.py", line 55, in inner
    response = get_response(request)
  File "/usr/local/lib/python3.10/dist-packages/django/core/handlers/base.py", line 197, in _get_response
    response = wrapped_callback(request, *callback_args, **callback_kwargs)
  File "/usr/local/lib/python3.10/dist-packages/django/views/decorators/csrf.py", line 65, in _view_wrapper
    return view_func(request, *args, **kwargs)
  File "/usr/local/lib/python3.10/dist-packages/rest_framework/viewsets.py", line 124, in view
    return self.dispatch(request, *args, **kwargs)
  File "/usr/local/lib/python3.10/dist-packages/rest_framework/views.py", line 509, in dispatch
    response = self.handle_exception(exc)
  File "/usr/local/lib/python3.10/dist-packages/rest_framework/views.py", line 469, in handle_exception
    self.raise_uncaught_exception(exc)
  File "/usr/local/lib/python3.10/dist-packages/rest_framework/views.py", line 480, in raise_uncaught_exception
    raise exc
  File "/usr/local/lib/python3.10/dist-packages/rest_framework/views.py", line 506, in dispatch
    response = handler(request, *args, **kwargs)
  File "/usr/lib/python3.10/contextlib.py", line 79, in inner
    return func(*args, **kwds)
  File "/home/shivamkumarsain/Projects/Creworder-Django/shipment/views.py", line 150, in create
    token=shiprocket_service.schedule_order([37,36,35,34], request.user.profile.branch.id, request.user.profile.company.id)
  File "/home/shivamkumarsain/Projects/Creworder-Django/services/shipment/schedule_orders.py", line 119, in schedule_order
    for order in OrdersDataSerializer:
TypeError: 'ListSerializer' object is not iterable
2024-12-02 10:29:23,834 - django.request - WARNING - Not Found: /favicon.ico
2024-12-02 12:23:37,078 - django.request - WARNING - Bad Request: /dj-rest-auth/login/
2024-12-02 13:05:52,769 - django.request - ERROR - Internal Server Error: /api/specific-users/
Traceback (most recent call last):
  File "/usr/local/lib/python3.10/dist-packages/django/core/handlers/exception.py", line 55, in inner
    response = get_response(request)
  File "/usr/local/lib/python3.10/dist-packages/django/core/handlers/base.py", line 197, in _get_response
    response = wrapped_callback(request, *callback_args, **callback_kwargs)
  File "/usr/local/lib/python3.10/dist-packages/django/views/decorators/csrf.py", line 65, in _view_wrapper
    return view_func(request, *args, **kwargs)
  File "/usr/local/lib/python3.10/dist-packages/django/views/generic/base.py", line 104, in view
    return self.dispatch(request, *args, **kwargs)
  File "/usr/local/lib/python3.10/dist-packages/rest_framework/views.py", line 509, in dispatch
    response = self.handle_exception(exc)
  File "/usr/local/lib/python3.10/dist-packages/rest_framework/views.py", line 469, in handle_exception
    self.raise_uncaught_exception(exc)
  File "/usr/local/lib/python3.10/dist-packages/rest_framework/views.py", line 480, in raise_uncaught_exception
    raise exc
  File "/usr/local/lib/python3.10/dist-packages/rest_framework/views.py", line 506, in dispatch
    response = handler(request, *args, **kwargs)
  File "/home/shivamkumarsain/Projects/Creworder-Django/accounts/views.py", line 255, in get
    if user.role.role == "superadmin":
AttributeError: 'User' object has no attribute 'role'
2024-12-02 13:05:53,846 - django.request - ERROR - Internal Server Error: /api/specific-users/
Traceback (most recent call last):
  File "/usr/local/lib/python3.10/dist-packages/django/core/handlers/exception.py", line 55, in inner
    response = get_response(request)
  File "/usr/local/lib/python3.10/dist-packages/django/core/handlers/base.py", line 197, in _get_response
    response = wrapped_callback(request, *callback_args, **callback_kwargs)
  File "/usr/local/lib/python3.10/dist-packages/django/views/decorators/csrf.py", line 65, in _view_wrapper
    return view_func(request, *args, **kwargs)
  File "/usr/local/lib/python3.10/dist-packages/django/views/generic/base.py", line 104, in view
    return self.dispatch(request, *args, **kwargs)
  File "/usr/local/lib/python3.10/dist-packages/rest_framework/views.py", line 509, in dispatch
    response = self.handle_exception(exc)
  File "/usr/local/lib/python3.10/dist-packages/rest_framework/views.py", line 469, in handle_exception
    self.raise_uncaught_exception(exc)
  File "/usr/local/lib/python3.10/dist-packages/rest_framework/views.py", line 480, in raise_uncaught_exception
    raise exc
  File "/usr/local/lib/python3.10/dist-packages/rest_framework/views.py", line 506, in dispatch
    response = handler(request, *args, **kwargs)
  File "/home/shivamkumarsain/Projects/Creworder-Django/accounts/views.py", line 255, in get
    if user.role.role == "superadmin":
AttributeError: 'User' object has no attribute 'role'
2024-12-02 13:05:55,943 - django.request - ERROR - Internal Server Error: /api/specific-users/
Traceback (most recent call last):
  File "/usr/local/lib/python3.10/dist-packages/django/core/handlers/exception.py", line 55, in inner
    response = get_response(request)
  File "/usr/local/lib/python3.10/dist-packages/django/core/handlers/base.py", line 197, in _get_response
    response = wrapped_callback(request, *callback_args, **callback_kwargs)
  File "/usr/local/lib/python3.10/dist-packages/django/views/decorators/csrf.py", line 65, in _view_wrapper
    return view_func(request, *args, **kwargs)
  File "/usr/local/lib/python3.10/dist-packages/django/views/generic/base.py", line 104, in view
    return self.dispatch(request, *args, **kwargs)
  File "/usr/local/lib/python3.10/dist-packages/rest_framework/views.py", line 509, in dispatch
    response = self.handle_exception(exc)
  File "/usr/local/lib/python3.10/dist-packages/rest_framework/views.py", line 469, in handle_exception
    self.raise_uncaught_exception(exc)
  File "/usr/local/lib/python3.10/dist-packages/rest_framework/views.py", line 480, in raise_uncaught_exception
    raise exc
  File "/usr/local/lib/python3.10/dist-packages/rest_framework/views.py", line 506, in dispatch
    response = handler(request, *args, **kwargs)
  File "/home/shivamkumarsain/Projects/Creworder-Django/accounts/views.py", line 255, in get
    if user.role.role == "superadmin":
AttributeError: 'User' object has no attribute 'role'
2024-12-02 13:06:00,044 - django.request - ERROR - Internal Server Error: /api/specific-users/
Traceback (most recent call last):
  File "/usr/local/lib/python3.10/dist-packages/django/core/handlers/exception.py", line 55, in inner
    response = get_response(request)
  File "/usr/local/lib/python3.10/dist-packages/django/core/handlers/base.py", line 197, in _get_response
    response = wrapped_callback(request, *callback_args, **callback_kwargs)
  File "/usr/local/lib/python3.10/dist-packages/django/views/decorators/csrf.py", line 65, in _view_wrapper
    return view_func(request, *args, **kwargs)
  File "/usr/local/lib/python3.10/dist-packages/django/views/generic/base.py", line 104, in view
    return self.dispatch(request, *args, **kwargs)
  File "/usr/local/lib/python3.10/dist-packages/rest_framework/views.py", line 509, in dispatch
    response = self.handle_exception(exc)
  File "/usr/local/lib/python3.10/dist-packages/rest_framework/views.py", line 469, in handle_exception
    self.raise_uncaught_exception(exc)
  File "/usr/local/lib/python3.10/dist-packages/rest_framework/views.py", line 480, in raise_uncaught_exception
    raise exc
  File "/usr/local/lib/python3.10/dist-packages/rest_framework/views.py", line 506, in dispatch
    response = handler(request, *args, **kwargs)
  File "/home/shivamkumarsain/Projects/Creworder-Django/accounts/views.py", line 255, in get
    if user.role.role == "superadmin":
AttributeError: 'User' object has no attribute 'role'
2024-12-02 14:44:40,811 - django.request - WARNING - Bad Request: /api/companies/
2024-12-02 14:45:22,864 - django.request - WARNING - Bad Request: /api/companies/
2024-12-02 16:51:32,254 - django.request - WARNING - Forbidden: /api/theam-setting/
2024-12-02 16:53:03,208 - django.request - WARNING - Bad Request: /api/theam-setting/
2024-12-02 16:55:57,922 - django.request - WARNING - Forbidden: /api/packages/
2024-12-03 10:55:05,144 - django.request - WARNING - Not Found: /favicon.ico
2024-12-03 10:58:57,632 - django.request - WARNING - Bad Request: /api/auth-role-group/
2024-12-03 11:01:39,180 - django.request - WARNING - Bad Request: /api/auth-role-group/
2024-12-03 11:01:54,282 - django.request - WARNING - Bad Request: /api/auth-role-group/
2024-12-03 15:01:45,592 - django.request - WARNING - Bad Request: /dj-rest-auth/login/
2024-12-03 15:55:07,873 - django.request - WARNING - Forbidden: /api/lead/
2024-12-03 15:55:20,532 - django.request - WARNING - Forbidden: /api/lead/
2024-12-03 16:19:09,265 - django.request - WARNING - Forbidden: /api/createFollowUp/
2024-12-03 16:25:20,761 - django.request - WARNING - Forbidden: /api/createFollowUp/
2024-12-03 16:56:26,793 - django.request - WARNING - Forbidden: /api/follow-up/
2024-12-03 16:57:32,047 - django.request - ERROR - Internal Server Error: /api/follow-up/
Traceback (most recent call last):
  File "/usr/local/lib/python3.10/dist-packages/django/core/handlers/exception.py", line 55, in inner
    response = get_response(request)
  File "/usr/local/lib/python3.10/dist-packages/django/core/handlers/base.py", line 197, in _get_response
    response = wrapped_callback(request, *callback_args, **callback_kwargs)
  File "/usr/local/lib/python3.10/dist-packages/django/views/decorators/csrf.py", line 65, in _view_wrapper
    return view_func(request, *args, **kwargs)
  File "/usr/local/lib/python3.10/dist-packages/rest_framework/viewsets.py", line 124, in view
    return self.dispatch(request, *args, **kwargs)
  File "/usr/local/lib/python3.10/dist-packages/rest_framework/views.py", line 509, in dispatch
    response = self.handle_exception(exc)
  File "/usr/local/lib/python3.10/dist-packages/rest_framework/views.py", line 469, in handle_exception
    self.raise_uncaught_exception(exc)
  File "/usr/local/lib/python3.10/dist-packages/rest_framework/views.py", line 480, in raise_uncaught_exception
    raise exc
  File "/usr/local/lib/python3.10/dist-packages/rest_framework/views.py", line 506, in dispatch
    response = handler(request, *args, **kwargs)
  File "/usr/lib/python3.10/contextlib.py", line 79, in inner
    return func(*args, **kwds)
  File "/home/shivamkumarsain/Projects/Creworder-Django/follow_up/views.py", line 102, in create
    request.data['company'] = user.profile.company.id
  File "/usr/local/lib/python3.10/dist-packages/django/http/request.py", line 562, in __setitem__
    self._assert_mutable()
  File "/usr/local/lib/python3.10/dist-packages/django/http/request.py", line 559, in _assert_mutable
    raise AttributeError("This QueryDict instance is immutable")
AttributeError: This QueryDict instance is immutable
2024-12-03 16:57:59,512 - django.request - WARNING - Bad Request: /api/follow-up/
2024-12-03 17:24:31,586 - django.request - WARNING - Forbidden: /api/follow-up/
2024-12-03 17:30:24,784 - django.request - WARNING - Forbidden: /api/follow-up/
2024-12-03 17:30:29,379 - django.request - WARNING - Forbidden: /api/follow-up/
2024-12-03 17:30:51,327 - django.request - WARNING - Method Not Allowed: /api/follow-up/
2024-12-03 17:31:05,226 - django.request - WARNING - Bad Request: /api/follow-up/
2024-12-03 17:31:41,544 - django.request - WARNING - Method Not Allowed: /api/follow-up/
2024-12-03 17:31:47,639 - django.request - WARNING - Method Not Allowed: /api/follow-up/
2024-12-03 17:31:54,572 - django.request - WARNING - Method Not Allowed: /api/follow-up/
2024-12-03 17:37:49,508 - django.request - WARNING - Not Found: /api/follow-up/1/
2024-12-03 17:38:02,963 - django.request - WARNING - Not Found: /api/follow-up/1/
2024-12-03 17:38:10,515 - django.request - WARNING - Method Not Allowed: /api/follow-up/1/
2024-12-03 17:38:19,247 - django.request - WARNING - Bad Request: /api/follow-up/
2024-12-03 17:40:45,352 - django.request - WARNING - Bad Request: /api/follow-up/
2024-12-03 17:43:16,214 - django.request - ERROR - Internal Server Error: /api/follow-up/1/
Traceback (most recent call last):
  File "/usr/local/lib/python3.10/dist-packages/django/core/handlers/exception.py", line 55, in inner
    response = get_response(request)
  File "/usr/local/lib/python3.10/dist-packages/django/core/handlers/base.py", line 197, in _get_response
    response = wrapped_callback(request, *callback_args, **callback_kwargs)
  File "/usr/local/lib/python3.10/dist-packages/django/views/decorators/csrf.py", line 65, in _view_wrapper
    return view_func(request, *args, **kwargs)
  File "/usr/local/lib/python3.10/dist-packages/rest_framework/viewsets.py", line 124, in view
    return self.dispatch(request, *args, **kwargs)
  File "/usr/local/lib/python3.10/dist-packages/rest_framework/views.py", line 509, in dispatch
    response = self.handle_exception(exc)
  File "/usr/local/lib/python3.10/dist-packages/rest_framework/views.py", line 469, in handle_exception
    self.raise_uncaught_exception(exc)
  File "/usr/local/lib/python3.10/dist-packages/rest_framework/views.py", line 480, in raise_uncaught_exception
    raise exc
  File "/usr/local/lib/python3.10/dist-packages/rest_framework/views.py", line 506, in dispatch
    response = handler(request, *args, **kwargs)
  File "/usr/lib/python3.10/contextlib.py", line 79, in inner
    return func(*args, **kwds)
  File "/home/shivamkumarsain/Projects/Creworder-Django/follow_up/views.py", line 33, in update
    request.data['company'] = instance.company.id
AttributeError: 'FollowUp' object has no attribute 'company'
2024-12-03 17:53:15,895 - django.request - ERROR - Internal Server Error: /api/follow-up/1/
Traceback (most recent call last):
  File "/usr/local/lib/python3.10/dist-packages/django/core/handlers/exception.py", line 55, in inner
    response = get_response(request)
  File "/usr/local/lib/python3.10/dist-packages/django/core/handlers/base.py", line 197, in _get_response
    response = wrapped_callback(request, *callback_args, **callback_kwargs)
  File "/usr/local/lib/python3.10/dist-packages/django/views/decorators/csrf.py", line 65, in _view_wrapper
    return view_func(request, *args, **kwargs)
  File "/usr/local/lib/python3.10/dist-packages/rest_framework/viewsets.py", line 124, in view
    return self.dispatch(request, *args, **kwargs)
  File "/usr/local/lib/python3.10/dist-packages/rest_framework/views.py", line 509, in dispatch
    response = self.handle_exception(exc)
  File "/usr/local/lib/python3.10/dist-packages/rest_framework/views.py", line 469, in handle_exception
    self.raise_uncaught_exception(exc)
  File "/usr/local/lib/python3.10/dist-packages/rest_framework/views.py", line 480, in raise_uncaught_exception
    raise exc
  File "/usr/local/lib/python3.10/dist-packages/rest_framework/views.py", line 506, in dispatch
    response = handler(request, *args, **kwargs)
  File "/usr/lib/python3.10/contextlib.py", line 79, in inner
    return func(*args, **kwds)
  File "/home/shivamkumarsain/Projects/Creworder-Django/follow_up/views.py", line 27, in update
    request.data['company'] = instance.company.id
AttributeError: 'NoneType' object has no attribute 'id'
2024-12-03 18:16:01,337 - django.request - WARNING - Method Not Allowed: /api/follow-up/
2024-12-03 18:57:09,864 - django.request - WARNING - Bad Request: /api/orders/
2024-12-03 19:15:40,072 - django.request - ERROR - Internal Server Error: /api/check-serviceability/
Traceback (most recent call last):
  File "/usr/local/lib/python3.10/dist-packages/django/core/handlers/exception.py", line 55, in inner
    response = get_response(request)
  File "/usr/local/lib/python3.10/dist-packages/django/core/handlers/base.py", line 197, in _get_response
    response = wrapped_callback(request, *callback_args, **callback_kwargs)
  File "/usr/local/lib/python3.10/dist-packages/django/views/decorators/csrf.py", line 65, in _view_wrapper
    return view_func(request, *args, **kwargs)
  File "/usr/local/lib/python3.10/dist-packages/django/views/generic/base.py", line 104, in view
    return self.dispatch(request, *args, **kwargs)
  File "/usr/local/lib/python3.10/dist-packages/rest_framework/views.py", line 509, in dispatch
    response = self.handle_exception(exc)
  File "/usr/local/lib/python3.10/dist-packages/rest_framework/views.py", line 469, in handle_exception
    self.raise_uncaught_exception(exc)
  File "/usr/local/lib/python3.10/dist-packages/rest_framework/views.py", line 480, in raise_uncaught_exception
    raise exc
  File "/usr/local/lib/python3.10/dist-packages/rest_framework/views.py", line 506, in dispatch
    response = handler(request, *args, **kwargs)
  File "/home/shivamkumarsain/Projects/Creworder-Django/orders/views.py", line 431, in get
    "data": {"massage": f"Non serviceable {request.data['pincode']}"},
KeyError: 'pincode'
2024-12-03 19:16:05,975 - django.request - ERROR - Internal Server Error: /api/check-serviceability/
Traceback (most recent call last):
  File "/usr/local/lib/python3.10/dist-packages/django/core/handlers/exception.py", line 55, in inner
    response = get_response(request)
  File "/usr/local/lib/python3.10/dist-packages/django/core/handlers/base.py", line 197, in _get_response
    response = wrapped_callback(request, *callback_args, **callback_kwargs)
  File "/usr/local/lib/python3.10/dist-packages/django/views/decorators/csrf.py", line 65, in _view_wrapper
    return view_func(request, *args, **kwargs)
  File "/usr/local/lib/python3.10/dist-packages/django/views/generic/base.py", line 104, in view
    return self.dispatch(request, *args, **kwargs)
  File "/usr/local/lib/python3.10/dist-packages/rest_framework/views.py", line 509, in dispatch
    response = self.handle_exception(exc)
  File "/usr/local/lib/python3.10/dist-packages/rest_framework/views.py", line 469, in handle_exception
    self.raise_uncaught_exception(exc)
  File "/usr/local/lib/python3.10/dist-packages/rest_framework/views.py", line 480, in raise_uncaught_exception
    raise exc
  File "/usr/local/lib/python3.10/dist-packages/rest_framework/views.py", line 506, in dispatch
    response = handler(request, *args, **kwargs)
  File "/home/shivamkumarsain/Projects/Creworder-Django/orders/views.py", line 431, in get
    "data": {"massage": f"Non serviceable {request.data['pincode']}"},
KeyError: 'pincode'
2024-12-03 19:18:34,247 - django.request - ERROR - Internal Server Error: /api/check-serviceability/
Traceback (most recent call last):
  File "/usr/local/lib/python3.10/dist-packages/django/core/handlers/exception.py", line 55, in inner
    response = get_response(request)
  File "/usr/local/lib/python3.10/dist-packages/django/core/handlers/base.py", line 197, in _get_response
    response = wrapped_callback(request, *callback_args, **callback_kwargs)
  File "/usr/local/lib/python3.10/dist-packages/django/views/decorators/csrf.py", line 65, in _view_wrapper
    return view_func(request, *args, **kwargs)
  File "/usr/local/lib/python3.10/dist-packages/django/views/generic/base.py", line 104, in view
    return self.dispatch(request, *args, **kwargs)
  File "/usr/local/lib/python3.10/dist-packages/rest_framework/views.py", line 509, in dispatch
    response = self.handle_exception(exc)
  File "/usr/local/lib/python3.10/dist-packages/rest_framework/views.py", line 469, in handle_exception
    self.raise_uncaught_exception(exc)
  File "/usr/local/lib/python3.10/dist-packages/rest_framework/views.py", line 480, in raise_uncaught_exception
    raise exc
  File "/usr/local/lib/python3.10/dist-packages/rest_framework/views.py", line 506, in dispatch
    response = handler(request, *args, **kwargs)
  File "/home/shivamkumarsain/Projects/Creworder-Django/orders/views.py", line 431, in get
    "data": {"massage": f"Non serviceable {request.data['pincode']}"},
KeyError: 'pincode'
2024-12-04 10:41:29,256 - django.request - WARNING - Not Found: /favicon.ico
2024-12-04 10:54:53,155 - django.request - ERROR - Internal Server Error: /api/check-serviceability/
Traceback (most recent call last):
  File "/usr/local/lib/python3.10/dist-packages/django/core/handlers/exception.py", line 55, in inner
    response = get_response(request)
  File "/usr/local/lib/python3.10/dist-packages/django/core/handlers/base.py", line 197, in _get_response
    response = wrapped_callback(request, *callback_args, **callback_kwargs)
  File "/usr/local/lib/python3.10/dist-packages/django/views/decorators/csrf.py", line 65, in _view_wrapper
    return view_func(request, *args, **kwargs)
  File "/usr/local/lib/python3.10/dist-packages/django/views/generic/base.py", line 104, in view
    return self.dispatch(request, *args, **kwargs)
  File "/usr/local/lib/python3.10/dist-packages/rest_framework/views.py", line 509, in dispatch
    response = self.handle_exception(exc)
  File "/usr/local/lib/python3.10/dist-packages/rest_framework/views.py", line 469, in handle_exception
    self.raise_uncaught_exception(exc)
  File "/usr/local/lib/python3.10/dist-packages/rest_framework/views.py", line 480, in raise_uncaught_exception
    raise exc
  File "/usr/local/lib/python3.10/dist-packages/rest_framework/views.py", line 506, in dispatch
    response = handler(request, *args, **kwargs)
  File "/home/shivamkumarsain/Projects/Creworder-Django/orders/views.py", line 432, in get
    "data": {"massage": f"Non serviceable {request.data['pincode']}"},
KeyError: 'pincode'
2024-12-04 10:55:15,339 - django.request - ERROR - Internal Server Error: /api/check-serviceability/
Traceback (most recent call last):
  File "/usr/local/lib/python3.10/dist-packages/django/core/handlers/exception.py", line 55, in inner
    response = get_response(request)
  File "/usr/local/lib/python3.10/dist-packages/django/core/handlers/base.py", line 197, in _get_response
    response = wrapped_callback(request, *callback_args, **callback_kwargs)
  File "/usr/local/lib/python3.10/dist-packages/django/views/decorators/csrf.py", line 65, in _view_wrapper
    return view_func(request, *args, **kwargs)
  File "/usr/local/lib/python3.10/dist-packages/django/views/generic/base.py", line 104, in view
    return self.dispatch(request, *args, **kwargs)
  File "/usr/local/lib/python3.10/dist-packages/rest_framework/views.py", line 509, in dispatch
    response = self.handle_exception(exc)
  File "/usr/local/lib/python3.10/dist-packages/rest_framework/views.py", line 469, in handle_exception
    self.raise_uncaught_exception(exc)
  File "/usr/local/lib/python3.10/dist-packages/rest_framework/views.py", line 480, in raise_uncaught_exception
    raise exc
  File "/usr/local/lib/python3.10/dist-packages/rest_framework/views.py", line 506, in dispatch
    response = handler(request, *args, **kwargs)
  File "/home/shivamkumarsain/Projects/Creworder-Django/orders/views.py", line 432, in get
    "data": {"massage": f"Non serviceable {request.data['pincode']}"},
KeyError: 'pincode'
2024-12-04 10:56:50,902 - django.request - ERROR - Internal Server Error: /api/check-serviceability/
Traceback (most recent call last):
  File "/usr/local/lib/python3.10/dist-packages/django/core/handlers/exception.py", line 55, in inner
    response = get_response(request)
  File "/usr/local/lib/python3.10/dist-packages/django/core/handlers/base.py", line 197, in _get_response
    response = wrapped_callback(request, *callback_args, **callback_kwargs)
  File "/usr/local/lib/python3.10/dist-packages/django/views/decorators/csrf.py", line 65, in _view_wrapper
    return view_func(request, *args, **kwargs)
  File "/usr/local/lib/python3.10/dist-packages/django/views/generic/base.py", line 104, in view
    return self.dispatch(request, *args, **kwargs)
  File "/usr/local/lib/python3.10/dist-packages/rest_framework/views.py", line 509, in dispatch
    response = self.handle_exception(exc)
  File "/usr/local/lib/python3.10/dist-packages/rest_framework/views.py", line 469, in handle_exception
    self.raise_uncaught_exception(exc)
  File "/usr/local/lib/python3.10/dist-packages/rest_framework/views.py", line 480, in raise_uncaught_exception
    raise exc
  File "/usr/local/lib/python3.10/dist-packages/rest_framework/views.py", line 506, in dispatch
    response = handler(request, *args, **kwargs)
  File "/home/shivamkumarsain/Projects/Creworder-Django/orders/views.py", line 432, in get
    "data": {"massage": f"Non serviceable {request.data['pincode']}"},
KeyError: 'pincode'
2024-12-04 10:58:17,094 - django.request - ERROR - Internal Server Error: /api/check-serviceability/
Traceback (most recent call last):
  File "/usr/local/lib/python3.10/dist-packages/django/core/handlers/exception.py", line 55, in inner
    response = get_response(request)
  File "/usr/local/lib/python3.10/dist-packages/django/core/handlers/base.py", line 197, in _get_response
    response = wrapped_callback(request, *callback_args, **callback_kwargs)
  File "/usr/local/lib/python3.10/dist-packages/django/views/decorators/csrf.py", line 65, in _view_wrapper
    return view_func(request, *args, **kwargs)
  File "/usr/local/lib/python3.10/dist-packages/django/views/generic/base.py", line 104, in view
    return self.dispatch(request, *args, **kwargs)
  File "/usr/local/lib/python3.10/dist-packages/rest_framework/views.py", line 509, in dispatch
    response = self.handle_exception(exc)
  File "/usr/local/lib/python3.10/dist-packages/rest_framework/views.py", line 469, in handle_exception
    self.raise_uncaught_exception(exc)
  File "/usr/local/lib/python3.10/dist-packages/rest_framework/views.py", line 480, in raise_uncaught_exception
    raise exc
  File "/usr/local/lib/python3.10/dist-packages/rest_framework/views.py", line 506, in dispatch
    response = handler(request, *args, **kwargs)
  File "/home/shivamkumarsain/Projects/Creworder-Django/orders/views.py", line 432, in get
    "data": {"massage": f"Non serviceable {request.data['pincode']}"},
KeyError: 'pincode'
2024-12-04 10:58:42,028 - django.request - ERROR - Internal Server Error: /api/check-serviceability/
Traceback (most recent call last):
  File "/usr/local/lib/python3.10/dist-packages/django/core/handlers/exception.py", line 55, in inner
    response = get_response(request)
  File "/usr/local/lib/python3.10/dist-packages/django/core/handlers/base.py", line 197, in _get_response
    response = wrapped_callback(request, *callback_args, **callback_kwargs)
  File "/usr/local/lib/python3.10/dist-packages/django/views/decorators/csrf.py", line 65, in _view_wrapper
    return view_func(request, *args, **kwargs)
  File "/usr/local/lib/python3.10/dist-packages/django/views/generic/base.py", line 104, in view
    return self.dispatch(request, *args, **kwargs)
  File "/usr/local/lib/python3.10/dist-packages/rest_framework/views.py", line 509, in dispatch
    response = self.handle_exception(exc)
  File "/usr/local/lib/python3.10/dist-packages/rest_framework/views.py", line 469, in handle_exception
    self.raise_uncaught_exception(exc)
  File "/usr/local/lib/python3.10/dist-packages/rest_framework/views.py", line 480, in raise_uncaught_exception
    raise exc
  File "/usr/local/lib/python3.10/dist-packages/rest_framework/views.py", line 506, in dispatch
    response = handler(request, *args, **kwargs)
  File "/home/shivamkumarsain/Projects/Creworder-Django/orders/views.py", line 432, in get
    "data": {"massage": f"Non serviceable {request.data['pincode']}"},
KeyError: 'pincode'
2024-12-04 10:59:10,680 - django.request - ERROR - Internal Server Error: /api/check-serviceability/
Traceback (most recent call last):
  File "/usr/local/lib/python3.10/dist-packages/django/core/handlers/exception.py", line 55, in inner
    response = get_response(request)
  File "/usr/local/lib/python3.10/dist-packages/django/core/handlers/base.py", line 197, in _get_response
    response = wrapped_callback(request, *callback_args, **callback_kwargs)
  File "/usr/local/lib/python3.10/dist-packages/django/views/decorators/csrf.py", line 65, in _view_wrapper
    return view_func(request, *args, **kwargs)
  File "/usr/local/lib/python3.10/dist-packages/django/views/generic/base.py", line 104, in view
    return self.dispatch(request, *args, **kwargs)
  File "/usr/local/lib/python3.10/dist-packages/rest_framework/views.py", line 509, in dispatch
    response = self.handle_exception(exc)
  File "/usr/local/lib/python3.10/dist-packages/rest_framework/views.py", line 469, in handle_exception
    self.raise_uncaught_exception(exc)
  File "/usr/local/lib/python3.10/dist-packages/rest_framework/views.py", line 480, in raise_uncaught_exception
    raise exc
  File "/usr/local/lib/python3.10/dist-packages/rest_framework/views.py", line 506, in dispatch
    response = handler(request, *args, **kwargs)
  File "/home/shivamkumarsain/Projects/Creworder-Django/orders/views.py", line 432, in get
    "data": {"massage": f"Non serviceable {request.data['pincode']}"},
KeyError: 'pincode'
2024-12-04 11:00:43,670 - django.request - ERROR - Internal Server Error: /api/check-serviceability/
Traceback (most recent call last):
  File "/usr/local/lib/python3.10/dist-packages/django/core/handlers/exception.py", line 55, in inner
    response = get_response(request)
  File "/usr/local/lib/python3.10/dist-packages/django/core/handlers/base.py", line 197, in _get_response
    response = wrapped_callback(request, *callback_args, **callback_kwargs)
  File "/usr/local/lib/python3.10/dist-packages/django/views/decorators/csrf.py", line 65, in _view_wrapper
    return view_func(request, *args, **kwargs)
  File "/usr/local/lib/python3.10/dist-packages/django/views/generic/base.py", line 104, in view
    return self.dispatch(request, *args, **kwargs)
  File "/usr/local/lib/python3.10/dist-packages/rest_framework/views.py", line 509, in dispatch
    response = self.handle_exception(exc)
  File "/usr/local/lib/python3.10/dist-packages/rest_framework/views.py", line 469, in handle_exception
    self.raise_uncaught_exception(exc)
  File "/usr/local/lib/python3.10/dist-packages/rest_framework/views.py", line 480, in raise_uncaught_exception
    raise exc
  File "/usr/local/lib/python3.10/dist-packages/rest_framework/views.py", line 506, in dispatch
    response = handler(request, *args, **kwargs)
  File "/home/shivamkumarsain/Projects/Creworder-Django/orders/views.py", line 432, in get
    "data": {"massage": f"Non serviceable {request.data['massage']}"},
KeyError: 'massage'
2024-12-04 11:01:12,936 - django.request - ERROR - Internal Server Error: /api/check-serviceability/
Traceback (most recent call last):
  File "/usr/local/lib/python3.10/dist-packages/django/core/handlers/exception.py", line 55, in inner
    response = get_response(request)
  File "/usr/local/lib/python3.10/dist-packages/django/core/handlers/base.py", line 197, in _get_response
    response = wrapped_callback(request, *callback_args, **callback_kwargs)
  File "/usr/local/lib/python3.10/dist-packages/django/views/decorators/csrf.py", line 65, in _view_wrapper
    return view_func(request, *args, **kwargs)
  File "/usr/local/lib/python3.10/dist-packages/django/views/generic/base.py", line 104, in view
    return self.dispatch(request, *args, **kwargs)
  File "/usr/local/lib/python3.10/dist-packages/rest_framework/views.py", line 509, in dispatch
    response = self.handle_exception(exc)
  File "/usr/local/lib/python3.10/dist-packages/rest_framework/views.py", line 469, in handle_exception
    self.raise_uncaught_exception(exc)
  File "/usr/local/lib/python3.10/dist-packages/rest_framework/views.py", line 480, in raise_uncaught_exception
    raise exc
  File "/usr/local/lib/python3.10/dist-packages/rest_framework/views.py", line 506, in dispatch
    response = handler(request, *args, **kwargs)
  File "/home/shivamkumarsain/Projects/Creworder-Django/orders/views.py", line 432, in get
    "data": {"massage": f"Non serviceable {data['massage']}"},
TypeError: list indices must be integers or slices, not str
2024-12-04 11:01:44,629 - django.request - WARNING - Not Found: /api/check-serviceability/
2024-12-04 11:02:53,966 - django.request - WARNING - Not Found: /api/check-serviceability/
2024-12-04 11:03:50,102 - django.request - WARNING - Not Found: /api/check-serviceability/
2024-12-04 11:23:15,573 - django.request - WARNING - Not Found: /api/check-serviceability/
2024-12-04 11:26:11,137 - django.request - WARNING - Not Found: /api/check-serviceability/
2024-12-04 11:26:19,098 - django.request - WARNING - Not Found: /api/check-serviceability/
2024-12-04 11:30:11,896 - django.request - WARNING - Not Found: /api/check-serviceability/
2024-12-04 11:36:18,781 - django.request - WARNING - Not Found: /api/check-serviceability/
2024-12-04 11:37:02,585 - django.request - WARNING - Not Found: /api/check-serviceability/
2024-12-04 18:28:28,349 - django.request - WARNING - Bad Request: /api/assign-role/
2024-12-04 18:28:59,413 - django.request - ERROR - Internal Server Error: /api/assign-role/
Traceback (most recent call last):
  File "/usr/local/lib/python3.10/dist-packages/django/core/handlers/exception.py", line 55, in inner
    response = get_response(request)
  File "/usr/local/lib/python3.10/dist-packages/django/core/handlers/base.py", line 197, in _get_response
    response = wrapped_callback(request, *callback_args, **callback_kwargs)
  File "/usr/local/lib/python3.10/dist-packages/django/views/decorators/csrf.py", line 65, in _view_wrapper
    return view_func(request, *args, **kwargs)
  File "/usr/local/lib/python3.10/dist-packages/rest_framework/viewsets.py", line 124, in view
    return self.dispatch(request, *args, **kwargs)
  File "/usr/local/lib/python3.10/dist-packages/rest_framework/views.py", line 509, in dispatch
    response = self.handle_exception(exc)
  File "/usr/local/lib/python3.10/dist-packages/rest_framework/views.py", line 469, in handle_exception
    self.raise_uncaught_exception(exc)
  File "/usr/local/lib/python3.10/dist-packages/rest_framework/views.py", line 480, in raise_uncaught_exception
    raise exc
  File "/usr/local/lib/python3.10/dist-packages/rest_framework/views.py", line 506, in dispatch
    response = handler(request, *args, **kwargs)
  File "/home/shivamkumarsain/Projects/Creworder-Django/accounts/views.py", line 971, in create
    return super().create(request, *args, **kwargs)
  File "/usr/local/lib/python3.10/dist-packages/rest_framework/mixins.py", line 17, in create
    serializer = self.get_serializer(data=request.data)
  File "/usr/local/lib/python3.10/dist-packages/rest_framework/generics.py", line 112, in get_serializer
    serializer_class = self.get_serializer_class()
  File "/usr/local/lib/python3.10/dist-packages/rest_framework/generics.py", line 126, in get_serializer_class
    assert self.serializer_class is not None, (
AssertionError: 'AssignRole' should either include a `serializer_class` attribute, or override the `get_serializer_class()` method.
2024-12-05 11:04:49,824 - django.request - WARNING - Not Found: /api/get_cloud_telephonic_channels/
2024-12-05 11:05:10,521 - django.request - WARNING - Not Found: /api/get_cloud_telephonic_channels/
2024-12-05 11:05:16,905 - django.request - WARNING - Not Found: /api/get_cloud_telephonic_channels/
2024-12-05 11:06:38,510 - django.request - WARNING - Method Not Allowed: /api/createCloudTelephoneyChannel/
2024-12-05 11:07:03,787 - django.request - WARNING - Method Not Allowed: /api/createCloudTelephoneyChannel/
2024-12-05 11:07:08,553 - django.request - WARNING - Bad Request: /api/createCloudTelephoneyChannel/
2024-12-05 11:07:24,702 - django.request - WARNING - Bad Request: /api/createCloudTelephoneyChannel/
2024-12-05 11:12:21,091 - django.request - WARNING - Not Found: /favicon.ico
2024-12-05 12:18:32,805 - django.request - ERROR - Internal Server Error: /api/assign-role/
Traceback (most recent call last):
  File "/usr/local/lib/python3.10/dist-packages/django/core/handlers/exception.py", line 55, in inner
    response = get_response(request)
  File "/usr/local/lib/python3.10/dist-packages/django/core/handlers/base.py", line 197, in _get_response
    response = wrapped_callback(request, *callback_args, **callback_kwargs)
  File "/usr/local/lib/python3.10/dist-packages/django/views/decorators/csrf.py", line 65, in _view_wrapper
    return view_func(request, *args, **kwargs)
  File "/usr/local/lib/python3.10/dist-packages/rest_framework/viewsets.py", line 124, in view
    return self.dispatch(request, *args, **kwargs)
  File "/usr/local/lib/python3.10/dist-packages/rest_framework/views.py", line 509, in dispatch
    response = self.handle_exception(exc)
  File "/usr/local/lib/python3.10/dist-packages/rest_framework/views.py", line 469, in handle_exception
    self.raise_uncaught_exception(exc)
  File "/usr/local/lib/python3.10/dist-packages/rest_framework/views.py", line 480, in raise_uncaught_exception
    raise exc
  File "/usr/local/lib/python3.10/dist-packages/rest_framework/views.py", line 506, in dispatch
    response = handler(request, *args, **kwargs)
  File "/usr/local/lib/python3.10/dist-packages/rest_framework/mixins.py", line 38, in list
    queryset = self.filter_queryset(self.get_queryset())
  File "/usr/local/lib/python3.10/dist-packages/rest_framework/generics.py", line 67, in get_queryset
    assert self.queryset is not None, (
AssertionError: 'AssignRole' should either include a `queryset` attribute, or override the `get_queryset()` method.
2024-12-05 12:19:13,476 - django.request - ERROR - Internal Server Error: /api/assign-role/
Traceback (most recent call last):
  File "/usr/local/lib/python3.10/dist-packages/django/core/handlers/exception.py", line 55, in inner
    response = get_response(request)
  File "/usr/local/lib/python3.10/dist-packages/django/core/handlers/base.py", line 197, in _get_response
    response = wrapped_callback(request, *callback_args, **callback_kwargs)
  File "/usr/local/lib/python3.10/dist-packages/django/views/decorators/csrf.py", line 65, in _view_wrapper
    return view_func(request, *args, **kwargs)
  File "/usr/local/lib/python3.10/dist-packages/rest_framework/viewsets.py", line 124, in view
    return self.dispatch(request, *args, **kwargs)
  File "/usr/local/lib/python3.10/dist-packages/rest_framework/views.py", line 509, in dispatch
    response = self.handle_exception(exc)
  File "/usr/local/lib/python3.10/dist-packages/rest_framework/views.py", line 469, in handle_exception
    self.raise_uncaught_exception(exc)
  File "/usr/local/lib/python3.10/dist-packages/rest_framework/views.py", line 480, in raise_uncaught_exception
    raise exc
  File "/usr/local/lib/python3.10/dist-packages/rest_framework/views.py", line 506, in dispatch
    response = handler(request, *args, **kwargs)
  File "/usr/local/lib/python3.10/dist-packages/rest_framework/mixins.py", line 38, in list
    queryset = self.filter_queryset(self.get_queryset())
  File "/usr/local/lib/python3.10/dist-packages/rest_framework/generics.py", line 67, in get_queryset
    assert self.queryset is not None, (
AssertionError: 'AssignRole' should either include a `queryset` attribute, or override the `get_queryset()` method.
2024-12-05 12:26:15,984 - django.request - ERROR - Internal Server Error: /api/assign-role/
Traceback (most recent call last):
  File "/usr/local/lib/python3.10/dist-packages/django/core/handlers/exception.py", line 55, in inner
    response = get_response(request)
  File "/usr/local/lib/python3.10/dist-packages/django/core/handlers/base.py", line 197, in _get_response
    response = wrapped_callback(request, *callback_args, **callback_kwargs)
  File "/usr/local/lib/python3.10/dist-packages/django/views/decorators/csrf.py", line 65, in _view_wrapper
    return view_func(request, *args, **kwargs)
  File "/usr/local/lib/python3.10/dist-packages/rest_framework/viewsets.py", line 124, in view
    return self.dispatch(request, *args, **kwargs)
  File "/usr/local/lib/python3.10/dist-packages/rest_framework/views.py", line 509, in dispatch
    response = self.handle_exception(exc)
  File "/usr/local/lib/python3.10/dist-packages/rest_framework/views.py", line 469, in handle_exception
    self.raise_uncaught_exception(exc)
  File "/usr/local/lib/python3.10/dist-packages/rest_framework/views.py", line 480, in raise_uncaught_exception
    raise exc
  File "/usr/local/lib/python3.10/dist-packages/rest_framework/views.py", line 506, in dispatch
    response = handler(request, *args, **kwargs)
  File "/usr/local/lib/python3.10/dist-packages/rest_framework/mixins.py", line 17, in create
    serializer = self.get_serializer(data=request.data)
  File "/usr/local/lib/python3.10/dist-packages/rest_framework/generics.py", line 112, in get_serializer
    serializer_class = self.get_serializer_class()
  File "/usr/local/lib/python3.10/dist-packages/rest_framework/generics.py", line 126, in get_serializer_class
    assert self.serializer_class is not None, (
AssertionError: 'AssignRole' should either include a `serializer_class` attribute, or override the `get_serializer_class()` method.
2024-12-05 12:41:01,433 - django.request - WARNING - Not Found: /api/sliders/
2024-12-05 12:41:08,776 - django.request - WARNING - Not Found: /api/sliders/
2024-12-05 12:42:09,437 - django.request - WARNING - Bad Request: /api/sliders/
